Workbook

Sheet Standalone Profit & Loss
A1: Particulars | B1: Cogencis Field | C1: Status | D1: Revised Field Mapping | E1: Field id | G1: Correct | H1: =COUNTIF(C:C,G1) -> 23
A2: Revenue from Operations | B2: Gross Sales/Income from Operations | C2: Correct | G2: Incorrect | H2: =COUNTIF(C:C,G2) -> 3
A3: Other Income | B3: Miscellaneous Income | C3: Correct | G3: Accuracy % | H3: =H1/SUM(H1:H2) -> 0.88461538
A4: Total Income | B4: Total Income | C4: Correct
A5: Expenses | B5: Lable | C5: Correct
A6: Cost of material consumed | B6: Cost of Materials Consumed | C6: Correct
A7: Purchases of stock - in - trade | B7: Purchase of Stock-in-Trade | C7: Correct
A8: Changes in inventories of finished goods work - in - progress and stock - in - trade | B8: Changes in Inventories of Finished Goods, Work-In-Progress and Stock-In-Trade | C8: Correct
A9: Employee benefits expense | B9: Employee Benefit Expense | C9: Correct
A10: Finance Cost | B10: Finance Costs | C10: Correct
A11: Depreciation and amortization expense | B11: Depreciation, Depletion and Amortisation Expense | C11: Correct
A12: Other Expense | B12: Other Expenses | C12: Correct
A13: Exchange rate difference | B13: Items that will be reclassified to Profit or Loss | C13: Incorrect | D13: Exchange (Gain)/Loss | E13: 240
A14: Total Expense | B14: Total Expenses | C14: Correct
A15: Profit / Loss before tax | B15: Profit/(Loss) From Ordinary Activities before Tax | C15: Correct
A16: Tax expense | B16: Lable | C16: Correct
A17: Current Tax | B17: Tax Expense | C17: Correct
A18: Short / ( Excess ) provision of taxation for previous period | B18: Tax Expense | C18: Correct
A19: Deferred Tax | B19: Deferred Tax | C19: Correct
A20: Total Tax Expenses | B20: Total Field | D20: ignore this field
A21: Net Profit/ Loss for the period | B21: Net Profit/(Loss) for the Period | C21: Correct
A22: Other Comprehensive Income ( After Tax ) | B22: Other Comprehensive Income | C22: Correct
A23: Total Comprehensive Income for the period comprising Net Profit / ( Loss ) for the period & Other Comprehensive Income | B23: Total Comprehensive Gain (Loss) For the Year | C23: Correct
A24: Paid - up equity share capital | B24: Paid-Up Equity Share Capital | C24: Correct
A25: Reserve ( excluding Revaluation Reserves ) as per Audited Balance Sheet . | B25: Reserve excluding Revaluation Reserves (as per Balance Sheet of Previous Accounting Year) | C25: Correct
A26: Earning Per Share | B26: Lable | C26: Correct
A27: Basic | B27: Lable | C27: Incorrect | D27: Basic EPS | E27: 222
A28: Diluted | B28: Lable | C28: Incorrect | D28: Diluted EPS | E28: 234

Sheet Consolidated Profit & Loss
A1: Particulars | B1: Cogencis Field | C1: Status | D1: Revised Field Mapping | E1: Field id | G1: Correct | H1: =COUNTIF(C:C,G1) -> 23
A2: Revenue from Operations | B2: Gross Sales/Income from Operations | C2: Correct | G2: Incorrect | H2: =COUNTIF(C:C,G2) -> 3
A3: Other Income | B3: Miscellaneous Income | C3: Correct | G3: Accuracy % | H3: =H1/SUM(H1:H2) -> 0.88461538
A4: Total Income | B4: Total Income | C4: Correct
A5: Expenses | B5: Lable | C5: Correct
A6: Cost of material consumed | B6: Cost of Materials Consumed | C6: Correct
A7: Purchases of stock - in - trade | B7: Purchase of Stock-in-Trade | C7: Correct
A8: Changes in inventories of finished goods work - in - progress and stock - in - trade | B8: Changes in Inventories of Finished Goods, Work-In-Progress and Stock-In-Trade | C8: Correct
A9: Employee benefits expense | B9: Employee Benefit Expense | C9: Correct
A10: Finance Cost | B10: Finance Costs | C10: Correct
A11: Depreciation and amortization expense | B11: Depreciation, Depletion and Amortisation Expense | C11: Correct
A12: Other Expense | B12: Other Expenses | C12: Correct
A13: Exchange rate difference | B13: Items that will be reclassified to Profit or Loss | C13: Incorrect | D13: Exchange (Gain)/Loss | E13: 240
A14: Total Expense | B14: Total Expenses | C14: Correct
A15: Profit / Loss before tax | B15: Profit/(Loss) From Ordinary Activities before Tax | C15: Correct
A16: Tax expense | B16: Lable | C16: Correct
A17: Current Tax | B17: Tax Expense | C17: Correct
A18: Short / ( Excess ) provision of taxation for previous period | B18: Tax Expense | C18: Correct
A19: Deferred Tax | B19: Deferred Tax | C19: Correct
A20: Total Tax Expenses | B20: Total Field | D20: Ignore this field
A21: Net Profit/ Loss for the period | B21: Net Profit/(Loss) for the Period | C21: Correct
A22: Other Comprehensive Income ( After Tax ) | B22: Other Comprehensive Income | C22: Correct
A23: Total Comprehensive Income for the period comprising Net Profit / ( Loss ) for the period & Other Comprehensive Income | B23: Total Comprehensive Gain (Loss) For the Year | C23: Correct
A24: Paid-up equity share capital (Face Value Rs. 5/- PerShare) | B24: Paid-Up Equity Share Capital | C24: Correct
A25: Reserve ( excluding Revaluation Reserves ) as per Audited Balance Sheet | B25: Reserve excluding Revaluation Reserves (as per Balance Sheet of Previous Accounting Year) | C25: Correct
A26: Eamlng Per Share (of Rs.5/- each) | B26: Face Value | C26: Correct
A27: Basic | B27: Lable | C27: Incorrect | D27: Basic EPS | E27: 222
A28: Diluted | B28: Lable | C28: Incorrect | D28: Diluted EPS | E28: 234

Sheet Standalone Balance Sheet
A1: Particulars | B1: Cogencis Field | C1: Status | D1: Revised Field Mapping | E1: Field id | G1: Correct | H1: =COUNTIF(C:C,G1) -> 42
A2: Non - Current Assets | B2: Lable | C2: Correct | G2: Incorrect | H2: =COUNTIF(C:C,G2) -> 5
A3: Property, Plant and Equipment | B3: Property, Plant & Equipment | C3: Correct | G3: Accuracy % | H3: =H1/SUM(H1:H2) -> 0.89361702
A4: Capital work - in - progress | B4: Capital Work-In-Progress | C4: Correct
A5: Investment property | B5: Investment Property | C5: Correct
A6: Other Intangible assets | B6: Other Intangible Assets | C6: Correct
A7: Intangible assets under development | B7: Intangible assets under development | C7: Correct
A8: Financial assets | B8: Lable | C8: Correct
A9: Investments | B9: Non-Current Investments | C9: Correct
A10: Loans | B10: Loans, Current | C10: Incorrect | D10: Loans Non-Current | E10: 20217
A11: Others financial assets | B11: Other Current Financial Assets | C11: Incorrect | D11: Other Non-Current Financial Assets | E11: 20216
A12: Deferred tax assets(Net ) | B12: Deferred Tax Assets (Net) | C12: Correct
A13: Total Non - current assets | B13: Total Non-Current Assets | C13: Correct
A14: Current Assets | B14: Lable | C14: Correct
A15: Inventories | B15: Inventories | C15: Correct
A16: Financial Assets | B16: Lable | C16: Correct
A17: Investment | B17: Non-Current Investments | C17: Incorrect | D17: Current Investments | E17: 13724
A18: Trade receivables | B18: Trade Receivables | C18: Correct | D18: Trade Receivables | E18: 13780
A19: Cash and cash equivalents | B19: Cash And Cash Equivalents | C19: Correct
A20: Loans | B20: Loans, Current | C20: Correct
A21: Other financial assets | B21: Other Non-Current Financial Assets | C21: Incorrect | D21: Other Current Financial Assets | E21: 20231
A22: Current Tax Assets | B22: Current Tax Assets (Net) | C22: Correct
A23: Other current assets | B23: Other Current Assets | C23: Correct
A24: Total current assets | B24: Total Current Assets | C24: Correct
A25: TOTAL ASSETS | B25: Total Assets | C25: Correct
A26: EQUITY AND LIABILITIES | B26: Lable | C26: Correct
A27: Equity | B27: Lable | C27: Correct
A28: Equity share capital | B28: Share Capital | C28: Correct
A29: Other equity | B29: Reserves And Surplus/Other Equity | C29: Correct
A30: Total Equity | B30: Total Share Holder's Funds | C30: Correct
A31: LIABILITIES | B31: Lable | C31: Correct
A32: Non - current liabilities | B32: Lable | C32: Correct
A33: Financial Liabilities | B33: Lable | C33: Correct
A34: Borrowings | B34: Borrowings | C34: Correct | D34: Borrowings | E34: 20223
A35: Other financial liabilities | B35: Other Non Current Financial Liabilities | C35: Correct
A36: Provisions | B36: Long-Term Provisions | C36: Correct
A37: Deferred Tax Liabilities | B37: Deferred Tax Liability (Net) | C37: Correct
A38: Total non - current liabilities | B38: Total Non-Current Liabilities | C38: Correct
A39: Current liabilities | B39: Lable | C39: Correct
A40: Financial liabilities | B40: Lable | C40: Correct
...

Sheet Consolidated Balance Sheet
A1: Particulars | B1: Cogencis Field | C1: Status | D1: Revised Field Mapping | E1: Field id | G1: Correct | H1: =COUNTIF(C:C,G1) -> 42
A2: Non - Current Assets | B2: Lable | C2: Correct | G2: Incorrect | H2: =COUNTIF(C:C,G2) -> 5
A3: Property, Plant and Equipment | B3: Property, Plant & Equipment | C3: Correct | G3: Accuracy % | H3: =H1/SUM(H1:H2) -> 0.89361702
A4: Capital work -in - progress | B4: Capital Work-In-Progress | C4: Correct
A5: Investment property | B5: Investment Property | C5: Correct
A6: Other Intangible assets | B6: Other Intangible Assets | C6: Correct
A7: Intangible assets under development | B7: Intangible assets under development | C7: Correct
A8: Financial assets | B8: Lable | C8: Correct
A9: Investments | B9: Non-Current Investments | C9: Correct
A10: Loans | B10: Loans, Current | C10: Incorrect | D10: Loans Non-Current | E10: 20217
A11: Others financial assets | B11: Other Current Financial Assets | C11: Incorrect | D11: Other Non-Current Financial Assets | E11: 20216
A12: Deferred tax assets(Net ) | B12: Deferred Tax Assets (Net) | C12: Correct
A13: Total Non - current assets | B13: Total Non-Current Assets | C13: Correct
A14: Current Assets | B14: Lable | C14: Correct
A15: Inventories | B15: Inventories | C15: Correct
A16: Financial Assets | B16: Lable | C16: Correct
A17: Investment | B17: Non-Current Investments | C17: Incorrect | D17: Current Investments | E17: 13724
A18: Trade receivables | B18: Trade Receivables | C18: Correct | D18: Trade Receivables | E18: 13780
A19: Cash and cash equivalents | B19: Cash And Cash Equivalents | C19: Correct
A20: Loans | B20: Loans, Current | C20: Correct
A21: Other financial assets | B21: Other Non-Current Financial Assets | C21: Incorrect | D21: Other Current Financial Assets | E21: 20231
A22: Current Tax Assets | B22: Current Tax Assets (Net) | C22: Correct
A23: Other currents assets | B23: Other Current Assets | C23: Correct
A24: Total current assets | B24: Total Current Assets | C24: Correct
A25: TOTAL ASSETS | B25: Total Assets | C25: Correct
A26: EQUITY AND LIABILITIES | B26: Lable | C26: Correct
A27: Equity | B27: Lable | C27: Correct
A28: Equity share capital | B28: Share Capital | C28: Correct
A29: Other equity | B29: Reserves And Surplus/Other Equity | C29: Correct
A30: Total Equity | B30: Total Share Holder's Funds | C30: Correct
A31: LIABILITIES | B31: Lable | C31: Correct
A32: Non - current liabilities | B32: Lable | C32: Correct
A33: Financial Liabilities | B33: Lable | C33: Correct
A34: Borrowings | B34: Borrowings | C34: Correct | D34: Borrowings | E34: 20223
A35: Other financial liabilities | B35: Other Non Current Financial Liabilities | C35: Correct
A36: Provisions | B36: Long-Term Provisions | C36: Correct
A37: Deferred Tax Liabilities | B37: Deferred Tax Liability (Net) | C37: Correct
A38: Total non - current liabilities | B38: Total Non-Current Liabilities | C38: Correct
A39: Current liabilities | B39: Lable | C39: Correct
A40: Financial liabilities | B40: Lable | C40: Correct
...

Sheet Standalone Cash Flow
A1: Particulars | B1: Cogencis Field | C1: Status | D1: Revised Field Mapping | E1: Field id | G1: Correct | H1: =COUNTIF(C:C,G1) -> 31
A2: Net Profit Before Tax and Extraordinary Items | B2: Net Profit Before Tax And Exceptional Item | C2: Correct | G2: Incorrect | H2: =COUNTIF(C:C,G2) -> 8
A3: ADJUSTMENTS FOR : | B3: Lable | C3: Correct | G3: Accuracy % | H3: =H1/SUM(H1:H2) -> 0.79487179
A4: Depreciation | B4: Depreciation and Amortisation Expense | C4: Correct
A5: (Gain) / Loss on Sales of Fixed Assets | B5: Loss On Sale Of Fixed Assets | C5: Incorrect | D5: Profit On Sale Of Fixed Assets | E5: 30576
A6: (Gain)/Loss On Sales of investments | B6: Profit On Sale Of Investments | C6: Correct
A7: Exchange Rate Difference / Extraordinary Items | B7: Trade Payables And Others | C7: Incorrect | D7: Foreign Exchange Gain / Loss | E7: 30414
A8: Interest Paid | B8: Interest Paid | C8: Incorrect | D8: Interest Expense | E8: 30479
A9: Interest Received | B9: Interest Income | C9: Incorrect | D9: Interest Income | E9: 30481
A10: Dividend on Investments | B10: Dividend Received | C10: Correct
A11: Investments Written Off | B11: Investment Written Off | C11: Correct
A12: Operating Profit Before Working Capital Changes | B12: Operating Profit Before Working Capital Changes | C12: Correct
A13: ADJUSTMENTS FOR MOVEMENT IN WORKING CAPITAL | B13: Lable | C13: Correct
A14: Trade Payable | B14: Trade Payables And Others | C14: Correct
A15: Employee Benefit Obigation | B15: Provisions | C15: Correct
A16: Short - Term Provisions | B16: Provisions | C16: Correct
A17: Other Current Liabilities | B17: Other Current and Non Current Liabilities | C17: Correct
A18: Trade Receivable | B18: Trade And Other Receivables | C18: Correct
A19: Other Current Assets | B19: Other Current and Non Current Assets | C19: Correct
A20: Other Financial Assets | B20: Adjustments for other financial assets, non-current | C20: Correct
A21: Inventories | B21: Inventories | C21: Correct
... A25: Net Cash from / ( used in ) Operating Activities | B25: Net Cash Flow From Operating Activities | C25: Correct
A26: CASH FLOW FROM INVESTING ACTIVITIES | B26: Net Cash Flow From Investing Activities | C26: Incorrect | D26: Label
A27: purchase of Property, plant and equipment | B27: Purchase Of Fixed Assets (Tangible / Intangible) | C27: Correct
A28: Sale of Property, plant and equipment | B28: Sale Of Fixed Assets (Tangible / Intangible) | C28: Correct
A29: Purchase of Investments | B29: Purchase Of Investments | C29: Correct
A30: Gain on Sale of Investments | B30: Profit On Sale Of Investments | C30: Incorrect | D30: Sale Of Investments | E30: 17563
A31: Dividend Received on Investments | B31: Dividend Received | C31: Correct
A32: Interest Received | B32: Interest Income | C32: Incorrect | D32: Interest Received | E32: 30485
A33: Net Cash from / ( used in ) Investing Activities | B33: Net Cash Flow From Investing Activities | C33: Correct
A34: CASH FLOW FROM FINANCING ACTIVITIES : | B34: Lable | C34: Correct
A35: Interest Paid | B35: Interest Paid | C35: Correct
A36: Net Cash from / ( used in ) Financing Activities | B36: Net Cash Flow From Financing Activities | C36: Correct
A37: Net Cash Inflow/ ( Outflow ) | B37: Net Increase in Cash and Cash Equivalents | C37: Correct
A38: Cash and Cash Equivalents as at 01.04.2025 (Opening Balance ) | B38: Cash and Cash Equivalents at the Beginning of the Year | C38: Correct
A39: Cash and Cash Equivalents as at 30.09.2025 (Closing Balance ) | B39: Cash and Cash Equivalents at the End of the Year | C39: Correct
A40: Net Increase / ( Decrease ) in Cash Cash Equivalents | B40: Net increase (decrease) in cash and cash equivalents before effect of exchange rate changes | C40: Incorrect | D40: Ignore this Field

Sheet Consolidated Cash Flow
A1: Particulars | B1: Cogencis Field | C1: Status | D1: Revised Field Mapping | E1: Field id | G1: Correct | H1: =COUNTIF(C:C,G1) -> 31
A2: Net Profit Before Tax and Extraordinary Items | B2: Net Profit Before Tax And Exceptional Item | C2: =VLOOKUP(A2,'Standalone Cash Flow'!A:C,3,0) -> Correct | G2: Incorrect | H2: =COUNTIF(C:C,G2) -> 8
A3: ADJUSTMENTS FOR : | B3: Lable | C3: =VLOOKUP(A3,'Standalone Cash Flow'!A:C,3,0) -> Correct | G3: Accuracy % | H3: =H1/SUM(H1:H2) -> 0.79487179
A4: Depreciation | B4: Depreciation and Amortisation Expense | C4: =VLOOKUP(A4,'Standalone Cash Flow'!A:C,3,0) -> Correct
A5: (Gain) / Loss on Sales of Fixed Assets | B5: Loss On Sale Of Fixed Assets | C5: Incorrect | D5: Profit On Sale Of Fixed Assets | E5: 30576
A6: (Gain) /Loss On Sales of Investments | B6: Profit On Sale Of Investments | C6: Correct
A7: Exchange Rate Difference / Extraordinary Items | B7: Trade Payables And Others | C7: =VLOOKUP(A7,'Standalone Cash Flow'!A:C,3,0) -> Incorrect | D7: Foreign Exchange Gain / Loss | E7: 30414
A8: Interest Paid | B8: Interest Paid | C8: =VLOOKUP(A8,'Standalone Cash Flow'!A:C,3,0) -> Incorrect | D8: Interest Expense | E8: 30479
A9: Interest Received | B9: Interest Income | C9: =VLOOKUP(A9,'Standalone Cash Flow'!A:C,3,0) -> Incorrect | D9: Interest Income | E9: 30481
A10: Dividend on Investments | B10: Dividend Received | C10: =VLOOKUP(A10,'Standalone Cash Flow'!A:C,3,0) -> Correct
A11: Investments Written Off | B11: Investment Written Off | C11: =VLOOKUP(A11,'Standalone Cash Flow'!A:C,3,0) -> Correct
A12: Operating Profit Before Working Capital Changes | B12: Operating Profit Before Working Capital Changes | C12: =VLOOKUP(A12,'Standalone Cash Flow'!A:C,3,0) -> Correct
A13: ADJUSTMENTS FOR MOVEMENT IN WORKING CAPITAL | B13: Lable | C13: =VLOOKUP(A13,'Standalone Cash Flow'!A:C,3,0) -> Correct
A14: Trade Payable | B14: Trade Payables And Others | C14: =VLOOKUP(A14,'Standalone Cash Flow'!A:C,3,0) -> Correct
A15: Employee Benefit Obigation | B15: Provisions | C15: =VLOOKUP(A15,'Standalone Cash Flow'!A:C,3,0) -> Correct
A16: Short - Term Provisions | B16: Provisions | C16: =VLOOKUP(A16,'Standalone Cash Flow'!A:C,3,0) -> Correct
A17: Other Current Liabilities | B17: Other Current and Non Current Liabilities | C17: =VLOOKUP(A17,'Standalone Cash Flow'!A:C,3,0) -> Correct
A18: Trade Receivable | B18: Trade And Other Receivables | C18: =VLOOKUP(A18,'Standalone Cash Flow'!A:C,3,0) -> Correct
A19: Other Current Assets | B19: Other Current and Non Current Assets | C19: =VLOOKUP(A19,'Standalone Cash Flow'!A:C,3,0) -> Correct
A20: Other Financial Assets | B20: Adjustments for other financial assets, non-current | C20: =VLOOKUP(A20,'Standalone Cash Flow'!A:C,3,0) -> Correct
A21: Inventories | B21: Inventories | C21: =VLOOKUP(A21,'Standalone Cash Flow'!A:C,3,0) -> Correct
... A25: Net Cash from / ( used in ) Operating Activities | B25: Net Cash Flow From Operating Activities | C25: =VLOOKUP(A25,'Standalone Cash Flow'!A:C,3,0) -> Correct
A26: CASH FLOW FROM INVESTING ACTIVITIES | B26: Net Cash Flow From Investing Activities | C26: =VLOOKUP(A26,'Standalone Cash Flow'!A:C,3,0) -> Incorrect | D26: Label
A27: Purchase of Property, plant and equipment | B27: Purchase Of Fixed Assets (Tangible / Intangible) | C27: =VLOOKUP(A27,'Standalone Cash Flow'!A:C,3,0) -> Correct
A28: Sale of Property, plant and equipment | B28: Sale Of Fixed Assets (Tangible / Intangible) | C28: =VLOOKUP(A28,'Standalone Cash Flow'!A:C,3,0) -> Correct
A29: Purchase of Investments | B29: Purchase Of Investments | C29: =VLOOKUP(A29,'Standalone Cash Flow'!A:C,3,0) -> Correct
A30: Gain on Sale of Investments | B30: Profit On Sale Of Investments | C30: =VLOOKUP(A30,'Standalone Cash Flow'!A:C,3,0) -> Incorrect | D30: Sale Of Investments | E30: 17563
A31: Dividend Received on Investments | B31: Dividend Received | C31: =VLOOKUP(A31,'Standalone Cash Flow'!A:C,3,0) -> Correct
A32: Interest Received | B32: Interest Income | C32: =VLOOKUP(A32,'Standalone Cash Flow'!A:C,3,0) -> Incorrect | D32: Interest Received | E32: 30485
A33: Net Cash from / ( used in ) Investing Activities | B33: Net Cash Flow From Investing Activities | C33: =VLOOKUP(A33,'Standalone Cash Flow'!A:C,3,0) -> Correct
A34: CASH FLOW FROM FINANCING ACTIVITIES : | B34: Lable | C34: =VLOOKUP(A34,'Standalone Cash Flow'!A:C,3,0) -> Correct
A35: Interest Paid | B35: Interest Paid | C35: Correct
A36: Net Cash from / ( used in ) Financing Activities | B36: Net Cash Flow From Financing Activities | C36: =VLOOKUP(A36,'Standalone Cash Flow'!A:C,3,0) -> Correct
A37: Net Cash Inflow / ( Outflow ) | B37: Net Increase in Cash and Cash Equivalents | C37: Correct
A38: Cash and Cash Equivalents as at 01.04.2025 (Opening Balance ) | B38: Cash and Cash Equivalents at the Beginning of the Year | C38: =VLOOKUP(A38,'Standalone Cash Flow'!A:C,3,0) -> Correct
A39: Cash and Cash Equivalents as at 30.09.2025 (Closing Balance ) | B39: Cash and Cash Equivalents at the End of the Year | C39: =VLOOKUP(A39,'Standalone Cash Flow'!A:C,3,0) -> Correct
A40: Net Increase / ( Decrease ) In Cash Cash Equivalents | B40: Net increase (decrease) in cash and cash equivalents before effect of exchange rate changes | C40: =VLOOKUP(A40,'Standalone Cash Flow'!A:C,3,0) -> Incorrect | D40: Ignore this Field
