Workbook

Sheet P&L_Standalone
A1: Particulars | B1: Cogencis Field | C1: Field id
A2: Income | B2: Lable
A3: Revenue from operations | B3: Gross Sales/Income from Operations | C3: 256
A4: Other income | B4: Miscellaneous Income | C4: 265
A5: Total income | B5: Total Income | C5: 25238
A6: Expense | B6: Lable
A7: Inventory and data costs | B7: Operating Expenses | C7: 276
A8: Employee benefits expense | B8: Employee Benefit Expense | C8: 238
A9: Finance costs | B9: Finance Costs | C9: 246
A10: Depreciation and amortisation expenses | B10: Depreciation, Depletion and Amortisation Expense | C10: 232
A11: Other expenses | B11: Other Expenses | C11: 279
A12: Total expenses | B12: Total Expenses | C12: 320
A13: Profit before tax | B13: Profit/(Loss) From Ordinary Activities before Tax | C13: 296
A14: Tax expense: | B14: Lable
A15: Current tax (including earlier year) | B15: Tax Expense | C15: 318
A16: Deferred tax (credit)/charge | B16: Deferred Tax | C16: 231
A17: Total tax expense | B17: Lable
A18: Profit for the periods / year | B18: Net Profit/(Loss) for the Period | C18: 269
A19: Other comprehensive income | B19: Lable
A20: Items that will not be reclassified to profit or loss in subsequent years | B20: Items that will not be reclassified to Profit or Loss | C20: 22293
A21: Re-measurement (losses)/ gains on defined benefit plans | B21: Items that will not be reclassified to Profit or Loss | C21: 22293
A22: Income tax effect | B22: Income Tax related to items that will not be reclassified to Profit or Loss | C22: 22295
A23: Other comprehensive (losses)/gains net of income tax | B23: Other Comprehensive Income | C23: 16484
A24: Total comprehensive income for the periods / year | B24: Total Comprehensive Gain (Loss) For the Year | C24: 20019
A25: Paid-up equity share capital (face value INR 2/- per equity share) | B25: Paid-Up Equity Share Capital | C25: 282
A26: Other equity for the years | B26: Reserve excluding Revaluation Reserves (as per Balance Sheet of Previous Accounting Year) | C26: 309
A27: Earnings per equity share (face value INR 2/- per equity share) (not annualised for quarters): | B27: Lable
A28: Basic | B28: Basic EPS | C28: 222
A29: Diluted | B29: Diluted EPS | C29: 234

Sheet P&L_Consolidated
A1: Particulars | B1: Cogencis Field | C1: Field id
A2: Income | B2: Lable
A3: Revenue from operations | B3: Gross Sales/Income from Operations | C3: 256
A4: Other income | B4: Miscellaneous Income | C4: 265
A5: Total income | B5: Total Income | C5: 25238
A6: Expense | B6: Lable
A7: Inventory and data costs | B7: Operating Expenses | C7: 276
A8: Employee benefits expense | B8: Employee Benefit Expense | C8: 238
A9: Finance costs | B9: Finance Costs | C9: 246
A10: Depreciation and amortisation expenses | B10: Depreciation, Depletion and Amortisation Expense | C10: 232
A11: Other expenses | B11: Other Expenses | C11: 279
A12: Total expense | B12: Total Expenses | C12: 320
A13: Profit before tax | B13: Profit/(Loss) From Ordinary Activities before Tax | C13: 296
A14: Tax expense: | B14: Lable
A15: Current tax (including earlier year) | B15: Tax Expense | C15: 318
A16: Deferred tax (credit) /charge | B16: Deferred Tax | C16: 231
A17: Total tax expense | B17: Lable
A18: Profit for the periods/year | B18: Net Profit/(Loss) for the Period | C18: 269
A19: Other comprehensive income | B19: Lable
A20: Items that will be reclassified to profit or loss in subsequent years | B20: Items that will be reclassified to Profit or Loss | C20: 22294
A21: Exchange differences on translating the financial statements of a foreign operation | B21: Items that will be reclassified to Profit or Loss | C21: 22294
A22: Hyperinflation adjustment in opening retained earnings | B22: Items that will be reclassified to Profit or Loss | C22: 22294
A23: Items that will not be reclassified to profit or loss in subsequent years | B23: Items that will not be reclassified to Profit or Loss | C23: 22293
A24: Re-measurement (losses)/ gains on defined benefit plans | B24: Items that will not be reclassified to Profit or Loss | C24: 22293
A25: Income tax effect | B25: Income Tax related to items that will not be reclassified to Profit or Loss | C25: 22295
A26: Other comprehensive gains/ (loss) net of tax | B26: Other Comprehensive Income | C26: 16484
A27: Total comprehensive income for the periods year | B27: Total Comprehensive Gain (Loss) For the Year | C27: 20019
A28: Profit for the periods/year attributable to: | B28: Profit (Loss) Attributable To [Total] | C28: 22300
A29: Equity holders of the parent | B29: Owners of the company | C29: 22299
A30: Other comprehensive income/(loss) for the periods/year attributable to: | B30: Comprehensive Income Attributable To [Total] | C30: 22292
A31: Equity holders of the parent | B31: Owners of the company | C31: 22291
... A35: Other equity for the years | B35: Reserve excluding Revaluation Reserves (as per Balance Sheet of Previous Accounting Year) | C35: 309
A36: Earnings per equity share (face value INR 2/- per equity share) (not annualised for quarters): | B36: Lable
A37: Basic | B37: Basic EPS | C37: 222
A38: Diluted | B38: Diluted EPS | C38: 234

Sheet BS_Standalone
A1: Particulars | B1: Cogencis Field | C1: Field id
A2: ASSETS | B2: Lable
A3: Non-current assets | B3: Lable
A4: Property, plant and equipment | B4: Property, Plant & Equipment | C4: 20222
A5: Right-of-use assets | B5: Right-of-use asset | C5: 30342
A6: Goodwill | B6: Goodwill | C6: 20220
A7: Other intangible assets | B7: Other Intangible Assets | C7: 20221
A8: Intangible assets under development | B8: Intangible assets under development | C8: 13736
A9: Financial assets | B9: Lable
A10: Investments | B10: Non-Current Investments | C10: 13748
A11: Other financial assets | B11: Other Non-Current Financial Assets | C11: 20216
A12: Income tax asset (net) | B12: Income Tax assets (net) | C12: 20215
A13: Other non current assets | B13: Other Non-Current Assets | C13: 13753
A14: Total non-current assets | B14: Total Non-Current Assets | C14: 13777
A15: Current assets | B15: Lable
A16: Contract assets (net) | B16: Other Current Assets | C16: 13750
A17: Financial assets | B17: Lable
A18: Trade receivables (net) | B18: Trade Receivables | C18: 13780
A19: Cash and cash equivalents | B19: Cash And Cash Equivalents | C19: 13722
A20: Bank balances other than cash and cash equivalents above | B20: Bank balance other than cash and cash equivalents | C20: 29788
A21: Loans | B21: Loans, Current | C21: 20230
A22: Other financial assets | B22: Other Current Financial Assets | C22: 20231
A23: Other current assets | B23: Other Current Assets | C23: 13750
A24: Investments held for sale | B24: Assets classified as held for sale | C24: 20208
A25: Total current assets | B25: Total Current Assets | C25: 13774
A26: Total assets | B26: Total Assets | C26: 13771
A27: EQUITY AND LIABILITIES | B27: Lable
A28: EQUITY | B28: Lable
A29: Equity share capital | B29: Share Capital | C29: 13765
A30: Other equity | B30: Lable
A31: Retained earnings | B31: Reserves And Surplus/Other Equity | C31: 13762
A32: Securities premium | B32: Reserves And Surplus/Other Equity | C32: 13762
A33: Treasury shares | B33: Reserves And Surplus/Other Equity | C33: 13762
A34: Share based payments reserves | B34: Reserves And Surplus/Other Equity | C34: 13762
A35: Total other equity
A36: Total equity | B36: Total Share Holder's Funds | C36: 13773
A37: LIABILITIES | B37: Lable
A38: Non-current liabilities | B38: Lable
A39: Financial liabilities | B39: Lable
A40: Lease liabilities | B40: Lease liabilities | C40: 30340
...

Sheet BS_Consolidated
A1: Particulars | B1: Cogencis Field | C1: Field id
A2: ASSETS | B2: Lable
A3: Non-current assets | B3: Lable
A4: Property, plant and equipment | B4: Property, Plant & Equipment | C4: 20222
A5: Right-of-use assets | B5: Right-of-use asset | C5: 30342
A6: Goodwill | B6: Goodwill On Consolidation | C6: 13734
A7: Other intangible assets | B7: Other Intangible Assets | C7: 20221
A8: Intangible assets under development | B8: Intangible assets under development | C8: 13736
A9: Financial assets | B9: Lable
A10: Investments | B10: Non-Current Investments | C10: 13748
A11: Other financial assets | B11: Other Non-Current Financial Assets | C11: 20216
A12: Deferred tax assets (net) | B12: Deferred Tax Assets (Net) | C12: 13726
A13: Income tax assets (net) | B13: Income Tax assets (net) | C13: 20215
A14: Other non current assets | B14: Other Non-Current Assets | C14: 13753
A15: Total non-current assets | B15: Total Non-Current Assets | C15: 13777
A16: Current assets | B16: Lable
A17: Contract assets (net) | B17: Other Current Assets | C17: 13750
A18: Financial assets | B18: Lable
A19: Trade receivables (net) | B19: Trade Receivables | C19: 13780
A20: Cash and cash equivalents | B20: Cash And Cash Equivalents | C20: 13722
A21: Bank balances other than cash and cash equivalents above | B21: Bank balance other than cash and cash equivalents | C21: 29788
A22: Loans | B22: Loans, Current | C22: 20230
A23: Other financial assets | B23: Other Current Financial Assets | C23: 20231
A24: Other current assets | B24: Other Current Assets | C24: 13750
A25: Investments held for sale | B25: Assets classified as held for sale | C25: 20208
A26: Total current assets | B26: Total Current Assets | C26: 13774
A27: Total assets | B27: Total Assets | C27: 13771
A28: EQUITY AND LIABILITIES | B28: Lable
A29: EQUITY | B29: Lable
A30: Equity share capital | B30: Share Capital | C30: 13765
A31: Other equity | B31: Lable
A32: Retained earnings | B32: Reserves And Surplus/Other Equity | C32: 13762
A33: Capital reserve | B33: Reserves And Surplus/Other Equity | C33: 13762
A34: Securities premium | B34: Reserves And Surplus/Other Equity | C34: 13762
A35: Treasury shares | B35: Reserves And Surplus/Other Equity | C35: 13762
A36: Share based payments reserve | B36: Reserves And Surplus/Other Equity | C36: 13762
A37: Other reserves | B37: Reserves And Surplus/Other Equity | C37: 13762
A38: Total other equity
A39: Total equity | B39: Total Share Holder's Funds | C39: 13773
A40: LIABILITIES | B40: Lable
...

Sheet CFS_Standalone
A1: Particulars | B1: Cogencis Field | C1: Field id
A2: Cash flow from operating activities | B2: Lable
A3: Profit before tax | B3: Net Profit Before Tax And Exceptional Item | C3: 17539
A4: Adjustments for: | B4: Lable
A5: Depreciation and amortisation expense | B5: Depreciation and Amortisation Expense | C5: 30399
A6: Interest on lease liabilities | B6: Interest Expense | C6: 30479
A7: Impairment allowance of trade receivables and contract assets | B7: Provision For Doubtful Debts | C7: 30631
A8: Liabilities written back | B8: Other Provisions Written Off | C8: 30520
A9: Loss /(Gain) on disposal of property, plant and equipment (net) | B9: Loss On Sale Of Fixed Assets | C9: 30502
A10: Interest income | B10: Interest Income | C10: 30481
A11: Interest expense | B11: Interest Expense | C11: 30479
A12: Unrealised foreign exchange gain | B12: Foreign Exchange Gain / Loss | C12: 30414
A13: Share based payments | B13: Employees Stock Options Grants | C13: 30407
A14: Gain on overnight fund | B14: Profit / Loss from Deployment in Mutual Funds | C14: 30575
A15: Operating profit before working capital changes | B15: Operating Profit Before Working Capital Changes | C15: 30511
A16: Change in working capital: | B16: Lable
A17: Contract assets | B17: Other Current and Non Current Assets | C17: 30518
A18: Trade receivables | B18: Trade And Other Receivables | C18: 30674
A19: Financial assets | B19: Adjustments for other financial assets, non-current | C19: 30452
A20: Other current assets | B20: Other Current and Non Current Assets | C20: 30518
A21: Contract liabilities | B21: Other Current and Non Current Liabilities | C21: 30519
A22: Trade payables | B22: Trade Payables And Others | C22: 30675
A23: Other financial liabilities | B23: Adjustments for other financial liabilities, non-current | C23: 30454
A24: Other current liabilities | B24: Other Current and Non Current Liabilities | C24: 30519
A25: Provisions | B25: Provisions | C25: 30627
A26: Net cash generated from operations | B26: Cash Generated From Operations | C26: 30372
A27: Direct taxes paid (net of refunds) | B27: Income Tax Paid | C27: 30422
A28: Net cash generated/(used in) from operating activities | B28: Net Cash Flow From Operating Activities | C28: 17538
A29: Cash flow from investing activities: | B29: Lable
A30: Purchase of property, plant and equipment, other intangible assets including intangible assets under development | B30: Purchase Of Fixed Assets (Tangible / Intangible) | C30: 17556
A31: Proceeds from sale of property, plant and equipment | B31: Sale Of Fixed Assets (Tangible / Intangible) | C31: 30662
A32: Investments in bank deposits (halving original maturity of more than three months) | B32: Fixed Deposits | C32: 30412
A33: Redemption of bank deposits (having original maturity of more than three months) | B33: Fixed Deposits | C33: 30412
A34: Investments in bank deposits (having original maturity of more than one year) | B34: Fixed Deposits | C34: 30412
A35: Investments made during the period | B35: Others-Investing Activities | C35: 17545
A36: Interest income | B36: Interest Received | C36: 30485
A37: Loan given to related party | B37: Loans To Subsidiaries | C37: 30499
A38: Loan received back from related party | B38: Cash Receipts from Repayment of Advances and Loans Made to Other Parties | C38: 30375
A39: Gain on overnight fund | B39: Investment Income | C39: 30488
A40: Net cash (used in)/generated from investing activities | B40: Net Cash Flow From Investing Activities | C40: 17537
...

Sheet CFS_Consolidated
A1: Particulars | B1: Cogencis Field | C1: Field id
A2: Cash flow from operating activities | B2: =_xlfn.XLOOKUP(A2,CFS_Standalone!A:A,CFS_Standalone!B:B) -> Lable
A3: Profit before tax | B3: =_xlfn.XLOOKUP(A3,CFS_Standalone!A:A,CFS_Standalone!B:B) -> Net Profit Before Tax And Exceptional Item | C3: =_xlfn.XLOOKUP(A3,CFS_Standalone!A:A,CFS_Standalone!C:C) -> 17539
A4: Adjustments for: | B4: =_xlfn.XLOOKUP(A4,CFS_Standalone!A:A,CFS_Standalone!B:B) -> Lable
A5: Depreciation and amortisation expense | B5: =_xlfn.XLOOKUP(A5,CFS_Standalone!A:A,CFS_Standalone!B:B) -> Depreciation and Amortisation Expense | C5: =_xlfn.XLOOKUP(A5,CFS_Standalone!A:A,CFS_Standalone!C:C) -> 30399
A6: Interest on lease liabilities | B6: =_xlfn.XLOOKUP(A6,CFS_Standalone!A:A,CFS_Standalone!B:B) -> Interest Expense | C6: =_xlfn.XLOOKUP(A6,CFS_Standalone!A:A,CFS_Standalone!C:C) -> 30479
A7: Impairment allowance of trade receivables and contracts assets | B7: Provision For Doubtful Debts | C7: 30631
A8: Liabilities written back | B8: =_xlfn.XLOOKUP(A8,CFS_Standalone!A:A,CFS_Standalone!B:B) -> Other Provisions Written Off | C8: =_xlfn.XLOOKUP(A8,CFS_Standalone!A:A,CFS_Standalone!C:C) -> 30520
A9: Loss on disposal of property plant and equipment (net) | B9: Profit On Sale Of Fixed Assets | C9: 30576
A10: Interest income | B10: =_xlfn.XLOOKUP(A10,CFS_Standalone!A:A,CFS_Standalone!B:B) -> Interest Income | C10: =_xlfn.XLOOKUP(A10,CFS_Standalone!A:A,CFS_Standalone!C:C) -> 30481
A11: Interest expense | B11: =_xlfn.XLOOKUP(A11,CFS_Standalone!A:A,CFS_Standalone!B:B) -> Interest Expense | C11: =_xlfn.XLOOKUP(A11,CFS_Standalone!A:A,CFS_Standalone!C:C) -> 30479
A12: Unrealised foreign exchange loss/ (gains) | B12: Foreign Exchange Gain / Loss | C12: 30414
A13: Fair value gain on financial instruments/liabilities | B13: Others-Before Working Capital Changes | C13: 17542
A14: Share based payments | B14: =_xlfn.XLOOKUP(A14,CFS_Standalone!A:A,CFS_Standalone!B:B) -> Employees Stock Options Grants | C14: =_xlfn.XLOOKUP(A14,CFS_Standalone!A:A,CFS_Standalone!C:C) -> 30407
A15: Gain on overnight fund | B15: =_xlfn.XLOOKUP(A15,CFS_Standalone!A:A,CFS_Standalone!B:B) -> Profit / Loss from Deployment in Mutual Funds | C15: =_xlfn.XLOOKUP(A15,CFS_Standalone!A:A,CFS_Standalone!C:C) -> 30575
A16: Operating profit before working capital changes | B16: =_xlfn.XLOOKUP(A16,CFS_Standalone!A:A,CFS_Standalone!B:B) -> Operating Profit Before Working Capital Changes | C16: =_xlfn.XLOOKUP(A16,CFS_Standalone!A:A,CFS_Standalone!C:C) -> 30511
A17: Change in working capital: | B17: =_xlfn.XLOOKUP(A17,CFS_Standalone!A:A,CFS_Standalone!B:B) -> Lable
A18: Contract assets | B18: =_xlfn.XLOOKUP(A18,CFS_Standalone!A:A,CFS_Standalone!B:B) -> Other Current and Non Current Assets | C18: =_xlfn.XLOOKUP(A18,CFS_Standalone!A:A,CFS_Standalone!C:C) -> 30518
A19: Trade receivables | B19: =_xlfn.XLOOKUP(A19,CFS_Standalone!A:A,CFS_Standalone!B:B) -> Trade And Other Receivables | C19: =_xlfn.XLOOKUP(A19,CFS_Standalone!A:A,CFS_Standalone!C:C) -> 30674
A20: Financial assets | B20: =_xlfn.XLOOKUP(A20,CFS_Standalone!A:A,CFS_Standalone!B:B) -> Adjustments for other financial assets, non-current | C20: =_xlfn.XLOOKUP(A20,CFS_Standalone!A:A,CFS_Standalone!C:C) -> 30452
A21: Other assets | B21: Other Current and Non Current Assets | C21: 30518
A22: Contract liabilities | B22: =_xlfn.XLOOKUP(A22,CFS_Standalone!A:A,CFS_Standalone!B:B) -> Other Current and Non Current Liabilities | C22: =_xlfn.XLOOKUP(A22,CFS_Standalone!A:A,CFS_Standalone!C:C) -> 30519
A23: Trade payables | B23: =_xlfn.XLOOKUP(A23,CFS_Standalone!A:A,CFS_Standalone!B:B) -> Trade Payables And Others | C23: =_xlfn.XLOOKUP(A23,CFS_Standalone!A:A,CFS_Standalone!C:C) -> 30675
A24: Other financial liabilities | B24: =_xlfn.XLOOKUP(A24,CFS_Standalone!A:A,CFS_Standalone!B:B) -> Adjustments for other financial liabilities, non-current | C24: =_xlfn.XLOOKUP(A24,CFS_Standalone!A:A,CFS_Standalone!C:C) -> 30454
A25: Other liabilities | B25: Other Current and Non Current Liabilities | C25: 30519
A26: Provisions | B26: =_xlfn.XLOOKUP(A26,CFS_Standalone!A:A,CFS_Standalone!B:B) -> Provisions | C26: =_xlfn.XLOOKUP(A26,CFS_Standalone!A:A,CFS_Standalone!C:C) -> 30627
A27: Net cash generated from operations | B27: =_xlfn.XLOOKUP(A27,CFS_Standalone!A:A,CFS_Standalone!B:B) -> Cash Generated From Operations | C27: =_xlfn.XLOOKUP(A27,CFS_Standalone!A:A,CFS_Standalone!C:C) -> 30372
A28: Direct taxes paid (net of refunds) | B28: =_xlfn.XLOOKUP(A28,CFS_Standalone!A:A,CFS_Standalone!B:B) -> Income Tax Paid | C28: =_xlfn.XLOOKUP(A28,CFS_Standalone!A:A,CFS_Standalone!C:C) -> 30422
A29: Net cash generated from operating activities | B29: Net Cash Flow From Operating Activities | C29: 17538
A30: Cash flow from investing activities: | B30: Lable
A31: Purchase of property, plant and equipment other intangible assets including intangible assets under development | B31: Purchase Of Fixed Assets (Tangible / Intangible) | C31: 17556
A32: Acquisition of a subsidiary, net of cash acquired | B32: Acquisition Of Companies | C32: 17772
A33: Acquisition of non controlling interest | B33: Acquisition Of Companies | C33: 17772
A34: Investments in bank deposits (having original maturity of more than three months) | B34: Fixed Deposits | C34: 30412
A35: Redemption of bank deposits (having original maturity of more than three months) | B35: Fixed Deposits | C35: 30412
A36: Purchase of investement | B36: Purchase Of Investments | C36: 17557
A37: Interest received | B37: Interest Received | C37: 30485
A38: Gain on overnight fund | B38: Investment Income | C38: 30488
A39: Net cash used in investing activities | B39: Net Cash Flow From Investing Activities | C39: 17537
A40: Cash flow from financing activities: | B40: Lable
...

Sheet SR_Standalone
A1: Particulars | B1: Cogencis Field | C1: Field id

Sheet SR_Consolidated
A1: Particulars | B1: Cogencis Field | C1: Field id
