Workbook

Sheet P&L_Standalone
A1: Particulars | B1: Cogencis Field | C1: Field id
A2: Revenue from Operation | B2: Gross Sales/Income from Operations | C2: 256
A3: Other Income | B3: Miscellaneous Income | C3: 265
A4: Total Income | B4: Total Income | C4: 25238
A5: Expenses | B5: Lable
A6: Purchase of Stock in Trade | B6: Purchase of Stock-in-Trade | C6: 307
A7: Employee benefit expenses | B7: Employee Benefit Expense | C7: 238
A8: Finance Cost | B8: Finance Costs | C8: 246
A9: Depreciation and Amortisation Expenses | B9: Depreciation, Depletion and Amortisation Expense | C9: 232
A10: Other Expenditure | B10: Other Expenses | C10: 279
A11: Total Expenses | B11: Total Expenses | C11: 320
A12: Profit/ (loss) before exceptional Item & Tax | B12: Profit/(Loss) from Ordinary Activities after Finance Costs but before Exceptional Items | C12: 294
A13: Exceptional Items | B13: Other Exceptional Items | C13: 278
A14: Total Exceptional Items | B14: Total Exceptional Items | C14: 319
A15: Profit before tax | B15: Profit/(Loss) From Ordinary Activities before Tax | C15: 296
A16: Tax expense | B16: Lable
A17: Current tax | B17: Tax Expense | C17: 318
A18: Deffered tax | B18: Deferred Tax | C18: 231
A19: Profit/ (loss) for the period | B19: Net Profit/(Loss) for the Period | C19: 269
A20: Other Comprehensive Income | B20: Lable | C20: 0
A21: Items that will not be reclassified to profit or (loss) | B21: Items that will not be reclassified to Profit or Loss | C21: 22293
A22: Income tax relating to items that will not be reclassified to profit or (loss) | B22: Income Tax related to items that will not be reclassified to Profit or Loss | C22: 22295
A23: Items that will be reclassified to profit or (loss) | B23: Items that will be reclassified to Profit or Loss | C23: 22294
A24: Income tax relating to items that will be reclassified to profit or (loss) | B24: Income Tax related to items that will be reclassified to Profit or Loss | C24: 22296
A25: Total | B25: Other Comprehensive Income | C25: 16484
A26: Total Comprehsive income for the period | B26: Total Comprehensive Gain (Loss) For the Year | C26: 20019
A27: Paid up Equity share value Capital (Face Value Rs 2/-) | B27: Paid-Up Equity Share Capital | C27: 282
A28: Earning per Equity Share of Rs2/- Each :
A29: Basic EPS | B29: Basic EPS | C29: 222
A30: Diluted EPS | B30: Diluted EPS | C30: 234
A31: PART II (Select Information for the Quarter Ended 30TH SEPT., 2020 | B31: Lable
A32: PARTICULARS OF SHAREHOLDING | B32: Lable
A33: Public Shareholding | B33: Lable
A34: Number of Shares | B34: Number of shares | C34: 275
A35: Percentage of shareholding | B35: Percentage of shareholding | C35: 287
A36: Promoter and promoter group shareholding | B36: Lable
A37: Pledged/Encumbered | B37: Lable
A38: Pledged/Encumbered | B38: Lable
A39: Non-encumbered | B39: Lable
A40: Number of Shares | B40: Number of shares | C40: 274
...

Sheet P&L_Consolidated
A1: Particulars | B1: Cogencis Field | C1: Field id
A2: Revenue from Operation | B2: =_xlfn.XLOOKUP(A2,'P&L_Standalone'!A:A,'P&L_Standalone'!B:B) -> Gross Sales/Income from Operations | C2: =_xlfn.XLOOKUP(A2,'P&L_Standalone'!A:A,'P&L_Standalone'!C:C) -> 256
A3: Other Income | B3: =_xlfn.XLOOKUP(A3,'P&L_Standalone'!A:A,'P&L_Standalone'!B:B) -> Miscellaneous Income | C3: =_xlfn.XLOOKUP(A3,'P&L_Standalone'!A:A,'P&L_Standalone'!C:C) -> 265
A4: Total Income | B4: =_xlfn.XLOOKUP(A4,'P&L_Standalone'!A:A,'P&L_Standalone'!B:B) -> Total Income | C4: =_xlfn.XLOOKUP(A4,'P&L_Standalone'!A:A,'P&L_Standalone'!C:C) -> 25238
A5: Expenses | B5: =_xlfn.XLOOKUP(A5,'P&L_Standalone'!A:A,'P&L_Standalone'!B:B) -> Lable
A6: Purchase of Stock in Trade | B6: =_xlfn.XLOOKUP(A6,'P&L_Standalone'!A:A,'P&L_Standalone'!B:B) -> Purchase of Stock-in-Trade | C6: =_xlfn.XLOOKUP(A6,'P&L_Standalone'!A:A,'P&L_Standalone'!C:C) -> 307
A7: Employee benefit expenses | B7: =_xlfn.XLOOKUP(A7,'P&L_Standalone'!A:A,'P&L_Standalone'!B:B) -> Employee Benefit Expense | C7: =_xlfn.XLOOKUP(A7,'P&L_Standalone'!A:A,'P&L_Standalone'!C:C) -> 238
A8: Finance Cost | B8: =_xlfn.XLOOKUP(A8,'P&L_Standalone'!A:A,'P&L_Standalone'!B:B) -> Finance Costs | C8: =_xlfn.XLOOKUP(A8,'P&L_Standalone'!A:A,'P&L_Standalone'!C:C) -> 246
A9: Depreciation and Amortisation Expenses | B9: =_xlfn.XLOOKUP(A9,'P&L_Standalone'!A:A,'P&L_Standalone'!B:B) -> Depreciation, Depletion and Amortisation Expense | C9: =_xlfn.XLOOKUP(A9,'P&L_Standalone'!A:A,'P&L_Standalone'!C:C) -> 232
A10: Other Expenditure | B10: =_xlfn.XLOOKUP(A10,'P&L_Standalone'!A:A,'P&L_Standalone'!B:B) -> Other Expenses | C10: =_xlfn.XLOOKUP(A10,'P&L_Standalone'!A:A,'P&L_Standalone'!C:C) -> 279
A11: Total Expenses | B11: =_xlfn.XLOOKUP(A11,'P&L_Standalone'!A:A,'P&L_Standalone'!B:B) -> Total Expenses | C11: =_xlfn.XLOOKUP(A11,'P&L_Standalone'!A:A,'P&L_Standalone'!C:C) -> 320
A12: Profit/ (loss) before exceptional Item & Tax | B12: =_xlfn.XLOOKUP(A12,'P&L_Standalone'!A:A,'P&L_Standalone'!B:B) -> Profit/(Loss) from Ordinary Activities after Finance Costs but before Exceptional Items | C12: =_xlfn.XLOOKUP(A12,'P&L_Standalone'!A:A,'P&L_Standalone'!C:C) -> 294
A13: Exceptional Items | B13: =_xlfn.XLOOKUP(A13,'P&L_Standalone'!A:A,'P&L_Standalone'!B:B) -> Other Exceptional Items | C13: =_xlfn.XLOOKUP(A13,'P&L_Standalone'!A:A,'P&L_Standalone'!C:C) -> 278
A14: Total Exceptional Items | B14: Total Exceptional Items | C14: 319
A15: Profit before tax | B15: =_xlfn.XLOOKUP(A15,'P&L_Standalone'!A:A,'P&L_Standalone'!B:B) -> Profit/(Loss) From Ordinary Activities before Tax | C15: =_xlfn.XLOOKUP(A15,'P&L_Standalone'!A:A,'P&L_Standalone'!C:C) -> 296
A16: Tax expense | B16: =_xlfn.XLOOKUP(A16,'P&L_Standalone'!A:A,'P&L_Standalone'!B:B) -> Lable
A17: Current tax | B17: =_xlfn.XLOOKUP(A17,'P&L_Standalone'!A:A,'P&L_Standalone'!B:B) -> Tax Expense | C17: =_xlfn.XLOOKUP(A17,'P&L_Standalone'!A:A,'P&L_Standalone'!C:C) -> 318
A18: Deffered tax | B18: =_xlfn.XLOOKUP(A18,'P&L_Standalone'!A:A,'P&L_Standalone'!B:B) -> Deferred Tax | C18: =_xlfn.XLOOKUP(A18,'P&L_Standalone'!A:A,'P&L_Standalone'!C:C) -> 231
A19: Profit/ (loss) for the period | B19: Net Profit/(Loss) After Taxes But Before Share of Profit/(Loss) of Associates and Minority Interest | C19: 268
A20: Shares of Profit/(Loss) of associates | B20: Share of Profit/(Loss) of Associates/Joint Ventures | C20: 292
A21: Net Profit/(Loss) for the Period | B21: Net Profit/(Loss) for the Period | C21: 269
A22: Other Comprehensive Income | B22: =_xlfn.XLOOKUP(A22,'P&L_Standalone'!A:A,'P&L_Standalone'!B:B) -> Lable
A23: Items that will not be reclassified to profit or (loss) | B23: =_xlfn.XLOOKUP(A23,'P&L_Standalone'!A:A,'P&L_Standalone'!B:B) -> Items that will not be reclassified to Profit or Loss | C23: =_xlfn.XLOOKUP(A23,'P&L_Standalone'!A:A,'P&L_Standalone'!C:C) -> 22293
A24: Income tax relating to items that will not be reclassified to profit or (loss) | B24: =_xlfn.XLOOKUP(A24,'P&L_Standalone'!A:A,'P&L_Standalone'!B:B) -> Income Tax related to items that will not be reclassified to Profit or Loss | C24: =_xlfn.XLOOKUP(A24,'P&L_Standalone'!A:A,'P&L_Standalone'!C:C) -> 22295
A25: Items that will be reclassified to profit or (loss) | B25: =_xlfn.XLOOKUP(A25,'P&L_Standalone'!A:A,'P&L_Standalone'!B:B) -> Items that will be reclassified to Profit or Loss | C25: =_xlfn.XLOOKUP(A25,'P&L_Standalone'!A:A,'P&L_Standalone'!C:C) -> 22294
A26: Income tax relating to items that will be reclassified to profit or (loss) | B26: =_xlfn.XLOOKUP(A26,'P&L_Standalone'!A:A,'P&L_Standalone'!B:B) -> Income Tax related to items that will be reclassified to Profit or Loss | C26: =_xlfn.XLOOKUP(A26,'P&L_Standalone'!A:A,'P&L_Standalone'!C:C) -> 22296
A27: Total | B27: Other Comprehensive Income | C27: 16484
A28: Total Comprehsive income for the period | B28: Total Comprehensive Gain (Loss) For the Year | C28: 20019
A29: Paid up Equity share value Capital (Face Value Rs 2/-) | B29: =_xlfn.XLOOKUP(A29,'P&L_Standalone'!A:A,'P&L_Standalone'!B:B) -> Paid-Up Equity Share Capital | C29: =_xlfn.XLOOKUP(A29,'P&L_Standalone'!A:A,'P&L_Standalone'!C:C) -> 282
A30: Earning per Equity Share of Rs2/- Each :
A31: Basic EPS | B31: =_xlfn.XLOOKUP(A31,'P&L_Standalone'!A:A,'P&L_Standalone'!B:B) -> Basic EPS | C31: =_xlfn.XLOOKUP(A31,'P&L_Standalone'!A:A,'P&L_Standalone'!C:C) -> 222
A32: Diluted EPS | B32: =_xlfn.XLOOKUP(A32,'P&L_Standalone'!A:A,'P&L_Standalone'!B:B) -> Diluted EPS | C32: =_xlfn.XLOOKUP(A32,'P&L_Standalone'!A:A,'P&L_Standalone'!C:C) -> 234
A33: PART II (Select Information for the Quarter Ended 30TH SEPT., 2020 | B33: Lable
A34: PARTICULARS OF SHAREHOLDING | B34: Lable
A35: Public Shareholding | B35: Lable
A36: Number of Shares | B36: Number of shares | C36: 275
A37: Percentage of shareholding | B37: Percentage of shareholding | C37: 287
A38: Promoter and promoter group shareholding | B38: Lable
A39: Pledged/Encumbered | B39: Lable
A40: Non-encumbered | B40: Lable
...

Sheet BS_Standalone
A1: Particulars | B1: Cogencis Field | C1: Field id
A2: ASSETS | B2: Lable
A3: Non - Current Assets | B3: Lable
A4: Property, plant and equipment | B4: Property, Plant & Equipment | C4: 20222
A5: Capital Work In Progress | B5: Capital Work-In-Progress | C5: 13720
A6: Intangible assets | B6: Other Intangible Assets | C6: 20221
A7: Intangible assets under development | B7: Intangible Assets Under Development | C7: 13736
A8: Investments | B8: Non-Current Investments | C8: 13748
A9: Trade Receivable | B9: Trade Receivables | C9: 20218
A10: Loans | B10: Loans Non-Current | C10: 20217
A11: Other Financial Assets | B11: Other Non-Current Financial Assets | C11: 20216
A12: Income tax assets (net) | B12: Income Tax assets (net) | C12: 20215
A13: Other non-current assets | B13: Other Non-Current Assets | C13: 13753
A14: Subtotal - Non-Current Assets | B14: Total Non-Current Assets | C14: 13777
A15: Current Asstes | B15: Lable
A16: Financial assets | B16: Lable
A17: Trade Receivables | B17: Trade Receivables | C17: 13780
A18: Cash and cash equivalents | B18: Cash And Cash Equivalents | C18: 13722
A19: Bank balances other that above | B19: Bank balance other than cash and cash equivalents | C19: 29788
A20: Loans | B20: Loans, Current | C20: 20230
A21: Others | B21: Other Current Financial Assets | C21: 20231
A22: Current Tax Assets (Net) | B22: Current Tax Assets (Net) | C22: 20228
A23: Other Current Assets | B23: Other Current Assets | C23: 13750
A24: Total - Current Assets | B24: Total Current Assets | C24: 13774
A25: Total Assets | B25: Total Assets | C25: 13771
A26: EQUITY AND LIABILITIES | B26: Lable
A27: Equity | B27: Lable
A28: Equity Share Capital | B28: Share Capital | C28: 13765
A29: Other Equity | B29: Reserves And Surplus/Other Equity | C29: 13762
A30: Total Equity | B30: Total Share Holder's Funds | C30: 13773
A31: LIABILITIES | B31: Lable
A32: Non - Current Liabilities | B32: Lable
A33: Financial Liability | B33: Lable
A34: Borrowings | B34: Borrowings | C34: 20223
A35: Other Financial Liability | B35: Other Non Current Financial Liabilities | C35: 20226
A36: Provisions | B36: Long-Term Provisions | C36: 13743
A37: Deferred Tax Liabilities (Net) | B37: Deferred Tax Liability (Net) | C37: 13727
A38: Other Non-current liablitiesFinancial Liability | B38: Other Non-Current Liabilities | C38: 26449
A39: Total - Non - Current Liabilities | B39: Total Non-Current Liabilities | C39: 13778
A40: Current Liabilities | B40: Lable
...

Sheet BS_Consolidated
A1: Particulars | B1: Cogencis Field | C1: Field id
A2: ASSETS | B2: Lable
A3: Non - Current Assets | B3: Lable
A4: Property, plant and equipment | B4: Property, Plant & Equipment | C4: 20222
A5: Capital Work In Progress | B5: Capital Work-In-Progress | C5: 13720
A6: Intangible assets | B6: Other Intangible Assets | C6: 20221
A7: Intangible assets under development | B7: Intangible Assets Under Development | C7: 13736
A8: Financial assets | B8: Lable
A9: Investments | B9: Non-Current Investments | C9: 13748
A10: Trade Receivable | B10: Trade Receivables | C10: 20218
A11: Loans | B11: Loans Non-Current | C11: 20217
A12: Other Financial Assets | B12: Other Non-Current Financial Assets | C12: 20216
A13: Income tax assets (net) | B13: Income Tax assets (net) | C13: 20215
A14: Other non-current assets | B14: Other Non-Current Assets | C14: 13753
A15: Subtotal - Non-Current Assets | B15: Total Non-Current Assets | C15: 13777
A16: Current Asstes | B16: Lable
A17: Financial assets | B17: Lable
A18: Trade Receivables | B18: Trade Receivables | C18: 13780
A19: Cash and cash equivalents | B19: Cash And Cash Equivalents | C19: 13722
A20: Bank balances other that above | B20: Bank balance other than cash and cash equivalents | C20: 29788
A21: Loans | B21: Loans, Current | C21: 20230
A22: Others | B22: Other Current Financial Assets | C22: 20231
A23: Current Tax Assets (Net) | B23: Current Tax Assets (Net) | C23: 20228
A24: Other Current Assets | B24: Other Current Assets | C24: 13750
A25: Total - Current Assets | B25: Total Current Assets | C25: 13774
A26: Total Assets | B26: Total Assets | C26: 13771
A27: EQUITY AND LIABILITIES | B27: Lable
A28: Equity | B28: Lable
A29: Equity Share Capital | B29: Share Capital | C29: 13765
A30: Other Equity | B30: Reserves And Surplus/Other Equity | C30: 13762
A31: Total Equity | B31: Total Share Holder's Funds | C31: 13773
A32: LIABILITIES | B32: Lable
A33: Non - Current Liabilities | B33: Lable
A34: Financial Liability | B34: Lable
A35: Borrowings | B35: Borrowings | C35: 20223
A36: Other Financial Liability | B36: Other Non Current Financial Liabilities | C36: 20226
A37: Provisions | B37: Long-Term Provisions | C37: 13743
A38: Deferred Tax Liabilities (Net) | B38: Deferred Tax Liability (Net) | C38: 13727
A39: Other Non-current liablitiesFinancial Liability | B39: Other Non-Current Liabilities | C39: 26449
A40: Total - Non - Current Liabilities | B40: Total Non-Current Liabilities | C40: 13778
...

Sheet CFS_Standalone
A1: Particulars | B1: Cogencis Field | C1: Field id
A2: CASH FLOW FROM OPERATING ACTIVITIES | B2: Lable
A3: Profit before tax | B3: Net Profit Before Tax And Exceptional Item | C3: 17539
A4: Adjustments for: | B4: Lable
A5: Add: | B5: Lable
A6: Depreciation & ammortisation expenses | B6: Depreciation and Amortisation Expense | C6: 30399
A7: Finance costs | B7: Interest Expense | C7: 30479
A8: Loss on disposal of property,plant& equipment | B8: Loss On Sale Of Fixed Assets | C8: 30502
A9: Loss on sale of Investments | B9: Loss On Sale Of Investments | C9: 30503
A10: Loss on Written of Assets | B10: Miscellaneous Expenditure Written Off | C10: 30505
A11: Provirion for dimunetion in the value of investments | B11: Provision For Dimunition In Investments | C11: 30630
A12: Less: | B12: Lable
A13: Dividend received | B13: Dividend Received | C13: 30404
A14: Interest income from financial assets measured at ammortised costs | B14: Interest Income | C14: 30481
A15: Gain on disposal of equity instruments measured at cost | B15: Profit On Sale Of Investments | C15: 30577
A16: Gain on disposal of property plant & equipment | B16: Profit On Sale Of Fixed Assets | C16: 30576
A17: Provision for dimunetion in the value of investments | B17: Provision For Dimunition In Investments | C17: 30630
A18: Operating profit before change in operating assets & liabilities | B18: Operating Profit Before Working Capital Changes | C18: 30511
A19: Adjustments for: | B19: Lable
A20: (Increase)/decrease in inventories | B20: Inventories | C20: 30487
A21: (Increase)/decrease in non current trade receivable | B21: Trade And Other Receivables | C21: 30674
A22: (Increase)/decrease in other financial assets | B22: Adjustments for other financial assets, non-current | C22: 30452
A23: (Increase)/decrease in other assets | B23: Other Current and Non Current Assets | C23: 30518
A24: (Increase)/decrease in NonCurrent loans & advances | B24: Loans And Advances | C24: 30497
A25: (Increase)/decrease in NonCurrent Assets | B25: Other Current and Non Current Assets | C25: 30518
A26: Increase/(decrease) in current trade receivable | B26: Trade And Other Receivables | C26: 30674
A27: Increase/(decrease) in other current financial assests | B27: Adjustments for other financial assets, current | C27: 30451
A28: Increase/(decrease) in current tax assets | B28: Other Current and Non Current Assets | C28: 30518
A29: Increase/(decrease) in other assets | B29: Other Current and Non Current Assets | C29: 30518
A30: Increase/(decrease) in other noncurrent Liabilities | B30: Other Current and Non Current Liabilities | C30: 30519
A31: Increase/(decrease) in non-current loans | B31: Others-From Operations | C31: 17546
... A37: Cash generated from operations | B37: Cash Generated From Operations | C37: 30372
A38: Less: | B38: Lable
A39: Income tax paid(net of refund) | B39: Income Tax Paid | C39: 30422
A40: Net cash flow from operating activities | B40: Net Cash Flow From Operating Activities | C40: 17538
A41: CASH FLOW FROM INVESTING ACTIVITIES | B41: Lable
A42: Payment to acquire property,plant & equipments | B42: Purchase Of Fixed Assets (Tangible / Intangible) | C42: 17556
A43: Proceeds from disposal of equity instruments measured at FVOCI | B43: Sale Of Investments | C43: 17563
A44: Sale of Investments | B44: Sale Of Investments | C44: 17563
A45: Purchase of Investments | B45: Purchase Of Investments | C45: 17557
...

Sheet CFS_Consolidated
A1: Particulars | B1: Cogencis Field | C1: Field id
A2: CASH FLOW FROM OPERATING ACTIVITIES | B2: =_xlfn.XLOOKUP(A2,CFS_Standalone!A:A,CFS_Standalone!B:B) -> Lable
A3: Profit before tax | B3: =_xlfn.XLOOKUP(A3,CFS_Standalone!A:A,CFS_Standalone!B:B) -> Net Profit Before Tax And Exceptional Item | C3: =_xlfn.XLOOKUP(A3,CFS_Standalone!A:A,CFS_Standalone!C:C) -> 17539
A4: Adjustments for: | B4: =_xlfn.XLOOKUP(A4,CFS_Standalone!A:A,CFS_Standalone!B:B) -> Lable
A5: Add: | B5: =_xlfn.XLOOKUP(A5,CFS_Standalone!A:A,CFS_Standalone!B:B) -> Lable
A6: Depreciation & ammortisation expenses | B6: =_xlfn.XLOOKUP(A6,CFS_Standalone!A:A,CFS_Standalone!B:B) -> Depreciation and Amortisation Expense | C6: =_xlfn.XLOOKUP(A6,CFS_Standalone!A:A,CFS_Standalone!C:C) -> 30399
A7: Finance costs | B7: =_xlfn.XLOOKUP(A7,CFS_Standalone!A:A,CFS_Standalone!B:B) -> Interest Expense | C7: =_xlfn.XLOOKUP(A7,CFS_Standalone!A:A,CFS_Standalone!C:C) -> 30479
A8: Loss on disposal of property,plant& equipment | B8: =_xlfn.XLOOKUP(A8,CFS_Standalone!A:A,CFS_Standalone!B:B) -> Loss On Sale Of Fixed Assets | C8: =_xlfn.XLOOKUP(A8,CFS_Standalone!A:A,CFS_Standalone!C:C) -> 30502
A9: Loss on sale of Investments | B9: =_xlfn.XLOOKUP(A9,CFS_Standalone!A:A,CFS_Standalone!B:B) -> Loss On Sale Of Investments | C9: =_xlfn.XLOOKUP(A9,CFS_Standalone!A:A,CFS_Standalone!C:C) -> 30503
A10: Loss on Written of Assets | B10: =_xlfn.XLOOKUP(A10,CFS_Standalone!A:A,CFS_Standalone!B:B) -> Miscellaneous Expenditure Written Off | C10: =_xlfn.XLOOKUP(A10,CFS_Standalone!A:A,CFS_Standalone!C:C) -> 30505
A11: Provirion for dimunetion in the value of investments | B11: =_xlfn.XLOOKUP(A11,CFS_Standalone!A:A,CFS_Standalone!B:B) -> Provision For Dimunition In Investments | C11: =_xlfn.XLOOKUP(A11,CFS_Standalone!A:A,CFS_Standalone!C:C) -> 30630
A12: Less: | B12: =_xlfn.XLOOKUP(A12,CFS_Standalone!A:A,CFS_Standalone!B:B) -> Lable
A13: Dividend received | B13: =_xlfn.XLOOKUP(A13,CFS_Standalone!A:A,CFS_Standalone!B:B) -> Dividend Received | C13: =_xlfn.XLOOKUP(A13,CFS_Standalone!A:A,CFS_Standalone!C:C) -> 30404
A14: Interest income from financial assets measured at ammortised costs | B14: =_xlfn.XLOOKUP(A14,CFS_Standalone!A:A,CFS_Standalone!B:B) -> Interest Income | C14: =_xlfn.XLOOKUP(A14,CFS_Standalone!A:A,CFS_Standalone!C:C) -> 30481
A15: Gain on disposal of equity instruments measured at cost | B15: =_xlfn.XLOOKUP(A15,CFS_Standalone!A:A,CFS_Standalone!B:B) -> Profit On Sale Of Investments | C15: =_xlfn.XLOOKUP(A15,CFS_Standalone!A:A,CFS_Standalone!C:C) -> 30577
A16: Gain on disposal of property plant & equipment | B16: =_xlfn.XLOOKUP(A16,CFS_Standalone!A:A,CFS_Standalone!B:B) -> Profit On Sale Of Fixed Assets | C16: =_xlfn.XLOOKUP(A16,CFS_Standalone!A:A,CFS_Standalone!C:C) -> 30576
A17: Provision for dimunetion in the value of investments profit/(loss) from Associates | B17: Provision For Dimunition In Investments | C17: 30630
A18: Operating profit before change in operating assets & liabilities | B18: =_xlfn.XLOOKUP(A18,CFS_Standalone!A:A,CFS_Standalone!B:B) -> Operating Profit Before Working Capital Changes | C18: =_xlfn.XLOOKUP(A18,CFS_Standalone!A:A,CFS_Standalone!C:C) -> 30511
A19: Adjustments for: | B19: =_xlfn.XLOOKUP(A19,CFS_Standalone!A:A,CFS_Standalone!B:B) -> Lable
A20: (Increase)/decrease in inventories | B20: =_xlfn.XLOOKUP(A20,CFS_Standalone!A:A,CFS_Standalone!B:B) -> Inventories | C20: =_xlfn.XLOOKUP(A20,CFS_Standalone!A:A,CFS_Standalone!C:C) -> 30487
A21: (Increase)/decrease in non current trade receivable | B21: =_xlfn.XLOOKUP(A21,CFS_Standalone!A:A,CFS_Standalone!B:B) -> Trade And Other Receivables | C21: =_xlfn.XLOOKUP(A21,CFS_Standalone!A:A,CFS_Standalone!C:C) -> 30674
A22: (Increase)/decrease in other financial assets | B22: =_xlfn.XLOOKUP(A22,CFS_Standalone!A:A,CFS_Standalone!B:B) -> Adjustments for other financial assets, non-current | C22: =_xlfn.XLOOKUP(A22,CFS_Standalone!A:A,CFS_Standalone!C:C) -> 30452
A23: (Increase)/decrease in other assets | B23: =_xlfn.XLOOKUP(A23,CFS_Standalone!A:A,CFS_Standalone!B:B) -> Other Current and Non Current Assets | C23: =_xlfn.XLOOKUP(A23,CFS_Standalone!A:A,CFS_Standalone!C:C) -> 30518
A24: (Increase)/decrease in Non-Current loans & advances | B24: Loans And Advances | C24: 30497
A25: (Increase)/decrease in Non-Current Assets | B25: Other Current and Non Current Assets | C25: 30518
A26: Increase/(decrease) in current trade receivable | B26: =_xlfn.XLOOKUP(A26,CFS_Standalone!A:A,CFS_Standalone!B:B) -> Trade And Other Receivables | C26: =_xlfn.XLOOKUP(A26,CFS_Standalone!A:A,CFS_Standalone!C:C) -> 30674
A27: Increase/(decrease) in other current financial assests | B27: =_xlfn.XLOOKUP(A27,CFS_Standalone!A:A,CFS_Standalone!B:B) -> Adjustments for other financial assets, current | C27: =_xlfn.XLOOKUP(A27,CFS_Standalone!A:A,CFS_Standalone!C:C) -> 30451
A28: Increase/(decrease) in current tax assets | B28: =_xlfn.XLOOKUP(A28,CFS_Standalone!A:A,CFS_Standalone!B:B) -> Other Current and Non Current Assets | C28: =_xlfn.XLOOKUP(A28,CFS_Standalone!A:A,CFS_Standalone!C:C) -> 30518
A29: Increase/(decrease) in other assets | B29: =_xlfn.XLOOKUP(A29,CFS_Standalone!A:A,CFS_Standalone!B:B) -> Other Current and Non Current Assets | C29: =_xlfn.XLOOKUP(A29,CFS_Standalone!A:A,CFS_Standalone!C:C) -> 30518
A30: Increase/(decrease) in other non-current Liabilities | B30: Other Current and Non Current Liabilities | C30: 30519
A31: Increase/(decrease) in non-current loans | B31: =_xlfn.XLOOKUP(A31,CFS_Standalone!A:A,CFS_Standalone!B:B) -> Others-From Operations | C31: =_xlfn.XLOOKUP(A31,CFS_Standalone!A:A,CFS_Standalone!C:C) -> 17546
A32: Increase/(decrease) in Current Liabities | B32: =_xlfn.XLOOKUP(A32,CFS_Standalone!A:A,CFS_Standalone!B:B) -> Other Current and Non Current Liabilities | C32: =_xlfn.XLOOKUP(A32,CFS_Standalone!A:A,CFS_Standalone!C:C) -> 30519
A33: Increase/(decrease) in trade payables | B33: =_xlfn.XLOOKUP(A33,CFS_Standalone!A:A,CFS_Standalone!B:B) -> Trade Payables And Others | C33: =_xlfn.XLOOKUP(A33,CFS_Standalone!A:A,CFS_Standalone!C:C) -> 30675
A34: Increase/(decrease) in other current Financial Assets | B34: =_xlfn.XLOOKUP(A34,CFS_Standalone!A:A,CFS_Standalone!B:B) -> Adjustments for other financial assets, current | C34: =_xlfn.XLOOKUP(A34,CFS_Standalone!A:A,CFS_Standalone!C:C) -> 30451
A35: Increase/(decrease) in other current assests | B35: =_xlfn.XLOOKUP(A35,CFS_Standalone!A:A,CFS_Standalone!B:B) -> Other Current and Non Current Assets | C35: =_xlfn.XLOOKUP(A35,CFS_Standalone!A:A,CFS_Standalone!C:C) -> 30518
A36: Increase/(decrease) in other current liabilities | B36: =_xlfn.XLOOKUP(A36,CFS_Standalone!A:A,CFS_Standalone!B:B) -> Other Current and Non Current Liabilities | C36: =_xlfn.XLOOKUP(A36,CFS_Standalone!A:A,CFS_Standalone!C:C) -> 30519
A37: Cash generated from operations | B37: =_xlfn.XLOOKUP(A37,CFS_Standalone!A:A,CFS_Standalone!B:B) -> Cash Generated From Operations | C37: =_xlfn.XLOOKUP(A37,CFS_Standalone!A:A,CFS_Standalone!C:C) -> 30372
A38: Less: | B38: =_xlfn.XLOOKUP(A38,CFS_Standalone!A:A,CFS_Standalone!B:B) -> Lable
A39: Income tax paid(net of refund) | B39: =_xlfn.XLOOKUP(A39,CFS_Standalone!A:A,CFS_Standalone!B:B) -> Income Tax Paid | C39: =_xlfn.XLOOKUP(A39,CFS_Standalone!A:A,CFS_Standalone!C:C) -> 30422
A40: Net cash flow from operating activities | B40: =_xlfn.XLOOKUP(A40,CFS_Standalone!A:A,CFS_Standalone!B:B) -> Net Cash Flow From Operating Activities
...

Sheet SR_Standalone
A1: Particulars | B1: Cogencis Field | C1: Field id

Sheet SR_Consolidated
A1: Particulars | B1: Cogencis Field | C1: Field id
