Workbook

Sheet P&L_Standalone
A1: Particulars | B1: Cogencis Field | C1: Field id
A2: Income | D2: Heading
A3: Revenue from operations | B3: Gross Sales/Income from Operations | C3: 256
A4: Other income | B4: Miscellaneous Income | C4: 265
A5: Total income | B5: Total Income | C5: 25238
A6: Expenses | D6: Heading
A7: Cost of material consumed | B7: Cost of Materials Consumed | C7: 230
A8: Purchase of security software products | B8: Purchase of Stock-in-Trade | C8: 307
A9: Changes in inventory of security software products | B9: Changes in Inventories of Finished Goods, Work-In-Progress and Stock-In-Trade | C9: 227
A10: Employee benefits expense | B10: Employee Benefit Expense | C10: 238
A11: Finance costs | B11: Finance Costs | C11: 246
A12: Depreciation and amortisation expense | B12: Depreciation, Depletion and Amortisation Expense | C12: 232
A13: Other expenses | B13: Other Expenses | C13: 279
A14: Total expenses | B14: Total Expenses | C14: 320
A15: Profit/ (loss) before tax | B15: Profit/(Loss) From Ordinary Activities before Tax | C15: 296
A16: Tax expense | D16: Heading
A17: Current tax | B17: Tax Expense | C17: 318
A18: Adjustments of tax relating to earlier periods (Net) | B18: Tax Expense | C18: 318
A19: Deferred tax charge/ (benefit) | B19: Deferred Tax | C19: 231
A20: Total tax expense/ (benefit) | D20: Calculated Field
A21: Profit/ (loss) after tax | B21: Net Profit/(Loss) for the Period | C21: 269
A22: Other comprehensive income/ (loss) (net of tax) | D22: Heading
A23: Items that will not be reclassified subsequently to profit or loss : | D23: Sub-heading
A24: Gain/ (loss) on re-measurement of defined benefit plans | B24: Items that will not be reclassified to Profit or Loss | C24: 22293
A25: Net (loss) or gain on FVOCI instruments | B25: Items that will not be reclassified to Profit or Loss | C25: 22293
A26: Total other comprehensive income/ (loss) for the period | B26: Other Comprehensive Income | C26: 16484
A27: Total comprehensive income/ (loss) (after tax) | B27: Total Comprehensive Gain (Loss) For the Year | C27: 20019
A28: Paid-up equity share capital (face value of₹ 10 each fully paid up) | B28: Paid-Up Equity Share Capital | C28: 282
A29: Other equity excluding revaluation reserves as per balance sheet | B29: Reserve excluding Revaluation Reserves (as per Balance Sheet of Previous Accounting Year) | C29: 309
A30: Earnings/ (loss) per share of ₹ 10 each: (not annualised except for the year ended March) | D30: Heading
A31: Basic | B31: Basic EPS | C31: 222
A32: Diluted | B32: Diluted EPS | C32: 234

Sheet P&L_Consolidated
A1: Particulars | B1: Cogencis Field | C1: Field id
A2: Income | D2: Heading
A3: Revenue from operations | B3: =VLOOKUP($A3,'P&L_Standalone'!A:C,2,0) -> Gross Sales/Income from Operations | C3: =VLOOKUP($A3,'P&L_Standalone'!A:C,3,0) -> 256
A4: Other income | B4: =VLOOKUP($A4,'P&L_Standalone'!A:C,2,0) -> Miscellaneous Income | C4: =VLOOKUP($A4,'P&L_Standalone'!A:C,3,0) -> 265
A5: Total income | B5: =VLOOKUP($A5,'P&L_Standalone'!A:C,2,0) -> Total Income | C5: =VLOOKUP($A5,'P&L_Standalone'!A:C,3,0) -> 25238
A6: Expenses | D6: Heading
A7: Cost of material consumed | B7: =VLOOKUP($A7,'P&L_Standalone'!A:C,2,0) -> Cost of Materials Consumed | C7: =VLOOKUP($A7,'P&L_Standalone'!A:C,3,0) -> 230
A8: Purchase of security software products | B8: =VLOOKUP($A8,'P&L_Standalone'!A:C,2,0) -> Purchase of Stock-in-Trade | C8: =VLOOKUP($A8,'P&L_Standalone'!A:C,3,0) -> 307
A9: Changes in inventory of security software products | B9: =VLOOKUP($A9,'P&L_Standalone'!A:C,2,0) -> Changes in Inventories of Finished Goods, Work-In-Progress and Stock-In-Trade | C9: =VLOOKUP($A9,'P&L_Standalone'!A:C,3,0) -> 227
A10: Employee benefits expense | B10: =VLOOKUP($A10,'P&L_Standalone'!A:C,2,0) -> Employee Benefit Expense | C10: =VLOOKUP($A10,'P&L_Standalone'!A:C,3,0) -> 238
A11: Finance costs | B11: =VLOOKUP($A11,'P&L_Standalone'!A:C,2,0) -> Finance Costs | C11: =VLOOKUP($A11,'P&L_Standalone'!A:C,3,0) -> 246
A12: Depreciation and amortisation expense | B12: =VLOOKUP($A12,'P&L_Standalone'!A:C,2,0) -> Depreciation, Depletion and Amortisation Expense | C12: =VLOOKUP($A12,'P&L_Standalone'!A:C,3,0) -> 232
A13: Other expenses | B13: =VLOOKUP($A13,'P&L_Standalone'!A:C,2,0) -> Other Expenses | C13: =VLOOKUP($A13,'P&L_Standalone'!A:C,3,0) -> 279
A14: Total expenses | B14: =VLOOKUP($A14,'P&L_Standalone'!A:C,2,0) -> Total Expenses | C14: =VLOOKUP($A14,'P&L_Standalone'!A:C,3,0) -> 320
A15: Profit/ (loss) before tax | B15: =VLOOKUP($A15,'P&L_Standalone'!A:C,2,0) -> Profit/(Loss) From Ordinary Activities before Tax | C15: =VLOOKUP($A15,'P&L_Standalone'!A:C,3,0) -> 296
A16: Tax expense | D16: Heading
A17: Current tax | B17: =VLOOKUP($A17,'P&L_Standalone'!A:C,2,0) -> Tax Expense | C17: =VLOOKUP($A17,'P&L_Standalone'!A:C,3,0) -> 318
A18: Adjustments of tax relating to earlier periods (Net) | B18: =VLOOKUP($A18,'P&L_Standalone'!A:C,2,0) -> Tax Expense | C18: =VLOOKUP($A18,'P&L_Standalone'!A:C,3,0) -> 318
A19: Deferred tax charge/ (benefit) | B19: =VLOOKUP($A19,'P&L_Standalone'!A:C,2,0) -> Deferred Tax | C19: =VLOOKUP($A19,'P&L_Standalone'!A:C,3,0) -> 231
A20: Total tax expense/ (benefit) | D20: Calculated Field
A21: Profit/ (loss) after tax | B21: Net Profit/(Loss) for the Period | C21: 269
A22: Other comprehensive income/ (loss) (net of tax) | D22: Heading
A23: Items that will not be reclassified subsequently to profit or loss : | D23: Sub-heading
A24: Gain/ (loss) on re-measurement of defined benefit plans | B24: =VLOOKUP($A24,'P&L_Standalone'!A:C,2,0) -> Items that will not be reclassified to Profit or Loss | C24: =VLOOKUP($A24,'P&L_Standalone'!A:C,3,0) -> 22293
A25: Net (loss) or gain on FVOCI instruments | B25: =VLOOKUP($A25,'P&L_Standalone'!A:C,2,0) -> Items that will not be reclassified to Profit or Loss | C25: =VLOOKUP($A25,'P&L_Standalone'!A:C,3,0) -> 22293
A26: Items that will be reclassified subsequently to profit or loss : | D26: Sub-heading
A27: Exchange differences on translation of foreign operations | B27: Items that will be reclassified to Profit or Loss | C27: 22294
A28: Total other comprehensive income/ (loss) for the period | B28: =VLOOKUP($A28,'P&L_Standalone'!A:C,2,0) -> Other Comprehensive Income | C28: =VLOOKUP($A28,'P&L_Standalone'!A:C,3,0) -> 16484
A29: Total comprehensive income/ (loss) (after tax) | B29: =VLOOKUP($A29,'P&L_Standalone'!A:C,2,0) -> Total Comprehensive Gain (Loss) For the Year | C29: =VLOOKUP($A29,'P&L_Standalone'!A:C,3,0) -> 20019
A30: Paid-up equity share capital (face value of ₹ 10 each, fully paid up) | B30: Paid-Up Equity Share Capital | C30: 282
A31: Other equity excluding revaluation reserves as per balance sheet | B31: =VLOOKUP($A31,'P&L_Standalone'!A:C,2,0) -> Reserve excluding Revaluation Reserves (as per Balance Sheet of Previous Accounting Year) | C31: =VLOOKUP($A31,'P&L_Standalone'!A:C,3,0) -> 309
A32: Earnings/ (loss) per share of ₹ 10 each: (not annualised except for the year ended March)
A33: Basic | B33: =VLOOKUP($A33,'P&L_Standalone'!A:C,2,0) -> Basic EPS | C33: =VLOOKUP($A33,'P&L_Standalone'!A:C,3,0) -> 222
A34: Diluted | B34: =VLOOKUP($A34,'P&L_Standalone'!A:C,2,0) -> Diluted EPS | C34: =VLOOKUP($A34,'P&L_Standalone'!A:C,3,0) -> 234

Sheet BS_Standalone
A1: Particulars | B1: Cogencis Field | C1: Field id
A2: Assets | D2: Heading
A3: Non-current assets | D3: Heading
A4: Property, plant and equipment | B4: Property, Plant & Equipment | C4: 20222
A5: Capital work-in-progress | B5: Capital Work-In-Progress | C5: 13720
A6: Investment property | B6: Investment Property | C6: 25736
A7: Intangible assets | B7: Other Intangible Assets | C7: 20221
A8: Right-of-use assets | B8: Right-of-use asset | C8: 30342
A9: Investments in subsidiaries | B9: Non-Current Investments | C9: 13748
A10: Financial assets
A11: Investments | B11: Non-Current Investments | C11: 13748
A12: Other financial assets | B12: Other Non-Current Financial Assets | C12: 20216
A13: Deferred tax assets (net) | B13: Deferred Tax Assets (Net) | C13: 13726
A14: Income tax assets (net) | B14: Income tax assets (net) | C14: 20215
A15: Other non-current assets | B15: Other Non-Current Assets | C15: 13753
A16: Current assets | D16: Heading
A17: Inventories | B17: Inventories | C17: 13737
A18: Financial assets | D18: Heading
A19: Investments | B19: Current Investments | C19: 13724
A20: Trade receivables | B20: Trade Receivables | C20: 13780
A21: Cash and cash equivalents | B21: Cash And Cash Equivalents | C21: 13722
A22: Bank balances other than above | B22: Bank balance other than cash and cash equivalents | C22: 29788
A23: Other financial assets | B23: Other Current Financial Assets | C23: 20231
A24: Other current assets | B24: Other Current Assets | C24: 13750
A25: Assets classified as held for sale | B25: Assets classified as held for sale | C25: 20208
A26: Total assets | B26: Total Assets | C26: 13771
A27: Equity and liabilities | D27: Heading
A28: Equity | D28: Heading
A29: Equity share capital | B29: Share Capital | C29: 13765
A30: Share application money pending allotment | B30: Share application money pending allotment | C30: 13768
A31: Other equity | B31: Reserves And Surplus/Other Equity | C31: 13762
A32: Total equity | B32: Total Share Holder's Funds | C32: 13773
A33: Liabilities | D33: Heading
A34: Non-current liabilities | D34: Heading
A35: Financial liabilities | D35: Heading
A36: Lease Liabilities | B36: Lease liabilities | C36: 30340
A37: Employee benefit obligations | B37: Long-Term Provisions | C37: 13743
A38: Other non-current liabilities | B38: Other Non-Current Liabilities | C38: 26449
A39: Current liabilities | D39: Heading
A40: Financial liabilities | D40: Heading
...

Sheet BS_Consolidated
A1: Particulars | B1: Cogencis Field | C1: Field id
A2: Assets | D2: Heading
A3: Non-current assets | D3: Heading
A4: Property, plant and equipment | B4: Property, Plant & Equipment | C4: 20222
A5: Capital work-in-progress | B5: Capital Work-In-Progress | C5: 13720
A6: Investment Property | B6: Investment Property | C6: 25736
A7: Intangible assets | B7: Other Intangible Assets | C7: 20221
A8: Right-of-use assets | B8: Right-of-use asset | C8: 30342
A9: Financial assets | D9: Heading
A10: Investments | B10: Non-Current Investments | C10: 13748
A11: Other financial assets | B11: Other Non-Current Financial Assets | C11: 20216
A12: Deferred tax assets (net) | B12: Deferred Tax Assets (Net) | C12: 13726
A13: Income tax assets (net) | B13: Income tax assets (net) | C13: 20215
A14: Other non-current assets | B14: Other Non-Current Assets | C14: 13753
A15: Current assets | D15: Heading
A16: Inventories | B16: Inventories | C16: 13737
A17: Financial assets | D17: Heading
A18: Investments | B18: Current Investments | C18: 13724
A19: Trade receivables | B19: Trade Receivables | C19: 13780
A20: Cash and cash equivalents | B20: Cash And Cash Equivalents | C20: 13722
A21: Bank balances other than above | B21: Bank balance other than cash and cash equivalents | C21: 29788
A22: Other financial assets | B22: Other Current Financial Assets | C22: 20231
A23: Other current assets | B23: Other Current Assets | C23: 13750
A24: Assets classified as held for sale | B24: Assets classified as held for sale | C24: 20208
A25: Total assets | B25: Total Assets | C25: 13771
A26: Equity and liabilities | D26: Heading
A27: Equity | D27: Heading
A28: Equity share capital | B28: Share Capital | C28: 13765
A29: Share application money pending allotment | B29: Share application money pending allotment | C29: 13768
A30: Other equity | B30: Reserves And Surplus/Other Equity | C30: 13762
A31: Total equity | B31: Total Share Holder's Funds | C31: 13773
A32: Liabilities | D32: Heading
A33: Non-current liabilities | D33: Heading
A34: Financial liabilities | D34: Heading
A35: Lease Liabilities | B35: Lease liabilities | C35: 30340 | D35: Heading
A36: Employee benefit obligations | B36: Long-Term Provisions | C36: 13743
A37: Other non-current liabilities | B37: Other Non-Current Liabilities | C37: 26449
A38: Current liabilities | D38: Heading
A39: Financial liabilities | D39: Heading
A40: Trade payables
...

Sheet CFS_Standalone
A1: Particulars | B1: Cogencis Field | C1: Field id
A2: Cash flow from operating activities | D2: Heading
A3: Profit before tax | B3: Net Profit Before Tax And Exceptional Item | C3: 17539
A4: Adjustment to reconcile profit before tax to net cash flows: | D4: Sub-Head
A5: Net (gain)/ loss on foreign exchange differences | B5: Foreign Exchange Gain / Loss | C5: 30414
A6: Employee share based payments expense | B6: Employees Stock Options Grants | C6: 30407
A7: Interest on lease | B7: Interest Expense | C7: 30479
A8: Rent equalisation | B8: Fin Lease & Rental Charges | C8: 30411
A9: Depreciation and amortization expense | B9: Depreciation and Amortisation Expense | C9: 30399
A10: Interest income | B10: Interest Income | C10: 30481
A11: Provision for doubtful debts and advances | B11: Provision For Doubtful Debts | C11: 30631
A12: (Profit)/ loss on sale of property, plant and equipment | B12: Profit On Sale Of Fixed Assets | C12: 30576
A13: Income from Investment Property | B13: Profit On Sale Of Investments | C13: 30577
A14: Net gain on sale of investment | B14: Profit On Sale Of Investments | C14: 30577
A15: Unrealised gain on investments | B15: Profit On Sale Of Investments | C15: 30577
A16: Operating profit before working capital changes | B16: Operating Profit Before Working Capital Changes | C16: 30511
A17: Movements in working capital: | D17: Sub-Head
A18: (Increase)/ decrease in trade receivables | B18: Trade And Other Receivables | C18: 30674
A19: (Increase)/ decrease in inventories | B19: Inventories | C19: 30487
A20: (Increase)/ decrease in other financial assets | B20: Adjustments for other financial assets, non-current | C20: 30452
A21: (Increase)/ decrease in other assets | B21: Other Current and Non Current Assets | C21: 0
A22: Increase/ (decrease) in net employee benefit obligations | B22: Provisions | C22: 30627
A23: Increase/(decrease) in trade payables | B23: Trade Payables And Others | C23: 30675
A24: Increase/ (decrease) in other financials liabilities | B24: Adjustments for other financial liabilities, non-current | C24: 30454
A25: Increase/ (decrease) in other current and non-current liabilities | B25: Other Current and Non Current Liabilities | C25: 30519
A26: Cash (used in)/ generated from operations | B26: Cash Generated From Operations | C26: 30372
A27: Income taxes paid (net of refund) | B27: Income Tax Paid | C27: 30422
A28: Net cash flow (used in)/ generated from operating activities | B28: Net Cash Flow From Operating Activities | C28: 17538
A29: Cash flow from investing activities | D29: Heading
A30: Purchase of property, plant and equipment and intangible assets (including capital work-in-progress and capital advances) | B30: Purchase Of Fixed Assets (Tangible / Intangible) | C30: 17556
A31: Proceeds from sale of property, plant and equipment | B31: Sale Of Fixed Assets (Tangible / Intangible) | C31: 30662
A32: Purchase of investment in mutual funds | B32: Investments in Mutual Funds | C32: 30489
A33: Proceeds from sale of investment in mutual funds | B33: Investments in Mutual Funds | C33: 30489
A34: Rental income from investment property | B34: Others-Before Working Capital Changes | C34: 17542
A35: Decrease in Deposits with remaining maturity of more than twelve months | B35: Fixed Deposits | C35: 30412
A36: Income interest received | B36: Interest Received | C36: 30485
A37: Net cash flow (used in)/ generated from investing activities | B37: Net Cash Flow From Investing Activities | C37: 17537
A38: Cash flow from financing activities | D38: Heading
A39: Dividend paid | B39: Dividend Paid | C39: 17528
A40: Principal and interest paid on lease liabilities | B40: Payments of lease liabilities | C40: 30467
...

Sheet CFS_Consolidated
A1: Particulars | B1: Cogencis Field | C1: Field id
A2: Cash flow from operating activities | D2: Heading
A3: Profit before tax | B3: Net Profit Before Tax And Exceptional Item | C3: 17539
A4: Adjustment to reconcile profit before tax to net cash flows: | D4: Sub-Head
A5: Net (gain)/ loss on foreign exchange differences | B5: Foreign Exchange Gain / Loss | C5: 30414
A6: Exchange difference on translation of foreign operations | B6: Foreign Exchange Gain / Loss | C6: 30414
A7: Employee share based payments expense | B7: Employees Stock Options Grants | C7: 30407
A8: Interest on lease | B8: Interest Expense | C8: 30479
A9: Rent equalisation | B9: Fin Lease & Rental Charges | C9: 30411
A10: Depreciation and amortization expense | B10: Depreciation and Amortisation Expense | C10: 30399
A11: Interest income | B11: Interest Income | C11: 30481
A12: Provision for doubtful debts and advances | B12: Provision For Doubtful Debts | C12: 30631
A13: (Profit)/ loss on sale of property, plant and equipment | B13: Profit On Sale Of Fixed Assets | C13: 30576
A14: Income from Investment Property | B14: Profit On Sale Of Investments | C14: 30577
A15: Net gain on sale of investment | B15: Profit On Sale Of Investments | C15: 30577
A16: Unrealised gain on investments | B16: Profit On Sale Of Investments | C16: 30577
A17: Operating profit before working capital changes | B17: Operating Profit Before Working Capital Changes | C17: 30511
A18: Movements in working capital: | D18: Sub-Head
A19: (Increase)/ decrease in trade receivables | B19: Trade And Other Receivables | C19: 30674
A20: (Increase)/ decrease in inventories | B20: Inventories | C20: 30487
A21: (Increase)/ decrease in other financial assets | B21: Adjustments for other financial assets, non-current | C21: 30452
A22: (Increase)/ decrease in other assets | B22: Other Current and Non Current Assets | C22: 0
A23: Increase/ (decrease) in net employee benefit obligations | B23: Provisions | C23: 30627
A24: Increase/ (decrease) in trade payables | B24: Trade Payables And Others | C24: 30675
A25: Increase/(decrease) in other financials liabilities | B25: Adjustments for other financial liabilities, non-current | C25: 30454
A26: Increase/ (decrease) in other current and non-current liabilities | B26: Other Current and Non Current Liabilities | C26: 30519
A27: Cash (used in)/ generated from operations | B27: Cash Generated From Operations | C27: 30372
A28: Income taxes paid (net of refund) | B28: Income Tax Paid | C28: 30422
A29: Net cash flow (used in)/ generated from operating activities | B29: Net Cash Flow From Operating Activities | C29: 17538
A30: Cash flow from investing activities | D30: Heading
A31: Purchase of property, plant and equipment and intangible assets (including capital work-in-progress and capital advances) | B31: Purchase Of Fixed Assets (Tangible / Intangible) | C31: 17556
A32: Proceeds from sale of property, plant and equipment | B32: Sale Of Fixed Assets (Tangible / Intangible) | C32: 30662
A33: Purchase of investment in mutual funds | B33: Investments in Mutual Funds | C33: 30489
A34: Proceeds from sale of investment in mutual funds | B34: Investments in Mutual Funds | C34: 30489
A35: Rental income from investment property | B35: Others-Before Working Capital Changes | C35: 17542
A36: Decrease in Deposits with remaining maturity of more than twelve months | B36: Fixed Deposits | C36: 30412
A37: Income interest received | B37: Interest Received | C37: 30485
A38: Net cash flow (used in)/ generated from investing activities | B38: Net Cash Flow From Investing Activities | C38: 17537
A39: Cash flow from financing activities | D39: Heading
A40: Dividend paid | B40: Dividend Paid | C40: 17528
...

Sheet SR_Standalone
A1: Particulars | B1: Cogencis Field | C1: Field id

Sheet SR_Consolidated
A1: Particulars | B1: Cogencis Field | C1: Field id
