Workbook

Sheet P&L_Standalone
A1: Particulars | B1: Cogencis Field | C1: Field id
A2: Income
A3: Revenue from operations | B3: Gross Sales/Income from Operations | C3: 256
A4: Other income | B4: Miscellaneous Income | C4: 265
A5: Total income | B5: Total Income | C5: 25238
A6: Expenses
A7: Employee benefits expense | B7: Employee Benefit Expense | C7: 238
A8: Finance costs | B8: Finance Costs | C8: 246
A9: Depreciation and amortization expense | B9: Depreciation, Depletion and Amortisation Expense | C9: 232
A10: Impairment allowance for trade receivables | B10: Provision/Written Off/for Contingencies | C10: 305
A11: Share of loss from Limited Liability Partnerships before exceptional items (net) | B11: Other Expenses | C11: 279
A12: Other expenses | B12: Other Expenses | C12: 279
A13: Total expenses | B13: Total Expenses | C13: 320
A14: Profit /(loss) before exceptional items and tax expense | B14: Profit/(Loss) from Ordinary Activities after Finance Costs but before Exceptional Items | C14: 294
A15: Exceptional items | D15: Heading
A16: Share of profit from Limited Liability Partnerships
A17: Profit on sale of business unit | B17: Other Exceptional Items | C17: 278
A18: Total exceptional items | B18: Total Exceptional Items | C18: 319
A19: Profit /(loss) before tax expense | B19: Profit/(Loss) From Ordinary Activities before Tax | C19: 296
A20: Tax expense, net
A21: Current tax | B21: Tax Expense | C21: 318
A22: Provision - foreign income taxes | B22: Tax Expense | C22: 318
A23: Deferred tax charge | B23: Deferred Tax | C23: 231
A24: Total tax expense
A25: Net Profit /(loss) for the period/ year | B25: Net Profit/(Loss) for the Period | C25: 269
A26: Other comprehensive (loss)/ income, net of tax expense | D26: Heading
A27: Items that will not be reclassified subsequently to profit or loss | D27: Sub-head
A28: Re-measurement loss on defined benefits plan | B28: Items that will not be reclassified to Profit or Loss | C28: 22293
A29: Total other comprehensive loss | B29: Other Comprehensive Income | C29: 16484
A30: Total comprehensive income /(loss) for the period/ year | B30: Total Comprehensive Gain (Loss) For the Year | C30: 20019
A31: Paid up equity share capital [face value of ₹ 5 per share] | B31: Paid-Up Equity Share Capital | C31: 282
A32: Other equity | B32: Reserve excluding Revaluation Reserves (as per Balance Sheet of Previous Accounting Year) | C32: 309
A33: Earnings per share (of ₹ 5/- each) (not annualised in case of the interim periods)
A34: Basic (₹) | B34: Basic EPS | C34: 222
A35: Diluted (₹) | B35: Diluted EPS | C35: 234

Sheet P&L_Consolidated
A1: Particulars | B1: Cogencis Field | C1: Field id
A2: Income
A3: Revenue from operations | B3: Gross Sales/Income from Operations | C3: 256
A4: Other income | B4: Miscellaneous Income | C4: 265
A5: Total income | B5: Total Income | C5: 25238
A6: Expenses
A7: Employee benefits expense | B7: Employee Benefit Expense | C7: 238
A8: Finance costs | B8: Finance Costs | C8: 246
A9: Depreciation and amortization expense | B9: Depreciation, Depletion and Amortisation Expense | C9: 232
A10: Impairment allowance for trade receivables | B10: Provision/Written Off/for Contingencies | C10: 305
A11: Other expenses | B11: Other Expenses | C11: 279
A12: Total expenses | B12: Total Expenses | C12: 320
A13: Profit/(loss) before exceptional items and tax expense | B13: Profit/(Loss) from Ordinary Activities after Finance Costs but before Exceptional Items | C13: 294
A14: Exceptional items
A15: Profit on sales of business unit | B15: Other Exceptional Items | C15: 278
A16: Total exceptional items | B16: Total Exceptional Items | C16: 319
A17: Profit /(loss) before tax expense | B17: Profit/(Loss) From Ordinary Activities before Tax | C17: 296
A18: Tax expense net
A19: Current tax charge | B19: Tax Expense | C19: 318
A20: Provision - foreign income taxes | B20: Tax Expense | C20: 318
A21: Deferred tax charge/(credit) | B21: Deferred Tax | C21: 231
A22: Total tax expense
A23: Net Profit /(loss) for the period/ year | B23: Net Profit/(Loss) for the Period | C23: 269
A24: Other comprehensive income/ (loss) net of tax expense | D24: Heading
A25: Items that will be reclassified subsequently to profit or loss: | D25: Sub-head
A26: Net exchange differences gain/(loss) on translation of foreign operations | B26: Items that will be reclassified to Profit or Loss | C26: 22294
A27: Items that will not be reclassified subsequently to profit or loss: | D27: Sub-head
A28: Re-measurement loss on defined benefit plan | B28: Items that will not be reclassified to Profit or Loss | C28: 22293
A29: Total other comprehensive income | B29: Other Comprehensive Income | C29: 16484
A30: Total comprehensive income/(loss) for the period year | B30: Total Comprehensive Gain (Loss) For the Year | C30: 20019
A31: Paid up equity share capital [face value of ₹ 5 per share] | B31: Paid-Up Equity Share Capital | C31: 282
A32: Other equity | B32: Reserve excluding Revaluation Reserves (as per Balance Sheet of Previous Accounting Year) | C32: 309
A33: Earnings per share (of ₹ 5/- each) (not annualised in case of the interim periods)
A34: Basic (₹) | B34: Basic EPS | C34: 222
A35: Diluted {₹) | B35: Diluted EPS | C35: 234

Sheet BS_Standalone
A1: Particulars | B1: Cogencis Field | C1: Field id
A2: ASSETS
A3: Non-current assets
A4: Property, plant and equipment | B4: Property, Plant & Equipment | C4: 20222
A5: Right-of-use assets | B5: Right-of-use asset | C5: 30342
A6: Intangible assets | B6: Other Intangible Assets | C6: 20221
A7: Financial assets
A8: Investments | B8: Non-Current Investments | C8: 13748
A9: Other financial assets | B9: Other Non-Current Financial Assets | C9: 20216
A10: Income tax asset (net) | B10: Income Tax assets (net) | C10: 20215
A11: Other non-current assets | B11: Other Non-Current Assets | C11: 13753
A12: Current assets
A13: Financial assets
A14: Investments | B14: Current Investments | C14: 13724
A15: Loans | B15: Loans, Current | C15: 20230
A16: Trade receivables | B16: Trade Receivables | C16: 13780
A17: Cash and cash equivalents | B17: Cash And Cash Equivalents | C17: 13722
A18: Other balances with banks | B18: Bank balance other than cash and cash equivalents | C18: 29788
A19: Other financial assets | B19: Other Current Financial Assets | C19: 20231
A20: Other current assets | B20: Other Current Assets | C20: 13750
A21: Total assets | B21: Total Assets | C21: 13771
A22: EQUITY AND LIABILITIES
A23: Equity
A24: Equity share capital | B24: Share Capital | C24: 13765
A25: Other equity | B25: Reserves And Surplus/Other Equity | C25: 13762
A26: Total equity | B26: Total Share Holder's Funds | C26: 13773
A27: Liabilities
A28: Non-current liabilities
A29: Financial liabilities
A30: Lease liabilities | B30: Lease liabilities | C30: 30340
A31: Current liabilities
A32: Financial liabilities
A33: Lease liabilities | B33: Lease liabilities | C33: 25716
A34: Trade payables
A35: total outstanding dues of micro enterprises and small enterprises | B35: Trade Payables | C35: 13779
A36: total outstanding dues of creditors other than micro enterprises and small enterprises | B36: Trade Payables | C36: 13779
A37: Other financial liabilities | B37: Other Current Financial Liabilities | C37: 20214
A38: Other current liabilities | B38: Other liabilities | C38: 26450
A39: Provisions | B39: Short-Term Provisions | C39: 13767
A40: Total liabilities
...

Sheet BS_Consolidated
A1: Particulars | B1: Cogencis Field | C1: Field id
A2: ASSETS
A3: Non-current assets
A4: Property, plant and equipment | B4: Property, Plant & Equipment | C4: 20222
A5: Right-of-use assets | B5: Right-of-use asset | C5: 30342
A6: Goodwill on consolidation | B6: Goodwill On Consolidation | C6: 13734
A7: Other intangible assets | B7: Other Intangible Assets | C7: 20221
A8: Financial assets
A9: Investments | B9: Non-Current Investments | C9: 13748
A10: Other financial assets | B10: Other Non-Current Financial Assets | C10: 20216
A11: Income tax assets (net) | B11: Income Tax assets (net) | C11: 20215
A12: Other non-current assets | B12: Other Non-Current Assets | C12: 13753
A13: Current assets
A14: Financial assets
A15: Loans | B15: Loans, Current | C15: 20230
A16: Investments | B16: Current Investments | C16: 13724
A17: Trade receivables | B17: Trade Receivables | C17: 13780
A18: Cash and cash equivalents | B18: Cash And Cash Equivalents | C18: 13722
A19: Other balances with banks | B19: Bank balance other than cash and cash equivalents | C19: 29788
A20: Other financial assets | B20: Other Current Financial Assets | C20: 20231
A21: Other current assets | B21: Other Current Assets | C21: 13750
A22: Total assets | B22: Total Assets | C22: 13771
A23: EQUITY AND LIABILITIES
A24: Equity
A25: Equity share capital | B25: Share Capital | C25: 13765
A26: Other equity | B26: Reserves And Surplus/Other Equity | C26: 13762
A27: T otal equity | B27: Total Share Holder's Funds | C27: 13773
A28: Liabilities
A29: Non-current liabilities
A30: Financial liabilities
A31: Lease liabilities | B31: Lease liabilities | C31: 30340
A32: Provisions | B32: Long-Term Provisions | C32: 13743
A33: Deferred tax liabilities (net) | B33: Deferred Tax Liability (Net) | C33: 13727
A34: Current liabilities
A35: Financial liabilities
A36: Lease liabilities | B36: Lease liabilities | C36: 25716
A37: Trade payables
A38: total outstanding dues of micro enterprises and small enterprises | B38: Trade Payables | C38: 13779
A39: total outstanding dues of creditors other than micro enterprises and small enterprises | B39: Trade Payables | C39: 13779
A40: Other financial liabilities | B40: Other Current Financial Liabilities | C40: 20214
...

Sheet CFS_Standalone
A1: Particulars | B1: Cogencis Field | C1: Field id
A2: Cash flow from operating activities
A3: Profit /(loss) before tax | B3: Net Profit Before Tax And Exceptional Item | C3: 17539
A4: Adjustments to reconcile Profit /(loss) before tax to net cash flows:
A5: Depreciation of property, plant and equipment and right-of-use assets | B5: Depreciation and Amortisation Expense | C5: 30399
A6: Amortization of intangible assets | B6: Depreciation and Amortisation Expense | C6: 30399
A7: Employee share based payments expense | B7: Employees Stock Options Grants | C7: 30407
A8: Interest income (including fair value changes) | B8: Interest Income | C8: 30481
A9: Net gain on sale of investment (including fair value changes) | B9: Profit On Sale Of Investments | C9: 30577
A10: Finance costs (including fair value changes) | B10: Interest Expense | C10: 30479
A11: Impairment allowance for trade receivables | B11: Provision For Doubtful Debts | C11: 30631
A12: Gain on termination/ modification of lease agreement | B12: Others-Before Working Capital Changes | C12: 17542
A13: Loss/ (gain) on disposal of property, plant and equipment | B13: Profit On Sale Of Fixed Assets | C13: 30576
A14: Share of loss from Limited Liability Partnerships (net) | B14: Others-Before Working Capital Changes | C14: 17542
A15: Profit on sale of business unit | B15: Others-Before Working Capital Changes | C15: 17542
A16: Net foreign exchange differences | B16: Foreign Exchange Gain / Loss | C16: 30414
A17: Operating loss before working capital changes | B17: Operating Profit Before Working Capital Changes | C17: 30511
A18: Working capital adjustments:
A19: (Increase)/ decrease in loans | B19: Loans And Advances | C19: 30497
A20: (Increase)/ decrease in trade receivables | B20: Trade And Other Receivables | C20: 30674
A21: (Increase)/ decrease in other financial assets and other assets | B21: Adjustments for other financial assets, non-current | C21: 30452
A22: Increase/ (decrease) in trade payables | B22: Trade Payables And Others | C22: 30675
A23: Increase/ (decrease) in other financial liabilities | B23: Adjustments for other financial liabilities, non-current | C23: 30454
A24: Increase/ (decrease) in other current liabilities | B24: Other Current and Non Current Liabilities | C24: 30519
A25: Increase/ (decrease) in provisions | B25: Provisions | C25: 30627
A26: Income tax refund (net) | B26: Income Tax Paid | C26: 30422
A27: Net cash flows generated from/ (used in) operating activities | B27: Net Cash Flow From Operating Activities | C27: 17538
A28: Cash flow from investing activities
A29: Purchase of property, plant and equipment, other intangible assets and capital advances | B29: Purchase Of Fixed Assets (Tangible / Intangible) | C29: 17556
A30: Drawings from Limited Liability Partnerships | B30: Others-Investing Activities | C30: 17545
A31: Share of loss paid to Limited Liability Partnerships | B31: Others-Investing Activities | C31: 17545
A32: Sale of mutual funds (net of purchases) | B32: Investments in Mutual Funds | C32: 30489
A33: Proceeds from liquidation of subsidiary (Subex Account Aggregator Services Pvt Ltd) | B33: Others-Investing Activities | C33: 17545
A34: Net (investment in)/ withdrawal from deposit account | B34: Fixed Deposits | C34: 30412
A35: Interest received | B35: Interest Received | C35: 30485
A36: Net cash flows (used in) / generated from investing activities | B36: Net Cash Flows from (Used in) Investing Activities before Extraordinary Items | C36: 30509
A37: Cash flow from financing activities
A38: Proceeds from sale of treasury shares | B38: Others-Financing Activities | C38: 17543
A39: Interest paid on lease liabilities | B39: Interest Paid | C39: 30484
A40: Repayment of principal portion of lease liabilities | B40: Payments of lease liabilities | C40: 30467
...

Sheet CFS_Consolidated
A1: Particulars | B1: Cogencis Field | C1: Field id
A2: Cash flow from operating activities
A3: Profit/ (loss) before tax | B3: Net Profit Before Tax And Exceptional Item | C3: 17539
A4: Adjustments to reconcile profit/(loss) before tax to net cash flows:
A5: Depreciation of property, plant and equipment and right-of-use assets | B5: =VLOOKUP(A5,CFS_Standalone!A:C,2,0) -> Depreciation and Amortisation Expense | C5: =VLOOKUP(A5,CFS_Standalone!A:C,3,0) -> 30399
A6: Amortization of intangible assets | B6: =VLOOKUP(A6,CFS_Standalone!A:C,2,0) -> Depreciation and Amortisation Expense | C6: =VLOOKUP(A6,CFS_Standalone!A:C,3,0) -> 30399
A7: Loss on disposal of property, plant and equipment (net) | B7: Profit On Sale Of Fixed Assets | C7: 30576
A8: Interest income (including fair value changes) | B8: =VLOOKUP(A8,CFS_Standalone!A:C,2,0) -> Interest Income | C8: =VLOOKUP(A8,CFS_Standalone!A:C,3,0) -> 30481
A9: Net gain on sale of investment (including fair value changes) | B9: =VLOOKUP(A9,CFS_Standalone!A:C,2,0) -> Profit On Sale Of Investments | C9: =VLOOKUP(A9,CFS_Standalone!A:C,3,0) -> 30577
A10: Finance costs (including fair value changes) | B10: =VLOOKUP(A10,CFS_Standalone!A:C,2,0) -> Interest Expense | C10: =VLOOKUP(A10,CFS_Standalone!A:C,3,0) -> 30479
A11: Impairment allowance for trade receivables | B11: =VLOOKUP(A11,CFS_Standalone!A:C,2,0) -> Provision For Doubtful Debts | C11: =VLOOKUP(A11,CFS_Standalone!A:C,3,0) -> 30631
A12: Employee share based payments expense | B12: Employees Stock Options Grants | C12: 30407
A13: Gain on termination/ modification of lease agreement | B13: =VLOOKUP(A13,CFS_Standalone!A:C,2,0) -> Others-Before Working Capital Changes | C13: =VLOOKUP(A13,CFS_Standalone!A:C,3,0) -> 17542
A14: Profit on sale of business unit | B14: =VLOOKUP(A14,CFS_Standalone!A:C,2,0) -> Others-Before Working Capital Changes | C14: =VLOOKUP(A14,CFS_Standalone!A:C,3,0) -> 17542
A15: Net foreign exchange differences | B15: =VLOOKUP(A15,CFS_Standalone!A:C,2,0) -> Foreign Exchange Gain / Loss | C15: =VLOOKUP(A15,CFS_Standalone!A:C,3,0) -> 30414
A16: Operating profit/ (loss) before working capital changes | B16: Operating Profit Before Working Capital Changes | C16: 30511
A17: Working capital adjustments:
A18: (Increase)/ decrease in loans | B18: =VLOOKUP(A18,CFS_Standalone!A:C,2,0) -> Loans And Advances | C18: =VLOOKUP(A18,CFS_Standalone!A:C,3,0) -> 30497
A19: (Increase)/ decrease in trade receivables | B19: =VLOOKUP(A19,CFS_Standalone!A:C,2,0) -> Trade And Other Receivables | C19: =VLOOKUP(A19,CFS_Standalone!A:C,3,0) -> 30674
A20: (Increase)/ decrease in other financial assets and other assets | B20: =VLOOKUP(A20,CFS_Standalone!A:C,2,0) -> Adjustments for other financial assets, non-current | C20: =VLOOKUP(A20,CFS_Standalone!A:C,3,0) -> 30452
A21: Increase/ (decrease) in trade payables | B21: =VLOOKUP(A21,CFS_Standalone!A:C,2,0) -> Trade Payables And Others | C21: =VLOOKUP(A21,CFS_Standalone!A:C,3,0) -> 30675
A22: Increase/ (decrease) in other financial liabilities | B22: =VLOOKUP(A22,CFS_Standalone!A:C,2,0) -> Adjustments for other financial liabilities, non-current | C22: =VLOOKUP(A22,CFS_Standalone!A:C,3,0) -> 30454
A23: Increase/ (decrease) in other current liabilities | B23: =VLOOKUP(A23,CFS_Standalone!A:C,2,0) -> Other Current and Non Current Liabilities | C23: =VLOOKUP(A23,CFS_Standalone!A:C,3,0) -> 30519
A24: Increase/ (decrease) in provisions | B24: =VLOOKUP(A24,CFS_Standalone!A:C,2,0) -> Provisions | C24: =VLOOKUP(A24,CFS_Standalone!A:C,3,0) -> 30627
A25: Income tax refund (net) | B25: =VLOOKUP(A25,CFS_Standalone!A:C,2,0) -> Income Tax Paid | C25: =VLOOKUP(A25,CFS_Standalone!A:C,3,0) -> 30422
A26: Net cash flows generated from/ (used in) operating activities | B26: =VLOOKUP(A26,CFS_Standalone!A:C,2,0) -> Net Cash Flow From Operating Activities | C26: =VLOOKUP(A26,CFS_Standalone!A:C,3,0) -> 17538
A27: Cash flow from investing activities
A28: Purchase of property, plant and equipment, other intangible assets and capital advances | B28: =VLOOKUP(A28,CFS_Standalone!A:C,2,0) -> Purchase Of Fixed Assets (Tangible / Intangible) | C28: =VLOOKUP(A28,CFS_Standalone!A:C,3,0) -> 17556
A29: Proceeds from sale of investments in mutual fund (net of purchase) | B29: Sale Of Investments | C29: 17563
A30: Net withdrawal / (investment) in deposit account | B30: Fixed Deposits | C30: 30412
A31: Interest received | B31: =VLOOKUP(A31,CFS_Standalone!A:C,2,0) -> Interest Received | C31: =VLOOKUP(A31,CFS_Standalone!A:C,3,0) -> 30485
A32: Net cash flows generated from/ (used in) investing activities | B32: Net Cash Flow From Investing Activities | C32: 17537
A33: Cash flow from financing activities
A34: Proceeds from sale of treasury shares | B34: =VLOOKUP(A34,CFS_Standalone!A:C,2,0) -> Others-Financing Activities | C34: =VLOOKUP(A34,CFS_Standalone!A:C,3,0) -> 17543
A35: Interest paid on lease liabilities | B35: =VLOOKUP(A35,CFS_Standalone!A:C,2,0) -> Interest Paid | C35: =VLOOKUP(A35,CFS_Standalone!A:C,3,0) -> 30484
A36: Repayment of principal portion of lease liabilities | B36: =VLOOKUP(A36,CFS_Standalone!A:C,2,0) -> Payments of lease liabilities | C36: =VLOOKUP(A36,CFS_Standalone!A:C,3,0) -> 30467
A37: Net cash flows used in financing activities | B37: Net Cash Flow From Financing Activities | C37: 17536
A38: Net increase/ (decrease) in cash and cash equivalents | B38: Net Increase in Cash and Cash Equivalents | C38: 17541
A39: Net foreign exchange difference on cash and cash equivalents | B39: Net increase (decrease) in cash and cash equivalents before effect of exchange rate changes | C39: 30458
A40: Cash and cash equivalents at the beginning of the period | B40: =VLOOKUP(A40,CFS_Standalone!A:C,2,0) -> Cash and Cash Equivalents at the Beginning of the Year | C40: =VLOOKUP(A40,CFS_Standalone!A:C,3,0) -> 17519
...

Sheet SR_Standalone
A1: Particulars | B1: Cogencis Field | C1: Field id

Sheet SR_Consolidated
A1: Particulars | B1: Cogencis Field | C1: Field id
