Workbook

Sheet P&L_Standalone
A1: Particulars | B1: Cogencis Field | C1: Field id
A2: Income from Operations
A3: Net Sales /Income from operations (net of excise duty) | B3: Gross Sales/Income from Operations | C3: 256
A4: Other operating Income | B4: Other Operating Income | C4: 281
A5: Other Income | B5: Miscellaneous Income | C5: 265
A6: Total Income from Operations (net) | B6: Total Income | C6: 25238
A7: Expenses
A8: Purchases | B8: Purchase of Stock-in-Trade | C8: 307
A9: Changes in inventories of finished goods, work-in­ progress and stock in trade | B9: Changes in Inventories of Finished Goods, Work-In-Progress and Stock-In-Trade | C9: 227
A10: Technical & Operation expense | B10: Operating Expenses | C10: 276
A11: Employee benefit expense | B11: Employee Benefit Expense | C11: 238
A12: Finance costs | B12: Finance Costs | C12: 246
A13: Depreciation & amortisation expense | B13: Depreciation, Depletion and Amortisation Expense | C13: 232
A14: Other Expenses | B14: Other Expenses | C14: 279
A15: Total Expenses | B15: Total Expenses | C15: 320
A16: Profit/(Loss) from ordinary activities but before Exceptional Items | B16: Profit/(Loss) from Ordinary Activities after Finance Costs but before Exceptional Items | C16: 294
A17: Add: Exceptional Items | B17: Other Exceptional Items | C17: 278
A18: Less: Exceptional Items | B18: Other Exceptional Items | C18: 278
A19: Profit/(Loss) from ordinary activities before tax | B19: Profit/(Loss) From Ordinary Activities before Tax | C19: 296
A20: Tax expense
A21: Current Tax | B21: Tax Expense | C21: 318
A22: Tax Expenses relating to Earlier years | B22: Tax Expense | C22: 318
A23: Deferred Tax | B23: Deferred Tax | C23: 231
A24: Profit/(Loss) from ordinary activities after tax | B24: Net Profit/(Loss) from Ordinary Activities after Tax | C24: 270
A25: Extraordinary items (net of tax Rs expense lakhs) | B25: Extraordinary Items | C25: 244
A26: Net Profit/(Loss) before Other comprehensive income | B26: Net Profit/(Loss) for the Period | C26: 269
A27: Other Comprehensive Income
A28: Add: Items that will be reclassified to profit or loss | B28: Items that will be reclassified to Profit or Loss | C28: 22294
A29: Less: Income Tax relating to items that will be reclassified to profit or loss | B29: Income Tax related to items that will be reclassified to Profit or Loss | C29: 22296
A30: Net Profit/(Loss) for the period | B30: Total Comprehensive Gain (Loss) For the Year | C30: 20019
A31: Paid up Equity Share Capital (Face Value Rs 10/-) | B31: Paid-Up Equity Share Capital | C31: 282
A32: Reserves (excluding Revaluation Reserve as per the Balance Sheet of previous accounting year) | B32: Reserve excluding Revaluation Reserves (as per Balance Sheet of Previous Accounting Year) | C32: 309
A33: Earning Per equity share (for continuing operations):
A34: Basic | B34: Basic EPS | C34: 222
A35: Diluted | B35: Diluted EPS | C35: 234
A36: Earning Per equity share (for discontinued & Continuing operations):
A37: Basic | B37: Basic EPS | C37: 222
A38: Diluted | B38: Diluted EPS | C38: 234

Sheet P&L_Consolidated
A1: Particulars | B1: Cogencis Field | C1: Field id
A2: Income from Operations
A3: Net Sales /Income from operations (net of excise duty) | B3: Gross Sales/Income from Operations | C3: 256
A4: Other operating Income | B4: Other Operating Income | C4: 281
A5: Other Income | B5: Miscellaneous Income | C5: 265
A6: Total Income from Operations (net) | B6: Total Income | C6: 25238
A7: Expenses
A8: Purchases | B8: Purchase of Stock-in-Trade | C8: 307
A9: Changes in inventories of finished goods work-in­ progress and stock in trade | B9: Changes in Inventories of Finished Goods, Work-In-Progress and Stock-In-Trade | C9: 227
A10: Technical & Operation expense | B10: Operating Expenses | C10: 276
A11: Employee benefit expense | B11: Employee Benefit Expense | C11: 238
A12: Finance costs | B12: Finance Costs | C12: 246
A13: Depreciation & amortisation expense | B13: Depreciation, Depletion and Amortisation Expense | C13: 232
A14: Other Expenses | B14: Other Expenses | C14: 279
A15: Total Expenses | B15: Total Expenses | C15: 320
A16: Profit/(Loss) from ordinary activities but before Exceptional Items | B16: Profit/(Loss) from ordinary activities after finance costs but before exceptional items | C16: 294
A17: Add: Exceptional Items | B17: Other Exceptional Items | C17: 278
A18: Less: Exceptional Items | B18: Other Exceptional Items | C18: 278
A19: Profit/(Loss) from ordinary activities before tax | B19: Profit/(Loss) From Ordinary Activities before Tax | C19: 296
A20: Tax expense
A21: Current Tax | B21: Tax Expense | C21: 318
A22: Tax Expenses relating to Earlier years | B22: Tax Expense | C22: 318
A23: Deferred Tax | B23: Deferred Tax | C23: 231
A24: Profit/(Loss) from ordinary activities after tax | B24: Net Profit/(Loss) from Ordinary Activities after Tax | C24: 270
A25: Extraordinary items (net of tax Rs expense Lakhs) | B25: Extraordinary Items | C25: 244
A26: Net Profit/(Loss) before Other comprehensive income
A27: Other Comprehensive Income
A28: Add:Items that will be reclassified to profit or loss | B28: Items that will be reclassified to Profit or Loss | C28: 22294
A29: Less:Income Tax relating to items that will be reclassified to profit or loss | B29: Income Tax related to items that will be reclassified to Profit or Loss | C29: 22296
A30: Net Profit/(Loss) for the period | B30: Net Profit/(Loss) for the Period | C30: 269
A31: Paid up Equity Share Capital (Face Value Rs 10/-) | B31: Paid-Up Equity Share Capital | C31: 282
A32: Reserves (excluding Revaluation Reserve as per the Balance Sheet of previous accounting year) | B32: Reserve excluding Revaluation Reserves (as per Balance Sheet of Previous Accounting Year) | C32: 309
A33: Earning Per equity share (for continuing operations):
A34: Basic | B34: Basic EPS | C34: 222
A35: Diluted | B35: Diluted EPS | C35: 234
A36: Earning Per equity share (for discontinued & Continuing operations):
A37: Basic | B37: Basic EPS | C37: 222
A38: Diluted | B38: Diluted EPS | C38: 234

Sheet BS_Standalone
A1: Particulars | B1: Cogencis Field | C1: Field id
A2: ASSETS
A3: Non-current assets
A4: Property, Plant & Equipment | B4: Property, Plant & Equipment | C4: 20222
A5: Financial Assets
A6: Investment | B6: Non-Current Investments | C6: 13748
A7: Other financial assets | B7: Other Non-Current Financial Assets | C7: 20216
A8: Other non current assets | B8: Other Non-Current Assets | C8: 13753
A9: Deferred tax Asset (net) | B9: Deferred Tax Assets (Net) | C9: 13726
A10: Current assets
A11: Inventories | B11: Inventories | C11: 13737
A12: Financial Assets
A13: Trade receivables | B13: Trade Receivables | C13: 13780
A14: Cash and Cash Equivalents | B14: Cash And Cash Equivalents | C14: 13722
A15: Other financial assets | B15: Other Current Financial Assets | C15: 20231
A16: Other current assets | B16: Other Current Assets | C16: 13750
A17: EQUITY AND LIABILITIES
A18: Equity
A19: Equity Share Capital | B19: Share Capital | C19: 13765
A20: Other Equity | B20: Reserves And Surplus/Other Equity | C20: 13762
A21: Liabilities
A22: Non-current liabilities
A23: Financial liabilities
A24: Borrowings | B24: Borrowings | C24: 20223
A25: Provisions | B25: Long-Term Provisions | C25: 13743
A26: Current liabilities
A27: Financial liabilities
A28: Borrowings | B28: Borrowings | C28: 20209
A29: Trade payables
A30: Total Outstanding dues to Micro enterprises and small enterprises | B30: Trade Payables | C30: 13779
A31: Total Outstanding dues to creditors other than Micro enterprises and small enterprises | B31: Trade Payables | C31: 13779
A32: Other financial liabilities | B32: Other Current Financial Liabilities | C32: 20214
A33: Other current liabilities | B33: Other liabilities | C33: 26450
A34: Provisions | B34: Short-Term Provisions | C34: 13767

Sheet BS_Consolidated
A1: Particulars | B1: Cogencis Field | C1: Field id
A2: ASSETS
A3: Non-current assets
A4: Property, Plant & Equipment | B4: =VLOOKUP(A4,BS_Standalone!A:C,2,0) -> Property, Plant & Equipment | C4: =VLOOKUP(A4,BS_Standalone!A:C,3,0) -> 20222
A5: Financial Assets
A6: Investment | B6: =VLOOKUP(A6,BS_Standalone!A:C,2,0) -> Non-Current Investments | C6: =VLOOKUP(A6,BS_Standalone!A:C,3,0) -> 13748
A7: Other financial assets | B7: =VLOOKUP(A7,BS_Standalone!A:C,2,0) -> Other Non-Current Financial Assets | C7: =VLOOKUP(A7,BS_Standalone!A:C,3,0) -> 20216
A8: Other non current assets | B8: =VLOOKUP(A8,BS_Standalone!A:C,2,0) -> Other Non-Current Assets | C8: =VLOOKUP(A8,BS_Standalone!A:C,3,0) -> 13753
A9: Deferred tax Asset (net) | B9: =VLOOKUP(A9,BS_Standalone!A:C,2,0) -> Deferred Tax Assets (Net) | C9: =VLOOKUP(A9,BS_Standalone!A:C,3,0) -> 13726
A10: Current assets
A11: Inventories | B11: =VLOOKUP(A11,BS_Standalone!A:C,2,0) -> Inventories | C11: =VLOOKUP(A11,BS_Standalone!A:C,3,0) -> 13737
A12: Financial Assets
A13: Trade receivables | B13: =VLOOKUP(A13,BS_Standalone!A:C,2,0) -> Trade Receivables | C13: =VLOOKUP(A13,BS_Standalone!A:C,3,0) -> 13780
A14: Cash and Cash Equivalents | B14: =VLOOKUP(A14,BS_Standalone!A:C,2,0) -> Cash And Cash Equivalents | C14: =VLOOKUP(A14,BS_Standalone!A:C,3,0) -> 13722
A15: Other financial assets | B15: Other Current Financial Assets | C15: 20231
A16: Other current assets | B16: =VLOOKUP(A16,BS_Standalone!A:C,2,0) -> Other Current Assets | C16: =VLOOKUP(A16,BS_Standalone!A:C,3,0) -> 13750
A17: EQUITY AND LIABILITIES
A18: Equity
A19: Equity Share Capital | B19: =VLOOKUP(A19,BS_Standalone!A:C,2,0) -> Share Capital | C19: =VLOOKUP(A19,BS_Standalone!A:C,3,0) -> 13765
A20: Other Equity | B20: =VLOOKUP(A20,BS_Standalone!A:C,2,0) -> Reserves And Surplus/Other Equity | C20: =VLOOKUP(A20,BS_Standalone!A:C,3,0) -> 13762
A21: Minority Interest | B21: Money Received Against Share Warrants | C21: 13745
A22: Liabilities
A23: Non-current liabilities
A24: Financial liabilities
A25: Borrowings | B25: =VLOOKUP(A25,BS_Standalone!A:C,2,0) -> Borrowings | C25: =VLOOKUP(A25,BS_Standalone!A:C,3,0) -> 20223
A26: Provisions | B26: =VLOOKUP(A26,BS_Standalone!A:C,2,0) -> Long-Term Provisions | C26: =VLOOKUP(A26,BS_Standalone!A:C,3,0) -> 13743
A27: Current liabilities
A28: Financial liabilities
A29: Borrowings | B29: Borrowings | C29: 20209
A30: Trade payables
A31: Total Outstanding dues to Micro enterprises and small enterprises | B31: =VLOOKUP(A31,BS_Standalone!A:C,2,0) -> Trade Payables | C31: =VLOOKUP(A31,BS_Standalone!A:C,3,0) -> 13779
A32: Total Outstanding dues to creditors other than Micro enterprises and small enterprises | B32: =VLOOKUP(A32,BS_Standalone!A:C,2,0) -> Trade Payables | C32: =VLOOKUP(A32,BS_Standalone!A:C,3,0) -> 13779
A33: Other financial liabilities | B33: =VLOOKUP(A33,BS_Standalone!A:C,2,0) -> Other Current Financial Liabilities | C33: =VLOOKUP(A33,BS_Standalone!A:C,3,0) -> 20214
A34: Other current liabilities | B34: =VLOOKUP(A34,BS_Standalone!A:C,2,0) -> Other liabilities | C34: =VLOOKUP(A34,BS_Standalone!A:C,3,0) -> 26450
A35: Provisions | B35: Short-Term Provisions | C35: 13767

Sheet CFS_Standalone
A1: Particulars | B1: Cogencis Field | C1: Field id
A2: Cash flow from operating activities
A3: Net Profit / (Loss) before tax as per Profit & Loss Statement | B3: Net Profit Before Tax And Exceptional Item | C3: 17539
A4: Adjustments for:
A5: Depreciation and amortisation | B5: Depreciation and Amortisation Expense | C5: 30399
A6: Sundry Credit Balances Written Back | B6: Other Provisions Written Off | C6: 30520
A7: Interest Income | B7: Interest Income | C7: 30481
A8: Bad Debts Written Off | B8: Bad Debts Written Off | C8: 30361
A9: Finance Cost | B9: Interest Expense | C9: 30479
A10: Advances Written off | B10: Other Provisions Written Off | C10: 30520
A11: SLA Deductions | B11: Others-Before Working Capital Changes | C11: 17542
A12: CSR Expenditure | B12: Others-Before Working Capital Changes | C12: 17542
A13: Exchange Fluctuations | B13: Others-Before Working Capital Changes | C13: 17542
A14: Exceptional Credit Loss | B14: Others-Before Working Capital Changes | C14: 17542
A15: Changes in Assets and Liabilities:
A16: Trade receivables | B16: Trade And Other Receivables | C16: 30674
A17: Other Financial Assets and Other Assets | B17: Adjustments for other financial assets, non-current | C17: 30452
A18: Other Non Current Assets | B18: Other Current and Non Current Assets | C18: 30518
A19: Other Financial Assets | B19: Adjustments for other financial assets, current | C19: 30451
A20: Other Current Assets | B20: Other Current and Non Current Assets | C20: 30518
A21: Inventories | B21: Inventories | C21: 30487
A22: Trade Payables | B22: Trade Payables And Others | C22: 30675
A23: Long Term Provisions | B23: Provisions | C23: 30627
A24: Other Current Liabilities | B24: Other Current and Non Current Liabilities | C24: 30519
A25: Short Term Provisions | B25: Provisions | C25: 30627
A26: Other Financial Liabilities | B26: Adjustments for other financial liabilities, non-current | C26: 30454
A27: Cash generated from operations | B27: Cash Generated From Operations | C27: 30372
... A29: Net cash flow from operating activities | B29: Net Cash Flow From Operating Activities | C29: 17538
A30: Cash flow from investing activities
A31: Property, Plant & Equipment | B31: Purchase Of Fixed Assets (Tangible / Intangible) | C31: 17556
A32: Sale of Land | B32: Sale Of Fixed Assets (Tangible / Intangible) | C32: 30662
A33: Interest Income | B33: Interest Received | C33: 30485
A34: Net cash flow from Investing activities | B34: Net Cash Flow From Investing Activities | C34: 17537
A35: Cash flow from financing activities
A36: Short Term Barrowings(Net) | B36: Proceeds From Short Term Borrowings | C36: 17555
A37: Long Term Borrowings | B37: Proceeds From Long Term Borrowings | C37: 17554
A38: Interest Paid | B38: Interest Paid | C38: 30484
A39: Net cash flow from Financing activities | B39: Net Cash Flow From Financing Activities | C39: 17536
A40: Net increase in Cash and cash equivalents | B40: Net Increase in Cash and Cash Equivalents | C40: 17541
A41: Opening balance of Cash and cash equivalents | B41: Cash and Cash Equivalents at the Beginning of the Year | C41: 17519
...

Sheet CFS_Consolidated
A1: Particulars | B1: Cogencis Field | C1: Field id
A2: Cash flow from operating activities
A3: Net Profit / (Loss) before tax as per Profit & Loss Statement | B3: Net Profit Before Tax And Exceptional Item | C3: 17539
A4: Adjustments for:
A5: Depreciation and amortisation | B5: Depreciation and Amortisation Expense | C5: 30399
A6: Sundry Credit Balances Written Back | B6: Other Provisions Written Off | C6: 30520
A7: Interest Income | B7: Interest Income | C7: 30481
A8: Bad Debts Written Off | B8: Bad Debts Written Off | C8: 30361
A9: Finance Cost | B9: Interest Expense | C9: 30479
A10: Advances Written off | B10: Other Provisions Written Off | C10: 30520
A11: SLA Deductions | B11: Others-Before Working Capital Changes | C11: 17542
A12: CSR Expenditure | B12: Others-Before Working Capital Changes | C12: 17542
A13: Exchange Fluctuations | B13: Others-Before Working Capital Changes | C13: 17542
A14: Exceptional Credit Loss | B14: Others-Before Working Capital Changes | C14: 17542
A15: Changes in Assets and Liabilities:
A16: Trade receivables | B16: Trade And Other Receivables | C16: 30674
A17: Other Financial Assets and Other Assets | B17: Adjustments for other financial assets, non-current | C17: 30452
A18: Other Non Current Assets | B18: Other Current and Non Current Assets | C18: 30518
A19: Other Financial Assets | B19: Adjustments for other financial assets, current | C19: 30451
A20: Other Current Assets | B20: Other Current and Non Current Assets | C20: 30518
A21: Inventories | B21: Inventories | C21: 30487
A22: Trade Payables | B22: Trade Payables And Others | C22: 30675
A23: Long Term Provisions | B23: Provisions | C23: 30627
A24: Other Current Liabilities | B24: Other Current and Non Current Liabilities | C24: 30519
A25: Short Term Provisions | B25: Provisions | C25: 30627
A26: Other Financial Liabilities | B26: Adjustments for other financial liabilities, non-current | C26: 30454
A27: Cash generated from operations | B27: Cash Generated From Operations | C27: 30372
... A29: Net cash flow from operating activities | B29: Net Cash Flow From Operating Activities | C29: 17538
A30: Cash flow from investing activities
A31: Property, Plant & Equipment | B31: Purchase Of Fixed Assets (Tangible / Intangible) | C31: 17556
A32: Sale of Land | B32: Sale Of Fixed Assets (Tangible / Intangible) | C32: 30662
A33: Interest Income | B33: Interest Received | C33: 30485
A34: Net cash flow from Investing activities | B34: Net Cash Flow From Investing Activities | C34: 17537
A35: Cash flow from financing activities
A36: Short Term Barrowings (Net) | B36: Proceeds From Short Term Borrowings | C36: 17555
A37: Long Term Borrowings | B37: Proceeds From Long Term Borrowings | C37: 17554
A38: Interest Paid | B38: Interest Paid | C38: 30484
A39: Net cash flow from Financing activities | B39: Net Cash Flow From Financing Activities | C39: 17536
A40: Net increase in Cash and cash equivalents | B40: Net Increase in Cash and Cash Equivalents | C40: 17541
A41: Opening balance of Cash and cash equivalents | B41: Cash and Cash Equivalents at the Beginning of the Year | C41: 17519
...

Sheet SR_Standalone
A1: Particulars | B1: Cogencis Field | C1: Field id
A2: Segment Revenue
A3: Integrated Solutions Division | B3: As per Product
A4: Technical Division | B4: As per Product
A5: Projects Division | B5: As per Product
A6: Net sales/Income from operations | B6: Total Segment Revenue | C6: 8931
A7: Segment Results [Profit / (Loss) before Tax and Interest from each Segment]
A8: Integrated Solutions Division | B8: As per Product
A9: Technical Division | B9: As per Product
A10: Projects Division | B10: As per Product
A11: Total | B11: Segment Results | C11: 8919
A12: Less:Interest Expenses | B12: Interest Expenses | C12: 8927
A13: Un-allocable expenditure (Net) | B13: Unallocated Income (Expenses) | C13: 8929
A14: Add: Interest and Other Income | B14: Other Income | C14: 14859
A15: Total Profit/(Loss) Before Exceptional items
A16: Exceptional Item: Add | B16: Exceptional Item | C16: 8926
A17: Less:
A18: Total Profit/(Loss) after Exceptional items | B18: Net Profit/(Loss) for the period | C18: 8908
A19: Segment Assets
A20: Integrated Solutions Division | B20: As per Product
A21: Technical Division | B21: As per Product
A22: Projects Division | B22: As per Product
A23: Unallocable | B23: Unallocable Corporate Assets | C23: 18580
A24: Total | B24: Total Segment Assets | C24: 18578
A25: Segment Liabilities
A26: Integrated Solutions Division | B26: As per Product
A27: Technical Division | B27: As per Product
A28: Projects Division | B28: As per Product
A29: Unallocable | B29: Unallocable Corporate Liabilities | C29: 18581
A30: Total | B30: Total Segment Liabilities | C30: 18579
A31: (Segment Assets - Liabilities)
A32: Integrated Solutions Division | B32: As per Product
A33: Technical Division | B33: As per Product
A34: Projects Division | B34: As per Product
A35: Unallocable | B35: Unallocated Income (Expenses) | C35: 8918
A36: Total | B36: Total Capital Employed | C36: 8930

Sheet SR_Consolidated
A1: Particulars | B1: Cogencis Field | C1: Field id
A2: Segment Revenue
A3: Integrated Solutions Division | B3: As per Product
A4: Technical Division | B4: As per Product
A5: Projects Division | B5: As per Product
A6: Net sales/Income from operations | B6: Total Segment Revenue | C6: 8931
A7: Segment Results [Profit / (Loss) before Tax and Interest from each Segment)
A8: Integrated Solutions Division | B8: As per Product
A9: Technical Division | B9: As per Product
A10: Projects Division | B10: As per Product
A11: Total | B11: Segment Results | C11: 8919
A12: Less: Interest Expenses | B12: Interest Expenses | C12: 8927
A13: Un-allocable expenditure (Net) | B13: Unallocated Income (Expenses) | C13: 8929
A14: Add: Interest and Other Income | B14: Interest Income | C14: 8928
A15: Total Profit/(Loss) Before Exceptional items
A16: Exceptional Item: Add | B16: Exceptional Item | C16: 8926
A17: Less:
A18: Total Profit/(Loss) after Exceptional items | B18: Net Profit/(Loss) for the period | C18: 8908
A19: Segment Assets
A20: Integrated Solutions Division | B20: As per Product
A21: Technical Division | B21: As per Product
A22: Projects Division | B22: As per Product
A23: Unallocable | B23: Unallocable Corporate Assets | C23: 18580
A24: Total | B24: Segment Revenue | C24: 8920
A25: Segment Liabilities
A26: Integrated Solutions Division | B26: As per Product
A27: Technical Division | B27: As per Product
A28: Projects Division | B28: As per Product
A29: Unallocable | B29: Unallocable Corporate Liabilities | C29: 18581
A30: Total | B30: Total Segment Liabilities | C30: 18579
A31: (Segment Assets - Liabilities)
A32: Integrated Solutions Division | B32: As per Product
A33: Technical Division | B33: As per Product
A34: Projects Division | B34: As per Product
A35: Unallocable | B35: Unallocated Income (Expenses) | C35: 8918
A36: Total | B36: Total Capital Employed | C36: 8930
