Workbook

Sheet P&L_Standalone
A1: Particulars | B1: Cogencis Field | C1: Field id
A2: INCOME | B2: Lable
A3: Revenue From Operations | B3: Gross Sales/Income from Operations | C3: 256
A4: Other Income | B4: Miscellaneous Income | C4: 265
A5: Total Income | B5: Total Income | C5: 25238
A6: EXPENSES | B6: Lable
A7: Cost of Material Consumed | B7: Cost of Materials Consumed | C7: 230
A8: Employee Benefits Expense | B8: Employee Benefit Expense | C8: 238
A9: Finance costs | B9: Finance Costs | C9: 246
A10: Depreciation and amortization expense | B10: Depreciation, Depletion and Amortisation Expense | C10: 232
A11: Other expenses | B11: Other Expenses | C11: 279
A12: Total expenses | B12: Total Expenses | C12: 320
A13: Profit/(loss) before tax | B13: Profit/(Loss) from Ordinary Activities after Finance Costs but before Exceptional Items | C13: 294
A14: Tax expense: | B14: Lable
A15: Current tax | B15: Tax Expense | C15: 318
A16: Deferred tax | B16: Deferred Tax | C16: 231
A17: Excess / (Short) provision of earlier years written off | B17: Tax Expense | C17: 318
A18: Profit/(Loss) for the period from continuing operations | B18: Net Profit/(Loss) for the Period | C18: 269
A19: Other Comprehensive Income | B19: Lable
A20: Items that will not be reclassified to Profit or Loss | B20: Items that will not be reclassified to Profit or Loss | C20: 22293
A21: Income tax relating to items that will not be reclassified to profit or loss | B21: Income Tax related to items that will not be reclassified to Profit or Loss | C21: 22295
A22: Items that will be reclassified to profit or loss | B22: Items that will be reclassified to Profit or Loss | C22: 22294
A23: Income tax relating to items that will be reclassified to profit or loss | B23: Income Tax related to items that will be reclassified to Profit or Loss | C23: 22296
A24: Total Other Comprehensive Income | B24: Other Comprehensive Income | C24: 16484
A25: Total Comprehensive Income for the Period | B25: Total Comprehensive Gain (Loss) For the Year | C25: 20019
A26: Paid-up Equity Share Capital (Face Value Rs.5 per share) | B26: Paid-Up Equity Share Capital | C26: 282
A27: Earnings per equity share (Fig in INR)(for continuing operation):
A28: Basic | B28: Basic EPS | C28: 222
A29: Diluted | B29: Diluted EPS | C29: 234

Sheet P&L_Consolidated
A1: Particulars | B1: Cogencis Field | C1: Field id
A2: INCOME | B2: Lable
A3: Revenue From Operations | B3: Gross Sales/Income from Operations | C3: 256
A4: Other Income | B4: Miscellaneous Income | C4: 265
A5: Total Income | B5: Total Income | C5: 25238
A6: EXPENSES | B6: Lable
A7: Cost of Material Consumed | B7: Cost of Materials Consumed | C7: 230
A8: Changes in Inventories of Finished Goods and Work in Progress | B8: Changes in Inventories of Finished Goods, Work-In-Progress and Stock-In-Trade | C8: 227
A9: Employee benefits expense | B9: Employee Benefit Expense | C9: 238
A10: Finance costs | B10: Finance Costs | C10: 246
A11: Depreciation and amortization expense | B11: Depreciation, Depletion and Amortisation Expense | C11: 232
A12: Other expenses | B12: Other Expenses | C12: 279
A13: Total expenses | B13: Total Expenses | C13: 320
A14: Profit/(loss) before tax | B14: Profit/(Loss) from ordinary activities after finance costs but before exceptional items | C14: 294
A15: Tax expense: | B15: Lable
A16: Current tax | B16: Tax Expense | C16: 318
A17: Deferred tax | B17: Deferred Tax | C17: 231
A18: Excess / (Short) provision of earlier years written off | B18: Tax Expense | C18: 318
A19: Profit (Loss) for the period from continuing operations | B19: Net Profit/(Loss) for the Period | C19: 269
A20: Other Comprehensive Income | B20: Lable
A21: Items that will not be reclassified to Profit or Loss | B21: Items that will not be reclassified to Profit or Loss | C21: 22293
A22: Income tax relating to items that will not be reclassified to profit or loss | B22: Income Tax related to items that will not be reclassified to Profit or Loss | C22: 22295
A23: Items that will be reclassified to profit or loss | B23: Items that will be reclassified to Profit or Loss | C23: 22294
A24: Income tax relating to items that will be reclassified to profit or loss | B24: Income Tax related to items that will be reclassified to Profit or Loss | C24: 22296
A25: Total Other Comprehensive Income | B25: Other Comprehensive Income | C25: 16484
A26: Total Income for the Period | B26: Total Comprehensive Gain (Loss) For the Year | C26: 20019
A27: Profit for the period attributable to | B27: Lable
A28: Controlling Interest | B28: Owners of the company | C28: 22299
A29: Non controlling Interest | B29: Non-Controlling Interests | C29: 22298
A30: Other Comprehensive income for the period attributable to | B30: Lable
A31: Controlling Interest | B31: Owners of the company | C31: 22291
A32: Non controlling Interest | B32: Non-Controlling Interests | C32: 22290
A33: Total Comprehensive income for the period attributable to | B33: Lable
A34: Controlling Interest | B34: Owners of the company | C34: 22303
A35: Non controlling Interest | B35: Non-Controlling Interests | C35: 22302
A36: Paid-up Equity Share Capital (Face Value Rs.5 per share) | B36: Paid-Up Equity Share Capital | C36: 282
A37: Earnings per equity share (In Rs.)
A38: Basic | B38: Basic EPS | C38: 222
A39: Diluted | B39: Diluted EPS | C39: 234

Sheet BS_Standalone
A1: Particulars | B1: Cogencis Field | C1: Field id
A2: ASSETS | B2: =_xlfn.XLOOKUP(A2,'[1]Standalone Balance Sheet'!$B:$B,'[1]Standalone Balance Sheet'!$C:$C) -> Lable
A3: Non-Current assets | B3: =_xlfn.XLOOKUP(A3,'[1]Standalone Balance Sheet'!$B:$B,'[1]Standalone Balance Sheet'!$C:$C) -> Lable
A4: Property, Plant and Equipment | B4: =_xlfn.XLOOKUP(A4,'[1]Standalone Balance Sheet'!$B:$B,'[1]Standalone Balance Sheet'!$C:$C) -> Property, Plant & Equipment | C4: =_xlfn.XLOOKUP(A4,'[1]Standalone Balance Sheet'!$B:$B,'[1]Standalone Balance Sheet'!$D:$D) -> 20222
A5: Right of Use Assets (Leased Assets) | B5: Right-of-use asset | C5: 30342
A6: Capital Work in Progress | B6: =_xlfn.XLOOKUP(A6,'[1]Standalone Balance Sheet'!$B:$B,'[1]Standalone Balance Sheet'!$C:$C) -> Capital Work-In-Progress | C6: =_xlfn.XLOOKUP(A6,'[1]Standalone Balance Sheet'!$B:$B,'[1]Standalone Balance Sheet'!$D:$D) -> 13720
A7: Financial Assets | B7: =_xlfn.XLOOKUP(A7,'[1]Standalone Balance Sheet'!$B:$B,'[1]Standalone Balance Sheet'!$C:$C) -> Lable
A8: Loans & Advances | B8: Loans Non-Current | C8: 20217
A9: Investments | B9: =_xlfn.XLOOKUP(A9,'[1]Standalone Balance Sheet'!$B:$B,'[1]Standalone Balance Sheet'!$C:$C) -> Non-Current Investments | C9: =_xlfn.XLOOKUP(A9,'[1]Standalone Balance Sheet'!$B:$B,'[1]Standalone Balance Sheet'!$D:$D) -> 13748
A10: Other Non-Current Assets | B10: =_xlfn.XLOOKUP(A10,'[1]Standalone Balance Sheet'!$B:$B,'[1]Standalone Balance Sheet'!$C:$C) -> Other Non-Current Assets | C10: =_xlfn.XLOOKUP(A10,'[1]Standalone Balance Sheet'!$B:$B,'[1]Standalone Balance Sheet'!$D:$D) -> 13753
A11: Deferred Tax Asset (Net) | B11: =_xlfn.XLOOKUP(A11,'[1]Standalone Balance Sheet'!$B:$B,'[1]Standalone Balance Sheet'!$C:$C) -> Deferred Tax Assets (Net) | C11: =_xlfn.XLOOKUP(A11,'[1]Standalone Balance Sheet'!$B:$B,'[1]Standalone Balance Sheet'!$D:$D) -> 13726
A12: Current assets | B12: =_xlfn.XLOOKUP(A12,'[1]Standalone Balance Sheet'!$B:$B,'[1]Standalone Balance Sheet'!$C:$C) -> Lable
A13: Inventories | B13: =_xlfn.XLOOKUP(A13,'[1]Standalone Balance Sheet'!$B:$B,'[1]Standalone Balance Sheet'!$C:$C) -> Inventories | C13: =_xlfn.XLOOKUP(A13,'[1]Standalone Balance Sheet'!$B:$B,'[1]Standalone Balance Sheet'!$D:$D) -> 13737
A14: Financial Assets | B14: =_xlfn.XLOOKUP(A14,'[1]Standalone Balance Sheet'!$B:$B,'[1]Standalone Balance Sheet'!$C:$C) -> Lable
A15: Investments | B15: Current Investments | C15: 13724
A16: Loans & Advances | B16: Loans, Current | C16: 20230
A17: Trade receivables | B17: Trade Receivables | C17: 13780
A18: Cash and cash equivalents | B18: =_xlfn.XLOOKUP(A18,'[1]Standalone Balance Sheet'!$B:$B,'[1]Standalone Balance Sheet'!$C:$C) -> Cash And Cash Equivalents | C18: =_xlfn.XLOOKUP(A18,'[1]Standalone Balance Sheet'!$B:$B,'[1]Standalone Balance Sheet'!$D:$D) -> 13722
A19: Other current assets | B19: Other Current Assets | C19: 13750
A20: Total Assets | B20: =_xlfn.XLOOKUP(A20,'[1]Standalone Balance Sheet'!$B:$B,'[1]Standalone Balance Sheet'!$C:$C) -> Total Assets | C20: =_xlfn.XLOOKUP(A20,'[1]Standalone Balance Sheet'!$B:$B,'[1]Standalone Balance Sheet'!$D:$D) -> 13771
A21: EQUITY AND LIABILITIES | B21: =_xlfn.XLOOKUP(A21,'[1]Standalone Balance Sheet'!$B:$B,'[1]Standalone Balance Sheet'!$C:$C) -> Lable
A22: Equity | B22: =_xlfn.XLOOKUP(A22,'[1]Standalone Balance Sheet'!$B:$B,'[1]Standalone Balance Sheet'!$C:$C) -> Lable
A23: Equity Share capital | B23: =_xlfn.XLOOKUP(A23,'[1]Standalone Balance Sheet'!$B:$B,'[1]Standalone Balance Sheet'!$C:$C) -> Share Capital | C23: =_xlfn.XLOOKUP(A23,'[1]Standalone Balance Sheet'!$B:$B,'[1]Standalone Balance Sheet'!$D:$D) -> 13765
A24: Other Equity | B24: =_xlfn.XLOOKUP(A24,'[1]Standalone Balance Sheet'!$B:$B,'[1]Standalone Balance Sheet'!$C:$C) -> Reserves And Surplus/Other Equity | C24: =_xlfn.XLOOKUP(A24,'[1]Standalone Balance Sheet'!$B:$B,'[1]Standalone Balance Sheet'!$D:$D) -> 13762
A25: LIABILITIES | B25: =_xlfn.XLOOKUP(A25,'[1]Standalone Balance Sheet'!$B:$B,'[1]Standalone Balance Sheet'!$C:$C) -> Lable
A26: Non-current liabilities | B26: =_xlfn.XLOOKUP(A26,'[1]Standalone Balance Sheet'!$B:$B,'[1]Standalone Balance Sheet'!$C:$C) -> Lable
A27: Financial Liabilities | B27: =_xlfn.XLOOKUP(A27,'[1]Standalone Balance Sheet'!$B:$B,'[1]Standalone Balance Sheet'!$C:$C) -> Lable
A28: Non Current Borrowings | B28: Borrowings | C28: 20223
A29: Lease Liabilities | B29: Lease liabilities | C29: 30340
A30: Provisions | B30: Long-Term Provisions | C30: 13743
A31: Deferred Tax Liability (Net) | B31: Deferred Tax Liability (Net) | C31: 13727
A32: Current liabilities | B32: =_xlfn.XLOOKUP(A32,'[1]Standalone Balance Sheet'!$B:$B,'[1]Standalone Balance Sheet'!$C:$C) -> Lable
A33: Financial Liabilities | B33: =_xlfn.XLOOKUP(A33,'[1]Standalone Balance Sheet'!$B:$B,'[1]Standalone Balance Sheet'!$C:$C) -> Lable
A34: Borrowings | B34: Borrowings | C34: 20209
A35: Trade payables
A36: Total Outstanding Dues of Micro Medium and small Enterprises | B36: Trade Payables | C36: 13779
A37: Total Outstanding Dues to Creditors other than Micro and small Enterprises | B37: Trade Payables | C37: 13779
A38: Other current liabilities | B38: =_xlfn.XLOOKUP(A38,'[1]Standalone Balance Sheet'!$B:$B,'[1]Standalone Balance Sheet'!$C:$C) -> Other liabilities | C38: =_xlfn.XLOOKUP(A38,'[1]Standalone Balance Sheet'!$B:$B,'[1]Standalone Balance Sheet'!$D:$D) -> 26450
A39: Current Tax Liabilities (Net) | B39: Current Tax Liabilities (Net) | C39: 20211
A40: Short Term Provisions | B40: =_xlfn.XLOOKUP(A40,'[1]Standalone Balance Sheet'!$B:$B,'[1]Standalone Balance Sheet'!$C:$C) -> Short-Term Provisions | C40: =_xlfn.XLOOKUP(A40,'[1]Standalone Balance Sheet'!$B:$B,'[1]Standalone Balance Sheet'!$D:$D) -> 13767
...

Sheet BS_Consolidated
A1: Particulars | B1: Cogencis Field | C1: Field id
A2: ASSETS | B2: =_xlfn.XLOOKUP(A2,BS_Standalone!A:A,BS_Standalone!B:B) -> Lable
A3: Non-current assets | B3: =_xlfn.XLOOKUP(A3,BS_Standalone!A:A,BS_Standalone!B:B) -> Lable
A4: Property, Plant and Equipment | B4: =_xlfn.XLOOKUP(A4,BS_Standalone!A:A,BS_Standalone!B:B) -> Property, Plant & Equipment | C4: =_xlfn.XLOOKUP(A4,BS_Standalone!A:A,BS_Standalone!C:C) -> 20222
A5: Right of Use Assets (Leased Assets) | B5: =_xlfn.XLOOKUP(A5,BS_Standalone!A:A,BS_Standalone!B:B) -> Right-of-use asset | C5: =_xlfn.XLOOKUP(A5,BS_Standalone!A:A,BS_Standalone!C:C) -> 30342
A6: Capital Work in Progress | B6: =_xlfn.XLOOKUP(A6,BS_Standalone!A:A,BS_Standalone!B:B) -> Capital Work-In-Progress | C6: =_xlfn.XLOOKUP(A6,BS_Standalone!A:A,BS_Standalone!C:C) -> 13720
A7: Financial Assets | B7: =_xlfn.XLOOKUP(A7,BS_Standalone!A:A,BS_Standalone!B:B) -> Lable
A8: Loans & Advances | B8: =_xlfn.XLOOKUP(A8,BS_Standalone!A:A,BS_Standalone!B:B) -> Loans Non-Current | C8: =_xlfn.XLOOKUP(A8,BS_Standalone!A:A,BS_Standalone!C:C) -> 20217
A9: Investments | B9: =_xlfn.XLOOKUP(A9,BS_Standalone!A:A,BS_Standalone!B:B) -> Non-Current Investments | C9: =_xlfn.XLOOKUP(A9,BS_Standalone!A:A,BS_Standalone!C:C) -> 13748
A10: Other | B10: Other Non-Current Financial Assets | C10: 20216
A11: Other non current asset | B11: Other Non-Current Assets | C11: 13753
A12: Deferred Tax Asset | B12: Deferred Tax Assets (Net) | C12: 13726
A13: Current assets | B13: =_xlfn.XLOOKUP(A13,BS_Standalone!A:A,BS_Standalone!B:B) -> Lable
A14: Inventories | B14: =_xlfn.XLOOKUP(A14,BS_Standalone!A:A,BS_Standalone!B:B) -> Inventories | C14: =_xlfn.XLOOKUP(A14,BS_Standalone!A:A,BS_Standalone!C:C) -> 13737
A15: Financial Assets | B15: =_xlfn.XLOOKUP(A15,BS_Standalone!A:A,BS_Standalone!B:B) -> Lable
A16: Investments | B16: Current Investments | C16: 13724
A17: Trade receivables | B17: Trade Receivables | C17: 13780
A18: Cash and cash equivalents | B18: Cash And Cash Equivalents | C18: 13722
A19: Loans & Advances | B19: Loans, Current | C19: 20230
A20: Other current assets | B20: Other Current Assets | C20: 13750
A21: Current Tax Asset | B21: Current Tax Assets (Net) | C21: 20228
A22: Total Assets | B22: =_xlfn.XLOOKUP(A22,BS_Standalone!A:A,BS_Standalone!B:B) -> Total Assets | C22: =_xlfn.XLOOKUP(A22,BS_Standalone!A:A,BS_Standalone!C:C) -> 13771
A23: EQUITY AND LIABILITIES | B23: =_xlfn.XLOOKUP(A23,BS_Standalone!A:A,BS_Standalone!B:B) -> Lable
A24: Equity | B24: =_xlfn.XLOOKUP(A24,BS_Standalone!A:A,BS_Standalone!B:B) -> Lable
A25: Equity Share capital | B25: =_xlfn.XLOOKUP(A25,BS_Standalone!A:A,BS_Standalone!B:B) -> Share Capital | C25: =_xlfn.XLOOKUP(A25,BS_Standalone!A:A,BS_Standalone!C:C) -> 13765
A26: Other Equity | B26: =_xlfn.XLOOKUP(A26,BS_Standalone!A:A,BS_Standalone!B:B) -> Reserves And Surplus/Other Equity | C26: =_xlfn.XLOOKUP(A26,BS_Standalone!A:A,BS_Standalone!C:C) -> 13762
A27: Non Controlling Interest | B27: Minority Interest | C27: 13744
A28: LIABILITIES | B28: =_xlfn.XLOOKUP(A28,BS_Standalone!A:A,BS_Standalone!B:B) -> Lable
A29: Non-current liabilities | B29: =_xlfn.XLOOKUP(A29,BS_Standalone!A:A,BS_Standalone!B:B) -> Lable
A30: Financial Liabilities | B30: =_xlfn.XLOOKUP(A30,BS_Standalone!A:A,BS_Standalone!B:B) -> Lable
A31: Non Current Borrowings | B31: =_xlfn.XLOOKUP(A31,BS_Standalone!A:A,BS_Standalone!B:B) -> Borrowings | C31: =_xlfn.XLOOKUP(A31,BS_Standalone!A:A,BS_Standalone!C:C) -> 20223
A32: Lease Liabilities | B32: Lease liabilities | C32: 30340
A33: Security Deposit | B33: Other Non Current Financial Liabilities | C33: 20226
A34: Other financial liabilities | B34: Other Non Current Financial Liabilities | C34: 20226
A35: Provisions | B35: Long-Term Provisions | C35: 13743
A36: Deferred Tax Liability | B36: Other Non-Current Liabilities | C36: 26449
A37: Security Deposit | B37: Other Non-Current Liabilities | C37: 26449
A38: Current liabilities | B38: =_xlfn.XLOOKUP(A38,BS_Standalone!A:A,BS_Standalone!B:B) -> Lable
A39: Financial Liabilities | B39: =_xlfn.XLOOKUP(A39,BS_Standalone!A:A,BS_Standalone!B:B) -> Lable
A40: Borrowings | B40: Borrowings | C40: 20209
...

Sheet CFS_Standalone
A1: Particulars | B1: Cogencis Field | C1: Field id
A2: CASH FLOW FROM OPERATING ACTIVITIES
A3: Net Profit before tax | B3: =_xlfn.XLOOKUP(A3,'[1]Standalone Cash Flow'!$B:$B,'[1]Standalone Cash Flow'!$C:$C) -> Net Profit Before Tax And Exceptional Item | C3: =_xlfn.XLOOKUP(A3,'[1]Standalone Cash Flow'!$B:$B,'[1]Standalone Cash Flow'!$D:$D) -> 17539
A4: Adjustments for:
A5: Other Comprehensive Income (OCI) | B5: Others-Before Working Capital Changes | C5: 17542
A6: Depreciation & Amortisation expenses | B6: Depreciation and Amortisation Expense | C6: 30399
A7: (Profit)/loss on Investments | B7: Loss On Sale Of Investments | C7: 30503
A8: Interest Received | B8: Interest Income | C8: 30481
A9: Dividend Received | B9: Dividend Received | C9: 30404
A10: Profit on sale of asset | B10: =_xlfn.XLOOKUP(A10,'[1]Standalone Cash Flow'!$B:$B,'[1]Standalone Cash Flow'!$C:$C) -> Profit On Sale Of Fixed Assets | C10: =_xlfn.XLOOKUP(A10,'[1]Standalone Cash Flow'!$B:$B,'[1]Standalone Cash Flow'!$D:$D) -> 30576
A11: Interest Paid | B11: Interest Expense | C11: 30479
A12: Lease liability | B12: Others-Before Working Capital Changes | C12: 17542
A13: Rent Paid | B13: Fin Lease & Rental Charges | C13: 30411
A14: Gain on liquidation | B14: Others-Before Working Capital Changes | C14: 17542
A15: Operating profit before working capital changes | B15: =_xlfn.XLOOKUP(A15,'[1]Standalone Cash Flow'!$B:$B,'[1]Standalone Cash Flow'!$C:$C) -> Operating Profit Before Working Capital Changes | C15: =_xlfn.XLOOKUP(A15,'[1]Standalone Cash Flow'!$B:$B,'[1]Standalone Cash Flow'!$D:$D) -> 30511
A16: Adjustments for:
A17: Inventories | B17: Inventories | C17: 30487
A18: Trade Receivables | B18: =_xlfn.XLOOKUP(A18,'[1]Standalone Cash Flow'!$B:$B,'[1]Standalone Cash Flow'!$C:$C) -> Trade And Other Receivables | C18: =_xlfn.XLOOKUP(A18,'[1]Standalone Cash Flow'!$B:$B,'[1]Standalone Cash Flow'!$D:$D) -> 30674
A19: Loans and Advances | B19: Loans And Advances | C19: 30497
A20: Other Current Assets | B20: Other Current and Non Current Assets | C20: 30518
A21: Other Non-Current Assets | B21: Other Current and Non Current Assets | C21: 30518
A22: Trade Payables | B22: Trade Payables And Others | C22: 30675
A23: Other Current Liabilities | B23: =_xlfn.XLOOKUP(A23,'[1]Standalone Cash Flow'!$B:$B,'[1]Standalone Cash Flow'!$C:$C) -> Other Current and Non Current Liabilities | C23: =_xlfn.XLOOKUP(A23,'[1]Standalone Cash Flow'!$B:$B,'[1]Standalone Cash Flow'!$D:$D) -> 30519
A24: Short Term Provisions | B24: =_xlfn.XLOOKUP(A24,'[1]Standalone Cash Flow'!$B:$B,'[1]Standalone Cash Flow'!$C:$C) -> Provisions | C24: =_xlfn.XLOOKUP(A24,'[1]Standalone Cash Flow'!$B:$B,'[1]Standalone Cash Flow'!$D:$D) -> 30627
A25: Non-Current Provisions | B25: =_xlfn.XLOOKUP(A25,'[1]Standalone Cash Flow'!$B:$B,'[1]Standalone Cash Flow'!$C:$C) -> Provisions | C25: =_xlfn.XLOOKUP(A25,'[1]Standalone Cash Flow'!$B:$B,'[1]Standalone Cash Flow'!$D:$D) -> 30627
A26: Cash generated from operations | B26: =_xlfn.XLOOKUP(A26,'[1]Standalone Cash Flow'!$B:$B,'[1]Standalone Cash Flow'!$C:$C) -> Cash Generated From Operations | C26: =_xlfn.XLOOKUP(A26,'[1]Standalone Cash Flow'!$B:$B,'[1]Standalone Cash Flow'!$D:$D) -> 30372
A27: Direct Taxes paid (net of refunds) | B27: =_xlfn.XLOOKUP(A27,'[1]Standalone Cash Flow'!$B:$B,'[1]Standalone Cash Flow'!$C:$C) -> Income Tax Paid | C27: =_xlfn.XLOOKUP(A27,'[1]Standalone Cash Flow'!$B:$B,'[1]Standalone Cash Flow'!$D:$D) -> 30422
A28: Net cash from operating activities | B28: =_xlfn.XLOOKUP(A28,'[1]Standalone Cash Flow'!$B:$B,'[1]Standalone Cash Flow'!$C:$C) -> Net Cash Flow From Operating Activities | C28: =_xlfn.XLOOKUP(A28,'[1]Standalone Cash Flow'!$B:$B,'[1]Standalone Cash Flow'!$D:$D) -> 17538
A29: CASH FLOW FROM INVESTING ACTIVITIES : | B29: Lable
A30: Purchase of fixed assets including capital work-in-progress | B30: Purchase Of Fixed Assets (Tangible / Intangible) | C30: 17556
A31: Proceeds from sale of fixed assets | B31: =_xlfn.XLOOKUP(A31,'[1]Standalone Cash Flow'!$B:$B,'[1]Standalone Cash Flow'!$C:$C) -> Sale Of Fixed Assets (Tangible / Intangible) | C31: =_xlfn.XLOOKUP(A31,'[1]Standalone Cash Flow'!$B:$B,'[1]Standalone Cash Flow'!$D:$D) -> 30662
A32: Sale/(purchase) of Non Current Investments | B32: Sale Of Investments | C32: 17563
A33: Interest Received | B33: Interest Received | C33: 30485
A34: Profit/(loss) on Non Current Investments | B34: Purchase Of Investments | C34: 17557
A35: Dividend Received | B35: Dividend Received | C35: 30402
A36: Sale/(purchase) of Current Investments | B36: Purchase Of Investments | C36: 17557
A37: Loans & advances | B37: Cash Receipts from Repayment of Advances and Loans Made to Other Parties | C37: 30375
A38: Net cash from investing activities | B38: =_xlfn.XLOOKUP(A38,'[1]Standalone Cash Flow'!$B:$B,'[1]Standalone Cash Flow'!$C:$C) -> Net Cash Flow From Investing Activities | C38: =_xlfn.XLOOKUP(A38,'[1]Standalone Cash Flow'!$B:$B,'[1]Standalone Cash Flow'!$D:$D) -> 17537
A39: CASH FLOW FROM FINANCING ACTIVITIES: | B39: Lable
A40: Issue of Equity Share Capital including Share Premium | B40: Proceeds From Issue Of Equity Shares (Inclu Share Premium) | C40: 17553
...

Sheet CFS_Consolidated
A1: Particulars | C1: Field id
A2: CASH FLOW FROM OPERATING ACTIVITIES
A3: Net Profit before tax | B3: =_xlfn.XLOOKUP(A3,CFS_Standalone!A:A,CFS_Standalone!B:B) -> Net Profit Before Tax And Exceptional Item | C3: =_xlfn.XLOOKUP(A3,CFS_Standalone!A:A,CFS_Standalone!C:C) -> 17539
A4: Adjustments for:
A5: Other Comprehensive Income (OCI) | B5: =_xlfn.XLOOKUP(A5,CFS_Standalone!A:A,CFS_Standalone!B:B) -> Others-Before Working Capital Changes | C5: =_xlfn.XLOOKUP(A5,CFS_Standalone!A:A,CFS_Standalone!C:C) -> 17542
A6: FCTR | B6: Others-Before Working Capital Changes | C6: 17542
A7: Depreciation & Amortisation expenses | B7: Depreciation and Amortisation Expense | C7: 30399
A8: (Profit)/loss on Investments | B8: =_xlfn.XLOOKUP(A8,CFS_Standalone!A:A,CFS_Standalone!B:B) -> Loss On Sale Of Investments | C8: =_xlfn.XLOOKUP(A8,CFS_Standalone!A:A,CFS_Standalone!C:C) -> 30503
A9: Interest Received | B9: =_xlfn.XLOOKUP(A9,CFS_Standalone!A:A,CFS_Standalone!B:B) -> Interest Income | C9: =_xlfn.XLOOKUP(A9,CFS_Standalone!A:A,CFS_Standalone!C:C) -> 30481
A10: Dividend Received | B10: =_xlfn.XLOOKUP(A10,CFS_Standalone!A:A,CFS_Standalone!B:B) -> Dividend Received | C10: =_xlfn.XLOOKUP(A10,CFS_Standalone!A:A,CFS_Standalone!C:C) -> 30404
A11: Interest Paid | B11: =_xlfn.XLOOKUP(A11,CFS_Standalone!A:A,CFS_Standalone!B:B) -> Interest Expense | C11: =_xlfn.XLOOKUP(A11,CFS_Standalone!A:A,CFS_Standalone!C:C) -> 30479
A12: Lease liability | B12: =_xlfn.XLOOKUP(A12,CFS_Standalone!A:A,CFS_Standalone!B:B) -> Others-Before Working Capital Changes | C12: =_xlfn.XLOOKUP(A12,CFS_Standalone!A:A,CFS_Standalone!C:C) -> 17542
A13: Rent Paid | B13: =_xlfn.XLOOKUP(A13,CFS_Standalone!A:A,CFS_Standalone!B:B) -> Fin Lease & Rental Charges | C13: =_xlfn.XLOOKUP(A13,CFS_Standalone!A:A,CFS_Standalone!C:C) -> 30411
A14: Profit on sale of Asset | B14: =_xlfn.XLOOKUP(A14,CFS_Standalone!A:A,CFS_Standalone!B:B) -> Profit On Sale Of Fixed Assets | C14: =_xlfn.XLOOKUP(A14,CFS_Standalone!A:A,CFS_Standalone!C:C) -> 30576
A15: Operating profit before working capital changes | B15: =_xlfn.XLOOKUP(A15,CFS_Standalone!A:A,CFS_Standalone!B:B) -> Operating Profit Before Working Capital Changes | C15: =_xlfn.XLOOKUP(A15,CFS_Standalone!A:A,CFS_Standalone!C:C) -> 30511
A16: Adjustments for:
A17: Inventories | B17: =_xlfn.XLOOKUP(A17,CFS_Standalone!A:A,CFS_Standalone!B:B) -> Inventories | C17: =_xlfn.XLOOKUP(A17,CFS_Standalone!A:A,CFS_Standalone!C:C) -> 30487
A18: Trade Receivables | B18: =_xlfn.XLOOKUP(A18,CFS_Standalone!A:A,CFS_Standalone!B:B) -> Trade And Other Receivables | C18: =_xlfn.XLOOKUP(A18,CFS_Standalone!A:A,CFS_Standalone!C:C) -> 30674
A19: Loans and advances | B19: =_xlfn.XLOOKUP(A19,CFS_Standalone!A:A,CFS_Standalone!B:B) -> Loans And Advances | C19: =_xlfn.XLOOKUP(A19,CFS_Standalone!A:A,CFS_Standalone!C:C) -> 30497
A20: Other Current Assets | B20: =_xlfn.XLOOKUP(A20,CFS_Standalone!A:A,CFS_Standalone!B:B) -> Other Current and Non Current Assets | C20: =_xlfn.XLOOKUP(A20,CFS_Standalone!A:A,CFS_Standalone!C:C) -> 30518
A21: Other Non-Current Assets | B21: =_xlfn.XLOOKUP(A21,CFS_Standalone!A:A,CFS_Standalone!B:B) -> Other Current and Non Current Assets | C21: =_xlfn.XLOOKUP(A21,CFS_Standalone!A:A,CFS_Standalone!C:C) -> 30518
A22: Trade Payables | B22: =_xlfn.XLOOKUP(A22,CFS_Standalone!A:A,CFS_Standalone!B:B) -> Trade Payables And Others | C22: =_xlfn.XLOOKUP(A22,CFS_Standalone!A:A,CFS_Standalone!C:C) -> 30675
A23: Other Current Liabilities | B23: =_xlfn.XLOOKUP(A23,CFS_Standalone!A:A,CFS_Standalone!B:B) -> Other Current and Non Current Liabilities | C23: =_xlfn.XLOOKUP(A23,CFS_Standalone!A:A,CFS_Standalone!C:C) -> 30519
A24: Short Term Provisions | B24: =_xlfn.XLOOKUP(A24,CFS_Standalone!A:A,CFS_Standalone!B:B) -> Provisions | C24: =_xlfn.XLOOKUP(A24,CFS_Standalone!A:A,CFS_Standalone!C:C) -> 30627
A25: Non-Current Provisions | B25: =_xlfn.XLOOKUP(A25,CFS_Standalone!A:A,CFS_Standalone!B:B) -> Provisions | C25: =_xlfn.XLOOKUP(A25,CFS_Standalone!A:A,CFS_Standalone!C:C) -> 30627
A26: Cash generated from operations | B26: =_xlfn.XLOOKUP(A26,CFS_Standalone!A:A,CFS_Standalone!B:B) -> Cash Generated From Operations | C26: =_xlfn.XLOOKUP(A26,CFS_Standalone!A:A,CFS_Standalone!C:C) -> 30372
A27: Direct Taxes paid (net of refunds) | B27: =_xlfn.XLOOKUP(A27,CFS_Standalone!A:A,CFS_Standalone!B:B) -> Income Tax Paid | C27: =_xlfn.XLOOKUP(A27,CFS_Standalone!A:A,CFS_Standalone!C:C) -> 30422
A28: Net cash from operating activities | B28: =_xlfn.XLOOKUP(A28,CFS_Standalone!A:A,CFS_Standalone!B:B) -> Net Cash Flow From Operating Activities | C28: =_xlfn.XLOOKUP(A28,CFS_Standalone!A:A,CFS_Standalone!C:C) -> 17538
A29: CASH FLOW FROM INVESTING ACTIVITIES : | B29: =_xlfn.XLOOKUP(A29,CFS_Standalone!A:A,CFS_Standalone!B:B) -> Lable
A30: Purchase of fixed assets including capital work-in-progress | B30: =_xlfn.XLOOKUP(A30,CFS_Standalone!A:A,CFS_Standalone!B:B) -> Purchase Of Fixed Assets (Tangible / Intangible) | C30: =_xlfn.XLOOKUP(A30,CFS_Standalone!A:A,CFS_Standalone!C:C) -> 17556
A31: Proceeds from sale of fixed assets | B31: =_xlfn.XLOOKUP(A31,CFS_Standalone!A:A,CFS_Standalone!B:B) -> Sale Of Fixed Assets (Tangible / Intangible) | C31: =_xlfn.XLOOKUP(A31,CFS_Standalone!A:A,CFS_Standalone!C:C) -> 30662
A32: Sale/(purchase) of Non Current Investments | B32: =_xlfn.XLOOKUP(A32,CFS_Standalone!A:A,CFS_Standalone!B:B) -> Sale Of Investments | C32: =_xlfn.XLOOKUP(A32,CFS_Standalone!A:A,CFS_Standalone!C:C) -> 17563
A33: Sale/(purchase) of Current Investments | B33: =_xlfn.XLOOKUP(A33,CFS_Standalone!A:A,CFS_Standalone!B:B) -> Purchase Of Investments | C33: =_xlfn.XLOOKUP(A33,CFS_Standalone!A:A,CFS_Standalone!C:C) -> 17557
A34: Interest Received | B34: Interest Received | C34: 30485
A35: Profit/(loss) on Non Current Investments | B35: =_xlfn.XLOOKUP(A35,CFS_Standalone!A:A,CFS_Standalone!B:B) -> Purchase Of Investments | C35: =_xlfn.XLOOKUP(A35,CFS_Standalone!A:A,CFS_Standalone!C:C) -> 17557
A36: Receipt of Security Deposit | B36: Others-Investing Activities | C36: 17545
A37: Dividend | B37: Dividend Received | C37: 30402
A38: Loans and Advances | B38: Cash Advances and Loans Made to Other Parties | C38: 30368
A39: Net cash from investing activities | B39: =_xlfn.XLOOKUP(A39,CFS_Standalone!A:A,CFS_Standalone!B:B) -> Net Cash Flow From Investing Activities | C39: =_xlfn.XLOOKUP(A39,CFS_Standalone!A:A,CFS_Standalone!C:C) -> 17537
A40: C CASH FLOW FROM FINANCING ACTIVITIES: | B40: Lable
...

Sheet SR_Standalone
A1: Particulars | B1: Cogencis Field | C1: Field id
A2: Segment Revenue (Sales and other operating income) | B2: Lable
A3: Information Technology | B3: As is Product Name
A4: Biofuels | B4: As is Product Name
A5: Investment | B5: As is Product Name
A6: Total Segment Revenue | B6: Total Segment Revenue | C6: 8931
A7: Segment Results | B7: Lable
A8: Information Technology | B8: As is Product Name
A9: Biofuels | B9: As is Product Name
A10: Investment | B10: As is Product Name
A11: Total Segment Results | B11: Segment Results | C11: 8919
A12: Add/(Less): Exceptional Items [net credit/ (charge)] | B12: Exceptional Item | C12: 8926
A13: Less: Finance Costs | B13: Interest Expenses | C13: 8927
A14: Add: Other Income | B14: Other Income | C14: 14859
A15: Total Profit Before Tax | B15: Profit/(Loss) from ordinary activities before tax | C15: 8911
A16: Segment Assets | B16: Lable
A17: Information Technology | B17: As is Product Name
A18: Biofuels | B18: As is Product Name
A19: Investment | B19: As is Product Name
A20: Unallocable corporate assets | B20: Unallocable Corporate Assets | C20: 18580
A21: Total Assets | B21: Total Segment Assets | C21: 18578
A22: Segment Liabilities | B22: Lable
A23: Information Technology | B23: As is Product Name
A24: Biofuels | B24: As is Product Name
A25: Investment | B25: As is Product Name
A26: Unallocable corporate liabilities | B26: Unallocable Corporate Liabilities | C26: 18581
A27: Total Liabilities | B27: Total Segment Liabilities | C27: 18579

Sheet SR_Consolidated
A1: Particulars | B1: Cogencis Field | C1: Field id
A2: Segment Revenue (Sales and Other operating income) | B2: Lable
A3: Information Technology | B3: As is Product Name
A4: Biofuels | B4: As is Product Name
A5: Investment | B5: As is Product Name
A6: Manufacturing of Racks | B6: As is Product Name
A7: Total Segment Revenue | B7: Total Segment Revenue | C7: 8931
A8: Segment Results | B8: Lable
A9: Information Technology | B9: As is Product Name
A10: Biofuels | B10: As is Product Name
A11: Investment | B11: As is Product Name
A12: Manufacturing of Racks | B12: As is Product Name
A13: Total Segment Results | B13: Segment Results | C13: 8919
A14: Add/(Less): Exceptional Items [net credit/ (charge)] | B14: Exceptional Item | C14: 8926
A15: Less: Finance Costs | B15: Interest Expenses | C15: 8927
A16: Add: Other Income | B16: Other Income | C16: 14859
A17: Intercompany Adjustment | B17: Unallocated Income (Expenses) | C17: 8929
A18: Total Profit Before Tax | B18: Profit/(Loss) from ordinary activities before tax | C18: 8911
A19: Segment Assets | B19: Lable
A20: Information Technology | B20: As is Product Name
A21: Biofuels | B21: As is Product Name
A22: Investment | B22: As is Product Name
A23: Manufacturing of Racks | B23: As is Product Name
A24: Unallocable corporate assets | B24: Unallocable Corporate Assets | C24: 18580
A25: Total Assets | B25: Total Segment Assets | C25: 18578
A26: Segment Liabilities | B26: Lable
A27: Information Technology | B27: As is Product Name
A28: Biofuels | B28: As is Product Name
A29: Investment | B29: As is Product Name
A30: Manufacturing of Racks | B30: As is Product Name
A31: Unallocable corporate liabilities | B31: Unallocable Corporate Liabilities | C31: 18581
A32: Total Liabilities | B32: Total Segment Liabilities | C32: 18579
