Workbook

Sheet P&L_Standalone
A1: Particulars | B1: Cogencis Field | C1: Field id
A2: Revenue from operations | B2: Gross Sales/Income from Operations | C2: 256
A3: Other income | B3: Miscellaneous Income | C3: 265
A4: Total income | B4: Total Income | C4: 25238
A5: Expenses
A6: Employee benefits expenses | B6: Employee Benefit Expense | C6: 238
A7: Finance costs | B7: Finance Costs | C7: 246
A8: Depreciation and amortization expenses | B8: Depreciation, Depletion and Amortisation Expense | C8: 232
A9: Other expenses | B9: Other Expenses | C9: 279
A10: Total expenses | B10: Total Expenses | C10: 320
A11: Profit before tax | B11: Profit/(Loss) From Ordinary Activities before Tax | C11: 296
A12: Tax expense | B12: Tax Expense | C12: 318
A13: Current tax | B13: Tax Expense | C13: 318
A14: Deferred tax | B14: Deferred Tax | C14: 231
A15: Total tax expenses
A16: Profit for the period / year | B16: Net Profit/(Loss) for the Period | C16: 269
A17: Other comprehensive income
A18: Items not to be reclassified to profit or loss in subsequent periods/ year
A19: Re-measurement of defined benefit plans | B19: Items that will not be reclassified to Profit or Loss | C19: 22293
A20: Income tax effect on above | B20: Income Tax related to items that will not be reclassified to Profit or Loss | C20: 22295
A21: Items to be reclassified to profit or loss in subsequent periods/ year
A22: Foreign currency translation reserve | B22: Items that will be reclassified to Profit or Loss | C22: 22294
A23: Income tax effect on above | B23: Income Tax related to items that will be reclassified to Profit or Loss | C23: 22296
A24: Total other comprehensive income | B24: Other Comprehensive Income | C24: 16484
A25: Total comprehensive income for the period /year | B25: Total Comprehensive Gain (Loss) For the Year | C25: 20019
A26: Paid up share capital (par value INR 10/- each , fully paid) | B26: Paid-Up Equity Share Capital | C26: 282
A27: Other Equity | B27: Reserve excluding Revaluation Reserves (as per Balance Sheet of Previous Accounting Year) | C27: 309
A28: Earnings per equity share (par value INR 10/- each, fully paid)
A29: Basic EPS (in INR per share) | B29: Basic EPS | C29: 222
A30: Diluted EPS (in INR per share) | B30: Diluted EPS | C30: 234

Sheet P&L_Consolidated
A1: Particulars | B1: Cogencis Field | C1: Field id
A2: Revenue from operations | B2: =VLOOKUP(A2,'P&L_Standalone'!A2:C31,2,0) -> Gross Sales/Income from Operations | C2: =VLOOKUP(A2,'P&L_Standalone'!A2:C31,3,0) -> 256
A3: Other income | B3: =VLOOKUP(A3,'P&L_Standalone'!A3:C32,2,0) -> Miscellaneous Income | C3: =VLOOKUP(A3,'P&L_Standalone'!A3:C32,3,0) -> 265
A4: Total income | B4: =VLOOKUP(A4,'P&L_Standalone'!A4:C33,2,0) -> Total Income | C4: =VLOOKUP(A4,'P&L_Standalone'!A4:C33,3,0) -> 25238
A5: Expenses
A6: Employee benefits expenses | B6: =VLOOKUP(A6,'P&L_Standalone'!A6:C35,2,0) -> Employee Benefit Expense | C6: =VLOOKUP(A6,'P&L_Standalone'!A6:C35,3,0) -> 238
A7: Finance costs | B7: =VLOOKUP(A7,'P&L_Standalone'!A7:C36,2,0) -> Finance Costs | C7: =VLOOKUP(A7,'P&L_Standalone'!A7:C36,3,0) -> 246
A8: Depreciation and amortization expenses | B8: =VLOOKUP(A8,'P&L_Standalone'!A8:C37,2,0) -> Depreciation, Depletion and Amortisation Expense | C8: =VLOOKUP(A8,'P&L_Standalone'!A8:C37,3,0) -> 232
A9: Other expenses | B9: =VLOOKUP(A9,'P&L_Standalone'!A9:C38,2,0) -> Other Expenses | C9: =VLOOKUP(A9,'P&L_Standalone'!A9:C38,3,0) -> 279
A10: Total expenses | B10: =VLOOKUP(A10,'P&L_Standalone'!A10:C39,2,0) -> Total Expenses | C10: =VLOOKUP(A10,'P&L_Standalone'!A10:C39,3,0) -> 320
A11: Profit before tax | B11: =VLOOKUP(A11,'P&L_Standalone'!A11:C40,2,0) -> Profit/(Loss) From Ordinary Activities before Tax | C11: =VLOOKUP(A11,'P&L_Standalone'!A11:C40,3,0) -> 296
A12: Tax expense | B12: =VLOOKUP(A12,'P&L_Standalone'!A12:C41,2,0) -> Tax Expense | C12: =VLOOKUP(A12,'P&L_Standalone'!A12:C41,3,0) -> 318
A13: Current tax | B13: =VLOOKUP(A13,'P&L_Standalone'!A13:C42,2,0) -> Tax Expense | C13: =VLOOKUP(A13,'P&L_Standalone'!A13:C42,3,0) -> 318
A14: Deferred tax | B14: =VLOOKUP(A14,'P&L_Standalone'!A14:C43,2,0) -> Deferred Tax | C14: =VLOOKUP(A14,'P&L_Standalone'!A14:C43,3,0) -> 231
A15: Total tax expenses
A16: Profit for the period / year | B16: =VLOOKUP(A16,'P&L_Standalone'!A16:C45,2,0) -> Net Profit/(Loss) for the Period | C16: =VLOOKUP(A16,'P&L_Standalone'!A16:C45,3,0) -> 269
A17: Other comprehensive income
A18: Items not to be reclassified to profit or loss in subsequent periods/ year
A19: Re-measurement of defined benefit plans | B19: =VLOOKUP(A19,'P&L_Standalone'!A19:C48,2,0) -> Items that will not be reclassified to Profit or Loss | C19: =VLOOKUP(A19,'P&L_Standalone'!A19:C48,3,0) -> 22293
A20: Income tax effect on above | B20: =VLOOKUP(A20,'P&L_Standalone'!A20:C49,2,0) -> Income Tax related to items that will not be reclassified to Profit or Loss | C20: =VLOOKUP(A20,'P&L_Standalone'!A20:C49,3,0) -> 22295
A21: Items to be reclassified to profit or loss in subsequent periods/ year
A22: Foreign currency translation reserve | B22: =VLOOKUP(A22,'P&L_Standalone'!A22:C51,2,0) -> Items that will be reclassified to Profit or Loss | C22: =VLOOKUP(A22,'P&L_Standalone'!A22:C51,3,0) -> 22294
A23: Income tax effect on above | B23: =VLOOKUP(A23,'P&L_Standalone'!A23:C52,2,0) -> Income Tax related to items that will be reclassified to Profit or Loss | C23: =VLOOKUP(A23,'P&L_Standalone'!A23:C52,3,0) -> 22296
A24: Total other comprehensive income | B24: =VLOOKUP(A24,'P&L_Standalone'!A24:C53,2,0) -> Other Comprehensive Income | C24: =VLOOKUP(A24,'P&L_Standalone'!A24:C53,3,0) -> 16484
A25: Total comprehensive income for the period /year | B25: =VLOOKUP(A25,'P&L_Standalone'!A25:C54,2,0) -> Total Comprehensive Gain (Loss) For the Year | C25: =VLOOKUP(A25,'P&L_Standalone'!A25:C54,3,0) -> 20019
A26: Paid up share capital (par value INR 10/- each , fully paid) | B26: =VLOOKUP(A26,'P&L_Standalone'!A26:C55,2,0) -> Paid-Up Equity Share Capital | C26: =VLOOKUP(A26,'P&L_Standalone'!A26:C55,3,0) -> 282
A27: Other Equity | B27: =VLOOKUP(A27,'P&L_Standalone'!A27:C56,2,0) -> Reserve excluding Revaluation Reserves (as per Balance Sheet of Previous Accounting Year) | C27: =VLOOKUP(A27,'P&L_Standalone'!A27:C56,3,0) -> 309
A28: Earnings per equity share (par value INR 10/- each, fully paid)
A29: Basic EPS (in INR per share) | B29: =VLOOKUP(A29,'P&L_Standalone'!A29:C58,2,0) -> Basic EPS | C29: =VLOOKUP(A29,'P&L_Standalone'!A29:C58,3,0) -> 222
A30: Diluted EPS (in INR per share) | B30: =VLOOKUP(A30,'P&L_Standalone'!A30:C59,2,0) -> Diluted EPS | C30: =VLOOKUP(A30,'P&L_Standalone'!A30:C59,3,0) -> 234

Sheet BS_Standalone
A1: Particulars | B1: Cogencis Field | C1: Field id
A2: ASSETS
A3: Non-current assets
A4: property, plant and equipment | B4: Property, Plant & Equipment | C4: 20222
A5: Right-of-use assets | B5: Right-of-use asset | C5: 30342
A6: Other Intangible Assets | B6: Other Intangible Assets | C6: 20221
A7: Intangible Assets under development | B7: Intangible assets under development | C7: 13736
A8: Financial assets
A9: Investments | B9: Non-Current Investments | C9: 13748
A10: Other financial assets | B10: Other Non-Current Financial Assets | C10: 20216
A11: Non-current tax assets (net) | B11: Income Tax assets (net) | C11: 20215
A12: Other non-current Assets | B12: Other Non-Current Assets | C12: 13753
A13: Total non-Current Assets | B13: Total Non-Current Assets | C13: 13777
A14: Current assets
A15: Financial assets
A16: Trade aeceivables | B16: Trade Receivables | C16: 13780
A17: Unbilled receivables | B17: Unbilled Revenue | C17: 20232
A18: Cash and cash equivalents | B18: Cash And Cash Equivalents | C18: 13722
A19: Bank balances other than above | B19: Bank balance other than cash and cash equivalents | C19: 29788
A20: Loans | B20: Loans, Current | C20: 20230
A21: Other current assets | B21: Other Current Assets | C21: 13750
A22: Total current assets | B22: Total Current Assets | C22: 13774
A23: Total Assets | B23: Total Assets | C23: 13771
A24: EQUITY & LIABILITIES
A25: Equity
A26: Equity share capital | B26: Share Capital | C26: 13765
A27: Other equity | B27: Reserves And Surplus/Other Equity | C27: 13762
A28: Total equity | B28: Total Share Holder's Funds | C28: 13773
A29: Liabilities
A30: Non-current liabilities
A31: Financial liabilities
A32: Lease liabilities | B32: Lease liabilities | C32: 30340
A33: Provisions | B33: Long-Term Provisions | C33: 13743
A34: Deferred tax liabilities (net) | B34: Deferred Tax Liability (Net) | C34: 13727
A35: Total non-current liabilities | B35: Total Non-Current Liabilities | C35: 13778
A36: Current liabilities
A37: Financial liabilities
A38: Borrowings | B38: Borrowings | C38: 20209
A39: Lease liabilities | B39: Lease liabilities | C39: 25716
A40: Trade payables
...

Sheet BS_Consolidated
A1: Particulars | B1: Cogencis Field | C1: Field id
A2: ASSETS
A3: Non-current assets
A4: Property, plant and equipment | B4: Property, Plant & Equipment | C4: 20222
A5: Right-of-use assets | B5: Right-of-use asset | C5: 30342
A6: Goodwill | B6: Goodwill On Consolidation | C6: 13734
A7: Other intangible assets | B7: Other Intangible Assets | C7: 20221
A8: Intangible assets under development | B8: Intangible Assets Under Development | C8: 13736
A9: Financial assets
A10: Other financial assets | B10: Other Non-Current Financial Assets | C10: 20216
A11: Non-current tax assets (net) | B11: Income Tax assets (net) | C11: 20215
A12: Other non-current Assets | B12: Other Non-Current Assets | C12: 13753
A13: Total non-Current Assets | B13: Total Non-Current Assets | C13: 13777
A14: Current assets
A15: Financial assets
A16: Trade receivables | B16: Trade Receivables | C16: 13780
A17: Unbilled receivables | B17: Unbilled Revenue | C17: 20232
A18: Cash and cash equivalents | B18: Cash And Cash Equivalents | C18: 13722
A19: Bank balances other than above | B19: Bank balance other than cash and cash equivalents | C19: 29788
A20: Loans | B20: Loans, Current | C20: 20230
A21: Other current assets | B21: Other Current Assets | C21: 13750
A22: Total current assets | B22: Total Current Assets | C22: 13774
A23: Total assets | B23: Total Assets | C23: 13771
A24: EQUITY & LIABILITIES
A25: Equity
A26: Equity share capital | B26: Share Capital | C26: 13765
A27: Other equity | B27: Reserves And Surplus/Other Equity | C27: 13762
A28: Total equity | B28: Total Share Holder's Funds | C28: 13773
A29: Liabilities
A30: Non-current liabilities
A31: Financial liabilities
A32: Lease liabilities | B32: Lease liabilities | C32: 30340
A33: Provisions | B33: Long-Term Provisions | C33: 13743
A34: Deferred tax liabilities (net) | B34: Deferred Tax Liability (Net) | C34: 13727
A35: Total non-current liabilities | B35: Total Non-Current Liabilities | C35: 13778
A36: Current liabilities
A37: Financial liabilities
A38: Borrowings | B38: Borrowings | C38: 20209
A39: Lease liabilities | B39: Lease liabilities | C39: 25716
A40: Trade payables
...

Sheet CFS_Standalone
A1: Particulars | B1: Cogencis Field | C1: Field id
A2: Cash flow from operating activities
A3: Profit before tax | B3: Net Profit Before Tax And Exceptional Item | C3: 17539
A4: Adjustments to reconcile profits before tax to net cash flows:
A5: Depreciation and Amortization expenses | B5: Depreciation and Amortisation Expense | C5: 30399
A6: Finance costs | B6: Interest Expense | C6: 30479
A7: Interest income | B7: Interest Income | C7: 30481
A8: Share based payments to employees | B8: Others-Before Working Capital Changes | C8: 17542
A9: Rental income | B9: Fin Lease & Rental Charges | C9: 30411
A10: Provision for compensated absences | B10: Provision For Gratuity,Leave Encashment And Pensions | C10: 30632
A11: Provision for gratuity | B11: Provision For Gratuity,Leave Encashment And Pensions | C11: 30632
A12: Unrealised foreign exchange (gain) | B12: Foreign Exchange Gain / Loss | C12: 30414
A13: (Profit) on sale of assets | B13: Profit On Sale Of Fixed Assets | C13: 30576
A14: Operating profit before working capital changes | B14: Operating Profit Before Working Capital Changes | C14: 30511
A15: Changes in assets and liabilities
A16: (Increase) / Decrease in trade receivables and unbilled revenue | B16: Trade And Other Receivables | C16: 30674
A17: Increase in other financial assets and other assets | B17: Adjustments for other financial assets, non-current | C17: 30452
A18: Increase/(Decrease) in trade payables | B18: Trade Payables And Others | C18: 30675
A19: Decrease in other financial liabilities, other liabilities and provisions | B19: Adjustments for other financial liabilities, non-current | C19: 30454
A20: Income tax paid | B20: Income Tax Paid | C20: 30422
A21: Net cash from operating activities | B21: Net Cash Flow From Operating Activities | C21: 17538
A22: Cash flow from investing activities
A23: Purchase of property, plant and equipment | B23: Purchase Of Fixed Assets (Tangible / Intangible) | C23: 17556
A24: Sale of property, plant and equipment | B24: Sale Of Fixed Assets (Tangible / Intangible) | C24: 30662
A25: Closure of right-of-use assets | B25: Others-Investing Activities | C25: 17545
A26: Intangible assets under development | B26: Purchase of intangible assets under development | C26: 30473
A27: Receipt of security deposit | B27: Others-Investing Activities | C27: 17545
A28: Acquisition of subsidiary | B28: Acquisition Of Companies | C28: 17772
A29: Capital advance paid of purchase of land | B29: Purchase Of Fixed Assets (Tangible / Intangible) | C29: 17556
A30: Interest received | B30: Interest Received | C30: 30485
A31: Investment in bank deposits, net | B31: Fixed Deposits | C31: 30412
A32: Net cash (used) in from investing activities | B32: Net Cash Flow From Investing Activities | C32: 17537
A33: Cash flow from financial activities
A34: Proceeds from borrowing (net) | B34: Proceeds From Long Term Borrowings | C34: 17554
A35: Shares issued on exercise of employee stock options | B35: Proceeds From Issue Of Equity Shares (Inclu Share Premium) | C35: 17553
A36: Repayment of borrowings | B36: Repayment Of Long Term Borrowings | C36: 30658
A37: Repayment of lease liabilities | B37: Payments of lease liabilities | C37: 30467
A38: Interest Paid | B38: Interest Paid | C38: 30484
A39: Net cash from / (used in ) financing activities | B39: Net Cash Flow From Financing Activities | C39: 17536
A40: Net increase in cash and cash equivalents | B40: Net Increase in Cash and Cash Equivalents | C40: 17541
...

Sheet CFS_Consolidated
A1: Particulars | B1: Cogencis Field | C1: Field id
A2: Cash flow from operating activities
A3: Profit before tax | B3: Net Profit Before Tax And Exceptional Item | C3: 17539
A4: Adjustments to reconcile profits before tax to net cash flows:
A5: Depreciation and Amortization expenses | B5: Depreciation and Amortisation Expense | C5: 30399
A6: Finance costs | B6: Interest Expense | C6: 30479
A7: Interest income | B7: Interest Income | C7: 30481
A8: Share based payments to employees | B8: Others-Before Working Capital Changes | C8: 17542
A9: Rental income | B9: Fin Lease & Rental Charges | C9: 30411
A10: Provision for compensated absences | B10: Provision For Gratuity,Leave Encashment And Pensions | C10: 30632
A11: Provision for gratuity | B11: Provision For Gratuity,Leave Encashment And Pensions | C11: 30632
A12: Unrealised foreign exchange (gain) | B12: Foreign Exchange Gain / Loss | C12: 30414
A13: (Profit) on sale of assets | B13: Profit On Sale Of Fixed Assets | C13: 30576
A14: Operating profit before working capital changes | B14: Operating Profit Before Working Capital Changes | C14: 30511
A15: Changes in assets and liabilities
A16: (Increase) / Decrease in trade receivables and unbilled revenue | B16: Trade And Other Receivables | C16: 30674
A17: Increase in other financial assets and other assets | B17: Adjustments for other financial assets, non-current | C17: 30452
A18: Decrease in trade payables | B18: Trade Payables And Others | C18: 30675
A19: Decrease in other financial liabilities, other liabilities and provisions | B19: Adjustments for other financial liabilities, non-current | C19: 30454
A20: Income tax paid | B20: Income Tax Paid | C20: 30422
A21: Net cash from operating activities | B21: Net Cash Flow From Operating Activities | C21: 17538
A22: Cash flow from investing activities
A23: Purchase of property, plant and equipment | B23: Purchase Of Fixed Assets (Tangible / Intangible) | C23: 17556
A24: Sale of property, plant and equipment | B24: Sale Of Fixed Assets (Tangible / Intangible) | C24: 30662
A25: Closure of Right-of-use assets | B25: Others-Investing Activities | C25: 17545
A26: Intangible assets under development | B26: Purchase of intangible assets under development | C26: 30473
A27: Receipt of security deposit | B27: Others-Investing Activities | C27: 17545
A28: Rental income received | B28: Others-Investing Activities | C28: 17545
A29: Acquisition of subsidiary, net of cash acquired | B29: Acquisition Of Companies | C29: 17772
A30: Capital advance paid of purchase of land | B30: Purchase Of Fixed Assets (Tangible / Intangible) | C30: 17556
A31: Interest received | B31: Interest Received | C31: 30485
A32: Investment in bank deposits, net | B32: Fixed Deposits | C32: 30412
A33: Net cash (used) in from investing activities | B33: Net Cash Flow From Investing Activities | C33: 17537
A34: Cash flow from financial activities
A35: Proceeds from borrowing (net) | B35: Proceeds From Long Term Borrowings | C35: 17554
A36: Shares issued on exercise of employee stock options | B36: Proceeds From Issue Of Equity Shares (Inclu Share Premium) | C36: 17553
A37: Repayment of lease liabilities | B37: Payments of lease liabilities | C37: 30467
A38: Repayment of borrowings | B38: Repayment Of Long Term Borrowings | C38: 30658
A39: Interest Paid | B39: Interest Paid | C39: 30484
A40: Net cash from / (used in ) financing activities | B40: Net Cash Flow From Financing Activities | C40: 17536
...

Sheet SR_Standalone
A1: Particulars | B1: Cogencis Field | C1: Field id

Sheet SR_Consolidated
A1: Particulars | B1: Cogencis Field | C1: Field id | D1: Segment Revenue Data Not Captured. (Refer Page No.8)
