Workbook

Sheet P&L_Standalone
A1: Particulars | B1: Cogencis Field | C1: Field id
A2: INCOMES
A3: Revenue from Operations (Net of Taxes) | B3: Gross Sales/Income from Operations | C3: 256
A4: Other Income | B4: Miscellaneous Income | C4: 265
A5: Total Income | B5: Total Income | C5: 25238
A6: EXPENSES
A7: Cost of Materials consumed | B7: Cost of Materials Consumed | C7: 230
A8: Purchase of Stock in Trade | B8: Purchase of Stock-in-Trade | C8: 307
A9: Changes of Inventories of Finished Goods, Work in Progress Work in Trade | B9: Changes in Inventories of Finished Goods, Work-In-Progress and Stock-In-Trade | C9: 227
A10: Employees Cost | B10: Employee Benefit Expense | C10: 238
A11: Finance Cost | B11: Finance Costs | C11: 246
A12: Depreciation and Amortisation Expenses | B12: Depreciation, Depletion and Amortisation Expense | C12: 232
A13: Other Expenses | B13: Other Expenses | C13: 279
A14: TOTAL EXPENSES | B14: Total Expenses | C14: 320
A15: Profit/(Loss) before Exceptional Items and Tax | B15: Profit/(Loss) from Ordinary Activities after Finance Costs but before Exceptional Items | C15: 294
A16: Exceptional Items& Extraordinary Item | B16: Other Exceptional Items | C16: 278
A17: Profit/ (Loss) Before Tax | B17: Profit/(Loss) From Ordinary Activities before Tax | C17: 296
A18: TAX EXPENSES
A19: Current Tax | B19: Tax Expense | C19: 318
A20: Deferred Tax | B20: Deferred Tax | C20: 231
A21: Short/(excess) provision of income tax | B21: Tax Expense | C21: 318
A22: Total Tax Expenses
A23: NET PROFIT AFTER TAX FROM BUSINESS | B23: Net Profit/(Loss) from Ordinary Activities after Tax | C23: 270
A24: OPERATIONS
A25: Other Comprehensive Income
A26: Items That will not be reclassified to profit or loss | B26: Items that will not be reclassified to Profit or Loss | C26: 22293
A27: Items That will be reclassified to profit or loss | B27: Items that will be reclassified to Profit or Loss | C27: 22294
A28: Total Comprehensive Income | B28: Total Comprehensive Gain (Loss) For the Year | C28: 20019
A29: Paid up Equity Share Capital (Amount in lacs) | B29: Paid-Up Equity Share Capital | C29: 282
A30: Face Value per share | B30: Face Value | C30: 245
A31: Other Equity Capital (Reserve & Surplus) | B31: Reserve excluding Revaluation Reserves (as per Balance Sheet of Previous Accounting Year) | C31: 309
A32: Earning Per Share (In Rupees) from
A33: Continuing Operations (Not Annualized).
A34: Basic | B34: Basic EPS | C34: 222
A35: Diluted | B35: Diluted EPS | C35: 234
A36: Income from Discontinuing Operations | D36: Ignore this field
A37: Profit /(Loss) from Discontinuing Operations | D37: Ignore this field
A38: Profit/(loss) for the period After Adjustment of discontinuing Operations with Current Operations | D38: Ignore this field

Sheet P&L_Consolidated
A1: Particulars | B1: Cogencis Field | C1: Field id
A2: INCOMES
A3: Revenue from Operations (Net of Taxes) | B3: =VLOOKUP(A3,'P&L_Standalone'!A:C,2,0) -> Gross Sales/Income from Operations | C3: =VLOOKUP(A3,'P&L_Standalone'!A:C,3,0) -> 256
A4: Other Income | B4: =VLOOKUP(A4,'P&L_Standalone'!A:C,2,0) -> Miscellaneous Income | C4: =VLOOKUP(A4,'P&L_Standalone'!A:C,3,0) -> 265
A5: Total Income | B5: =VLOOKUP(A5,'P&L_Standalone'!A:C,2,0) -> Total Income | C5: =VLOOKUP(A5,'P&L_Standalone'!A:C,3,0) -> 25238
A6: EXPENSES
A7: Cost of Materials consumed | B7: =VLOOKUP(A7,'P&L_Standalone'!A:C,2,0) -> Cost of Materials Consumed | C7: =VLOOKUP(A7,'P&L_Standalone'!A:C,3,0) -> 230
A8: Purchase of Stock in Trade. | B8: Purchase of Stock-in-Trade | C8: 307
A9: Changes of Inventories of Finished Goods, Work in Progress Work in Trade | B9: =VLOOKUP(A9,'P&L_Standalone'!A:C,2,0) -> Changes in Inventories of Finished Goods, Work-In-Progress and Stock-In-Trade | C9: =VLOOKUP(A9,'P&L_Standalone'!A:C,3,0) -> 227
A10: Employees Cost | B10: =VLOOKUP(A10,'P&L_Standalone'!A:C,2,0) -> Employee Benefit Expense | C10: =VLOOKUP(A10,'P&L_Standalone'!A:C,3,0) -> 238
A11: Finance Cost | B11: =VLOOKUP(A11,'P&L_Standalone'!A:C,2,0) -> Finance Costs | C11: =VLOOKUP(A11,'P&L_Standalone'!A:C,3,0) -> 246
A12: Depreciation and Amortisation Expenses | B12: =VLOOKUP(A12,'P&L_Standalone'!A:C,2,0) -> Depreciation, Depletion and Amortisation Expense | C12: =VLOOKUP(A12,'P&L_Standalone'!A:C,3,0) -> 232
A13: Other Expenses | B13: =VLOOKUP(A13,'P&L_Standalone'!A:C,2,0) -> Other Expenses | C13: =VLOOKUP(A13,'P&L_Standalone'!A:C,3,0) -> 279
A14: TOTAL EXPENSES | B14: =VLOOKUP(A14,'P&L_Standalone'!A:C,2,0) -> Total Expenses | C14: =VLOOKUP(A14,'P&L_Standalone'!A:C,3,0) -> 320
A15: Profit/(Loss) before Exceptional Items and Tax | B15: =VLOOKUP(A15,'P&L_Standalone'!A:C,2,0) -> Profit/(Loss) from Ordinary Activities after Finance Costs but before Exceptional Items | C15: =VLOOKUP(A15,'P&L_Standalone'!A:C,3,0) -> 294
A16: Exceptional Items& Extraordinary Item | B16: =VLOOKUP(A16,'P&L_Standalone'!A:C,2,0) -> Other Exceptional Items | C16: =VLOOKUP(A16,'P&L_Standalone'!A:C,3,0) -> 278
A17: Share of Net Profit/Loss in Associate | B17: Share of Profit/(loss) of associates and Joint Ventures before ebt | C17: 25236
A18: Profit/ (Loss) Before Tax | B18: =VLOOKUP(A18,'P&L_Standalone'!A:C,2,0) -> Profit/(Loss) From Ordinary Activities before Tax | C18: =VLOOKUP(A18,'P&L_Standalone'!A:C,3,0) -> 296
A19: TAX EXPENSES
A20: Current Tax | B20: =VLOOKUP(A20,'P&L_Standalone'!A:C,2,0) -> Tax Expense | C20: =VLOOKUP(A20,'P&L_Standalone'!A:C,3,0) -> 318
A21: Deferred Tax | B21: =VLOOKUP(A21,'P&L_Standalone'!A:C,2,0) -> Deferred Tax | C21: =VLOOKUP(A21,'P&L_Standalone'!A:C,3,0) -> 231
A22: Short/(excess) provision of income tax | B22: =VLOOKUP(A22,'P&L_Standalone'!A:C,2,0) -> Tax Expense | C22: =VLOOKUP(A22,'P&L_Standalone'!A:C,3,0) -> 318
A23: Total Tax Expenses
A24: NET PROFIT AFTER TAX FROM BUSINESS OPERATIONS | B24: Net Profit/(Loss) for the Period | C24: 269
A25: Other Comprehensive Income
A26: Items That will not be reclassified to profit or loss | B26: =VLOOKUP(A26,'P&L_Standalone'!A:C,2,0) -> Items that will not be reclassified to Profit or Loss | C26: =VLOOKUP(A26,'P&L_Standalone'!A:C,3,0) -> 22293
A27: Items That will be reclassified to profit or loss | B27: =VLOOKUP(A27,'P&L_Standalone'!A:C,2,0) -> Items that will be reclassified to Profit or Loss | C27: =VLOOKUP(A27,'P&L_Standalone'!A:C,3,0) -> 22294
A28: Total Comprehensive Income | B28: =VLOOKUP(A28,'P&L_Standalone'!A:C,2,0) -> Total Comprehensive Gain (Loss) For the Year | C28: =VLOOKUP(A28,'P&L_Standalone'!A:C,3,0) -> 20019
A29: Paid up Equity Share Capital (Amount in lacs) | B29: =VLOOKUP(A29,'P&L_Standalone'!A:C,2,0) -> Paid-Up Equity Share Capital | C29: =VLOOKUP(A29,'P&L_Standalone'!A:C,3,0) -> 282
A30: Face Value per share | B30: Face Value | C30: 245
A31: Other Equity Capital (Reserve & Surplus) | B31: =VLOOKUP(A31,'P&L_Standalone'!A:C,2,0) -> Reserve excluding Revaluation Reserves (as per Balance Sheet of Previous Accounting Year) | C31: =VLOOKUP(A31,'P&L_Standalone'!A:C,3,0) -> 309
A32: Earning Per Share (In Rupees) from
A33: Continuing Operations (Not Annualized).
A34: Basic | B34: =VLOOKUP(A34,'P&L_Standalone'!A:C,2,0) -> Basic EPS | C34: =VLOOKUP(A34,'P&L_Standalone'!A:C,3,0) -> 222
A35: Diluted | B35: =VLOOKUP(A35,'P&L_Standalone'!A:C,2,0) -> Diluted EPS | C35: =VLOOKUP(A35,'P&L_Standalone'!A:C,3,0) -> 234
A36: Income from Discontinuing Operations | D36: Ignore this field
A37: Profit /(Loss) from Discontinuing Operations | D37: Ignore this field
A38: Profit/(loss) for the period After Adjustment of discontinuing Operations with Current Operations | D38: Ignore this field

Sheet BS_Standalone
A1: Particulars | B1: Cogencis Field | C1: Field id
A2: ASSETS
A3: Non-current assets
A4: Property,Plant and Equipment | B4: Property, Plant & Equipment | C4: 20222
A5: Capital work-in-progress | B5: Capital Work-In-Progress | C5: 13720
A6: Investment property | B6: Investment Property | C6: 25736
A7: Goodwill | B7: Goodwill | C7: 20220
A8: Other intangible assets | B8: Other Intangible Assets | C8: 20221
A9: Intangible assets under development | B9: Intangible assets under development | C9: 13736
A10: Biological Assets other than bearer plants | B10: Biological Assets other than bearer plants | C10: 20219
A11: Financial assets
A12: Investments | B12: Non-Current Investments | C12: 13748
A13: Trade receivables | B13: Trade Receivables | C13: 20218
A14: Loans | B14: Loans Non-Current | C14: 20217
A15: Other financial assets | B15: Other Non-Current Financial Assets | C15: 20216
A16: Deferred tax assets (net) | B16: Deferred Tax Assets (Net) | C16: 13726
A17: Other non-current assets | B17: Other Non-Current Assets | C17: 13753
A18: Current assets
A19: Inventories | B19: Inventories | C19: 13737
A20: Financial Assets
A21: Investments | B21: Current Investments | C21: 13724
A22: Trade receivables | B22: Trade Receivables | C22: 13780
A23: Cash and cash equivalents | B23: Cash And Cash Equivalents | C23: 13722
A24: Other Bank balances | B24: Bank balance other than cash and cash equivalents | C24: 29788
A25: Loans | B25: Loans, Current | C25: 20230
A26: Other financial assets | B26: Other Current Financial Assets | C26: 20231
A27: Current tax assets (Net) | B27: Current Tax Assets (Net) | C27: 20228
A28: Other current assets | B28: Other Current Assets | C28: 13750
A29: Total Assets | B29: Total Assets | C29: 13771
A30: EQUITY AND LIABILITIES
A31: Equity
A32: Equity Share capital | B32: Share Capital | C32: 13765
A33: Other Equity | B33: Reserves And Surplus/Other Equity | C33: 13762
A34: Liabilities
A35: Non-current liabilities
A36: Financial Liabilities
A37: Borrowings | B37: Borrowings | C37: 20223
A38: Trade payables
A39: Total outstanding due of
A40: Micro enterprises and small enterprises | B40: Trade Payables | C40: 20227
...

Sheet BS_Consolidated
A1: Particulars | B1: Cogencis Field | C1: Field id
A2: ASSETS
A3: Non-current assets
A4: Property, Plant and Equipment | B4: Property, Plant & Equipment | C4: 20222
A5: Capital work-in-progress | B5: Capital Work-In-Progress | C5: 13720
A6: Investment property | B6: Investment Property | C6: 25736
A7: Goodwill | B7: Goodwill On Consolidation | C7: 13734
A8: Other intangible assets | B8: Other Intangible Assets | C8: 20221
A9: Intangible assets under development | B9: Intangible assets under development | C9: 13736
A10: Biological Assets other than bearer plants | B10: Biological Assets other than bearer plants | C10: 20219
A11: Financial assets
A12: Investments | B12: Non-Current Investments | C12: 13748
A13: Trade receivables | B13: Trade Receivables | C13: 20218
A14: Loans | B14: Loans Non-Current | C14: 20217
A15: Other financial assets | B15: Other Non-Current Financial Assets | C15: 20216
A16: Deferred tax assets (net) | B16: Deferred Tax Assets (Net) | C16: 13726
A17: Other non-current assets | B17: Other Non-Current Assets | C17: 13753
A18: Current assets
A19: Inventories | B19: Inventories | C19: 13737
A20: Financial Assets
A21: Investments | B21: Current Investments | C21: 13724
A22: Trade receivables | B22: Trade Receivables | C22: 13780
A23: Cash and cash equivalents | B23: Cash And Cash Equivalents | C23: 13722
A24: Other Bank balances | B24: Bank balance other than cash and cash equivalents | C24: 29788
A25: Loans | B25: Loans, Current | C25: 20230
A26: Other financial assets | B26: Other Current Financial Assets | C26: 20231
A27: Current tax assets (Net) | B27: Current Tax Assets (Net) | C27: 20228
A28: Other current assets | B28: Other Current Assets | C28: 13750
A29: Total Assets | B29: Total Assets | C29: 13771
A30: EQUITY AND LIABILITIES
A31: Equity
A32: Equity Share capital | B32: Share Capital | C32: 13765
A33: Other Equity | B33: Reserves And Surplus/Other Equity | C33: 13762
A34: Non-Controlling Interest | B34: Minority Interest | C34: 13744
A35: Liabilities
A36: Non-current liabilities
A37: Financial Liabilities
A38: Borrowings | B38: Borrowings | C38: 20223
A39: Trade payables
A40: Total outstanding due of
...

Sheet CFS_Standalone
A1: Particulars | B1: Cogencis Field | C1: Field id
A2: CASH FLOW FROM OPERATING ACTIVITIES
A3: Net Profit/(Loss) After Tax | B3: Net Profit Before Tax And Exceptional Item | C3: 17539
A4: Add/(Less) : Adjustments for non cash items
A5: Depreciation | B5: Depreciation and Amortisation Expense | C5: 30399
A6: Provision for tax | B6: Others-Before Working Capital Changes | C6: 17542
A7: Add/(Less) : Other adjustments
A8: Interest Income | B8: Interest Income | C8: 30481
A9: Operating Profit before Working Capital Changes | B9: Operating Profit Before Working Capital Changes | C9: 30511
A10: Add/(Less) : Adjustments for working capital changes
A11: Changes in Current Assets
A12: Decrease / (Increase) in Inventory | B12: Inventories | C12: 30487
A13: Decrease / (Increase) in Trade Receivables | B13: Trade And Other Receivables | C13: 30674
A14: Decrease / (Increase) in Other bank balances | B14: Other Current and Non Current Assets | C14: 30518
A15: Decrease / (Increase) in loans and other financial assets | B15: Loans And Advances | C15: 30497
A16: Decrease / (Increase) in Current tax assets | B16: Other Current and Non Current Assets | C16: 30518
A17: Decrease / (Increase) in Other current assets | B17: Other Current and Non Current Assets | C17: 30518
A18: Changes in Current Liabilities
A19: (Decrease) / Increase in Trade Payables | B19: Trade Payables And Others | C19: 30675
A20: (Decrease) / Increase in Other Current Liabilities | B20: Other Current and Non Current Liabilities | C20: 30519
A21: (Decrease) / Increase in Other Financial Liabilities | B21: Adjustments for other financial liabilities, non-current | C21: 30454
A22: (Decrease) / Increase in Provisions | B22: Provisions | C22: 30627
A23: Cash Generated from Operation | B23: Net Cash Flow From Operating Activities | C23: 17538
A24: Less: Income Tax Paid | B24: Income Tax Paid | C24: 30422
A25: Net cash generated from operations : | B25: Cash Generated From Operations | C25: 30372
A26: NET CASH FLOW FROM INVESTING ACTIVITIES
A27: Purchase of property, plant & equipment/intangible assets | B27: Purchase Of Fixed Assets (Tangible / Intangible) | C27: 17556
A28: Sale of property, plant & equipment | B28: Sale Of Fixed Assets (Tangible / Intangible) | C28: 30662
A29: Change in other non current assets | B29: Others-Investing Activities | C29: 17545
A30: Investment in Shares of Subisdiary | B30: Investment In Subsidiaries | C30: 30491
A31: Investment in Shares (Net) | B31: Purchase Of Investments | C31: 17557
A32: Interest Income | B32: Interest Received | C32: 30485
A33: Net cash used in investing activities : | B33: Net Cash Flow From Investing Activities | C33: 17537
A34: CASH FLOW FROM FINANCING ACTIVITIES
A35: Proceeds from issue of shares | B35: Proceeds From Issue Of Equity Shares (Inclu Share Premium) | C35: 17553
A36: Changes in non current borrowings | B36: Proceeds From Long Term Borrowings | C36: 17554
A37: Interest and Other Borrowing Cost Paid | B37: Interest Paid | C37: 30484
A38: Net cash generated from financing activities : | B38: Net Cash Flow From Financing Activities | C38: 17536
A39: NET INCREASE/(DECREASE) IN CASH AND CASH EQUIVALENTS | B39: Net Increase in Cash and Cash Equivalents | C39: 17541
A40: CASH AND CASH EQUIVALENTS AS AT BEGINNING OF THE YEAR | B40: Cash and Cash Equivalents at the Beginning of the Year | C40: 17519
...

Sheet CFS_Consolidated
A1: Particulars | B1: Cogencis Field | C1: Field id
A2: CASH FLOW FROM OPERATING ACTIVITIES
A3: Net Profit/(Loss) before Tax | B3: Net Profit Before Tax And Exceptional Item | C3: 17539
A4: Add/(Less) : Adjustments for non cash items
A5: Depreciation | B5: Depreciation and Amortisation Expense | C5: 30399
A6: Provision for tax | B6: Others-Before Working Capital Changes | C6: 17542
A7: Add/(Less) : Other adjustments
A8: Interest Income | B8: Interest Income | C8: 30481
A9: Operating Profit before Working Capital Changes | B9: Operating Profit Before Working Capital Changes | C9: 30511
A10: Add/(Less) : Adjustments for working capital changes
A11: Changes in Current Assets
A12: Decrease / (Increase) in Inventory | B12: Inventories | C12: 30487
A13: Decrease / (Increase) in Trade Receivables | B13: Trade And Other Receivables | C13: 30674
A14: Decrease / (Increase) in Other bank balances | B14: Other Current and Non Current Assets | C14: 30518
A15: Decrease / (Increase) in loans and other financial assets | B15: Loans And Advances | C15: 30497
A16: Decrease / (Increase) in Current tax assets | B16: Other Current and Non Current Assets | C16: 30518
A17: Decrease / (Increase) in Other current assets | B17: Other Current and Non Current Assets | C17: 30518
A18: Changes in Current Liabilities
A19: (Decrease) / Increase in Trade Payables | B19: Trade Payables And Others | C19: 30675
A20: (Decrease) / Increase in Other Current Liabilities | B20: Other Current and Non Current Liabilities | C20: 30519
A21: (Decrease) / Increase in Other Financial Liabilities | B21: Adjustments for other financial liabilities, non-current | C21: 30454
A22: (Decrease) / Increase in Provisions | B22: Provisions | C22: 30627
A23: Cash Generated from Operation | B23: Net Cash Flow From Operating Activities | C23: 17538
A24: Less: Income Tax Paid | B24: Income Tax Paid | C24: 30422
A25: Net cash generated from operations : | B25: Cash Generated From Operations | C25: 30372
A26: NET CASH FLOW FROM INVESTING ACTIVITIES
A27: Purchase of property, plant & equipment/intangible assets | B27: Purchase Of Fixed Assets (Tangible / Intangible) | C27: 17556
A28: Sale of property, plant & equipment | B28: Sale Of Fixed Assets (Tangible / Intangible) | C28: 30662
A29: Change in other non current assets | B29: Others-Investing Activities | C29: 17545
A30: Investment in Shares of Subisdiary | B30: Investment In Subsidiaries | C30: 30491
A31: Investment in Shares (Net) | B31: Purchase Of Investments | C31: 17557
A32: Interest Income | B32: Interest Received | C32: 30485
A33: Net cash used in investing activities : | B33: Net Cash Flow From Investing Activities | C33: 17537
A34: CASH FLOW FROM FINANCING ACTIVITIES
A35: Proceeds from issue of shares | B35: Proceeds From Issue Of Equity Shares (Inclu Share Premium) | C35: 17553
A36: Changes in Non-Controlling interest | B36: Others-Financing Activities | C36: 17543
A37: Changes in Non Current borrowings | B37: Proceeds From Long Term Borrowings | C37: 17554
A38: Interest and Other Borrowing Cost Paid | B38: Interest Paid | C38: 30484
A39: Net cash generated from financing activities : | B39: Net Cash Flow From Financing Activities | C39: 17536
A40: NET INCREASE/(DECREASE) IN CASH AND CASH EQUIVALENTS | B40: Net Increase in Cash and Cash Equivalents | C40: 17541
...

Sheet SR_Standalone
A1: Particulars | B1: Cogencis Field | C1: Field id
A2: Segment Revenue
A3: Trading of Commodities including FMCG | B3: Product
A4: Supply of Technical Services for Software Systems | B4: Product
A5: Solar | B5: Product
A6: Construction Chemicals | B6: Product
A7: Other Unallocable Segment | B7: Unallocated Income (Expenses) | C7: 8925
A8: Total Segment Revenue
A9: Less : Inter-Segment Revenue | B9: Less: Inter Segment Revenue | C9: 8924
A10: Net Segment Revenue | B10: Total Segment Revenue | C10: 8931
A11: Segment Results Profit / (Loss) before Tax, Interest Depreciation and Amortization Expenses
A12: Trading of Commodities including FMCG | B12: Product
A13: Supply of Technical Services for Software Systems | B13: Product
A14: Solar | B14: Product
A15: Construction Chemicals | B15: Product
A16: Other Unallocable Activities | B16: Unallocated Income (Expenses) | C16: 8929
A17: Total Segment Profit / (Loss)
A18: Less :
A19: Finance Cost | B19: Interest Expenses | C19: 8927
A20: Depreciation | B20: Unallocated Income (Expenses) | C20: 8929
A21: Other Unallocable Expenses | B21: Unallocated Income (Expenses) | C21: 8929
A22: Total
A23: Add : Unallocable Income | B23: Interest Income | C23: 8928
A24: Total Profit before Tax | B24: Profit/(Loss) from ordinary activities before tax | C24: 8911
A25: Segment Assets
A26: Trading of Commodities including FMCG | B26: Product
A27: Supply of Technical Services for Software Systems | B27: Product
A28: Solar | B28: Product
A29: Construction Chemicals | B29: Product
A30: Total Allocable Segment Assets | B30: Segment Assets | C30: 18571
A31: Add : Un-allocable Assets | B31: Unallocable Corporate Assets | C31: 18580
A32: Total Assets | B32: Total Segment Assets | C32: 18578
A33: Segment Liabilities
A34: Trading of Commodities including FMCG | B34: Product
A35: Supply of Technical Services for Software Systems | B35: Product
A36: Solar | B36: Product
A37: Construction Chemicals | B37: Product
A38: Total Allocable Segment Liabilities | B38: Segment Liabilities | C38: 18573
A39: Add : Un-allocable Liabilities | B39: Unallocable Corporate Liabilities | C39: 18581
A40: Total Liabilities | B40: Total Segment Liabilities | C40: 18579

Sheet SR_Consolidated
A1: Particulars | B1: Cogencis Field | C1: Field id
A2: Segment Revenue
A3: Trading of Commodities including FMCG | B3: Product
A4: Supply of Technical Services for Software Systems | B4: Product
A5: Solar | B5: Product
A6: Construction Chemicals | B6: Product
A7: Other Unallocable Segment | B7: Unallocated Income (Expenses) | C7: 8925
A8: Total Segment Revenue
A9: Less : Inter-Segment Revenue | B9: Less: Inter Segment Revenue | C9: 8924
A10: Net Segment Revenue | B10: Total Segment Revenue | C10: 8931
A11: Segment Results Profit / (Loss) before Tax Interest Depreciation and Amortization Expenses
A12: Trading of Commodities including FMCG | B12: Product
A13: Supply of Technical Services for Software Systems | B13: Product
A14: Solar | B14: Product
A15: Construction Chemicals | B15: Product
A16: Other Unallocable Activities | B16: Unallocated Income (Expenses) | C16: 8929
A17: Total Segment Profit / (Loss)
A18: Less :
A19: Finance Cost | B19: Interest Expenses | C19: 8927
A20: Depreciation | B20: Unallocated Income (Expenses) | C20: 8929
A21: Other Unallocable Expenses | B21: Unallocated Income (Expenses) | C21: 8929
A22: Total
A23: Add : Unallocable Income | B23: Interest Income | C23: 8928
A24: Total Profit before Tax | B24: Profit/(Loss) from ordinary activities before tax | C24: 8911
A25: Segment Assets
A26: Trading of Commodities including FMCG | B26: Product
A27: Supply of Technical Services for Software Systems | B27: Product
A28: Solar | B28: Product
A29: Construction Chemicals | B29: Product
A30: Total Allocable Segment Assets | B30: Segment Assets | C30: 18571
A31: Add : Un-allocable Assets | B31: Unallocable Corporate Assets | C31: 18580
A32: Total Assets | B32: Total Segment Assets | C32: 18578
A33: Segment Liabilities
A34: Trading of Commodities including FMCG | B34: Product
A35: Supply of Technical Services for Software Systems | B35: Product
A36: Solar | B36: Product
A37: Construction Chemicals | B37: Product
A38: Total Allocable Segment Liabilities | B38: Segment Liabilities | C38: 18573
A39: Add : Un-allocable Liabilities | B39: Unallocable Corporate Liabilities | C39: 18581
A40: Total Liabilities | B40: Total Segment Liabilities | C40: 18579
